<?xml version='1.0' encoding='utf-8'?>
<mujoco model="openarmx">
  <compiler angle="radian" />

  <asset>
    <mesh name="body_v10_visual_body_link0_part0" content_type="model/obj" file="mujoco_meshes/body_v10_visual_body_link0_part0.obj" />
    <mesh name="arm_v10_visual_link0_mirror_pnp_part0" content_type="model/obj" file="mujoco_meshes/arm_v10_visual_link0_mirror_pnp_part0.obj" />
    <mesh name="arm_v10_visual_link0_mirror_pnp_part1" content_type="model/obj" file="mujoco_meshes/arm_v10_visual_link0_mirror_pnp_part1.obj" />
    <mesh name="arm_v10_visual_link1_mirror_pnp_part0" content_type="model/obj" file="mujoco_meshes/arm_v10_visual_link1_mirror_pnp_part0.obj" />
    <mesh name="arm_v10_visual_link1_mirror_pnp_part1" content_type="model/obj" file="mujoco_meshes/arm_v10_visual_link1_mirror_pnp_part1.obj" />
    <mesh name="arm_v10_visual_link2_mirror_pnp_part0" content_type="model/obj" file="mujoco_meshes/arm_v10_visual_link2_mirror_pnp_part0.obj" />
    <mesh name="arm_v10_visual_link2_mirror_pnp_part1" content_type="model/obj" file="mujoco_meshes/arm_v10_visual_link2_mirror_pnp_part1.obj" />
    <mesh name="arm_v10_visual_link3_mirror_pnp_part0" content_type="model/obj" file="mujoco_meshes/arm_v10_visual_link3_mirror_pnp_part0.obj" />
    <mesh name="arm_v10_visual_link3_mirror_pnp_part1" content_type="model/obj" file="mujoco_meshes/arm_v10_visual_link3_mirror_pnp_part1.obj" />
    <mesh name="arm_v10_visual_link4_part0" content_type="model/obj" file="mujoco_meshes/arm_v10_visual_link4_part0.obj" />
    <mesh name="arm_v10_visual_link4_part1" content_type="model/obj" file="mujoco_meshes/arm_v10_visual_link4_part1.obj" />
    <mesh name="arm_v10_visual_link5_mirror_pnp_part0" content_type="model/obj" file="mujoco_meshes/arm_v10_visual_link5_mirror_pnp_part0.obj" />
    <mesh name="arm_v10_visual_link5_mirror_pnp_part1" content_type="model/obj" file="mujoco_meshes/arm_v10_visual_link5_mirror_pnp_part1.obj" />
    <mesh name="arm_v10_visual_link6_mirror_pnp_part0" content_type="model/obj" file="mujoco_meshes/arm_v10_visual_link6_mirror_pnp_part0.obj" />
    <mesh name="arm_v10_visual_link6_mirror_pnp_part1" content_type="model/obj" file="mujoco_meshes/arm_v10_visual_link6_mirror_pnp_part1.obj" />
    <mesh name="arm_v10_visual_link7_mirror_pnp_part0" content_type="model/obj" file="mujoco_meshes/arm_v10_visual_link7_mirror_pnp_part0.obj" />
    <mesh name="arm_v10_visual_link7_mirror_pnp_part1" content_type="model/obj" file="mujoco_meshes/arm_v10_visual_link7_mirror_pnp_part1.obj" />
    <mesh name="arm_v10_visual_link0_part0" content_type="model/obj" file="mujoco_meshes/arm_v10_visual_link0_part0.obj" />
    <mesh name="arm_v10_visual_link0_part1" content_type="model/obj" file="mujoco_meshes/arm_v10_visual_link0_part1.obj" />
    <mesh name="arm_v10_visual_link1_part0" content_type="model/obj" file="mujoco_meshes/arm_v10_visual_link1_part0.obj" />
    <mesh name="arm_v10_visual_link1_part1" content_type="model/obj" file="mujoco_meshes/arm_v10_visual_link1_part1.obj" />
    <mesh name="arm_v10_visual_link2_part0" content_type="model/obj" file="mujoco_meshes/arm_v10_visual_link2_part0.obj" />
    <mesh name="arm_v10_visual_link2_part1" content_type="model/obj" file="mujoco_meshes/arm_v10_visual_link2_part1.obj" />
    <mesh name="arm_v10_visual_link3_part0" content_type="model/obj" file="mujoco_meshes/arm_v10_visual_link3_part0.obj" />
    <mesh name="arm_v10_visual_link3_part1" content_type="model/obj" file="mujoco_meshes/arm_v10_visual_link3_part1.obj" />
    <mesh name="arm_v10_visual_link5_part0" content_type="model/obj" file="mujoco_meshes/arm_v10_visual_link5_part0.obj" />
    <mesh name="arm_v10_visual_link5_part1" content_type="model/obj" file="mujoco_meshes/arm_v10_visual_link5_part1.obj" />
    <mesh name="arm_v10_visual_link6_part0" content_type="model/obj" file="mujoco_meshes/arm_v10_visual_link6_part0.obj" />
    <mesh name="arm_v10_visual_link6_part1" content_type="model/obj" file="mujoco_meshes/arm_v10_visual_link6_part1.obj" />
    <mesh name="arm_v10_visual_link7_part0" content_type="model/obj" file="mujoco_meshes/arm_v10_visual_link7_part0.obj" />
    <mesh name="arm_v10_visual_link7_part1" content_type="model/obj" file="mujoco_meshes/arm_v10_visual_link7_part1.obj" />
    <mesh name="ee_openarmx_hand_visual_hand_part0" content_type="model/obj" file="mujoco_meshes/ee_openarmx_hand_visual_hand_part0.obj" scale="0.001 0.001 0.001" />
    <mesh name="ee_openarmx_hand_visual_hand_part1" content_type="model/obj" file="mujoco_meshes/ee_openarmx_hand_visual_hand_part1.obj" scale="0.001 0.001 0.001" />
    <mesh name="ee_openarmx_hand_visual_finger_part0" content_type="model/obj" file="mujoco_meshes/ee_openarmx_hand_visual_finger_part0.obj" scale="0.001 0.001 0.001" />
    <mesh name="ee_openarmx_hand_visual_finger_part1" content_type="model/obj" file="mujoco_meshes/ee_openarmx_hand_visual_finger_part1.obj" scale="0.001 0.001 0.001" />
    <mesh name="ee_openarmx_hand_visual_finger_mirror_pnp_part0" content_type="model/obj" file="mujoco_meshes/ee_openarmx_hand_visual_finger_mirror_pnp_part0.obj" scale="0.001 0.001 0.001" />
    <mesh name="ee_openarmx_hand_visual_finger_mirror_pnp_part1" content_type="model/obj" file="mujoco_meshes/ee_openarmx_hand_visual_finger_mirror_pnp_part1.obj" scale="0.001 0.001 0.001" />
  <texture name="sky" type="skybox" builtin="gradient" rgb1="0.08 0.10 0.14" rgb2="0.01 0.012 0.018" width="512" height="512" />
  <texture name="floor_grid" type="2d" builtin="checker" rgb1="0.18 0.20 0.23" rgb2="0.26 0.29 0.33" width="1024" height="1024" mark="edge" markrgb="0.55 0.60 0.68" />
  <material name="floor_mat" texture="floor_grid" texrepeat="8 8" reflectance="0.20" shininess="0.30" specular="0.20" />
</asset>

  <worldbody>
    <body name="openflex_robot_yaw_root" euler="0 0 -1.57079632679"><geom name="openarmx_body_link0_visual_part0" type="mesh" contype="0" conaffinity="0" group="1" density="0" rgba="0.3 0.32 0.35 1" mesh="body_v10_visual_body_link0_part0" />
    <geom name="openarmx_left_link0_visual_part0" pos="0 0.031 0.735" quat="0.707105 -0.707108 0 0" type="mesh" contype="0" conaffinity="0" group="1" density="0" rgba="0.5 0.5 0.55 1" mesh="arm_v10_visual_link0_mirror_pnp_part0" />
    <geom name="openarmx_left_link0_visual_part1" pos="0 0.031 0.735" quat="0.707105 -0.707108 0 0" type="mesh" contype="0" conaffinity="0" group="1" density="0" rgba="0.92 0.92 0.95 1" mesh="arm_v10_visual_link0_mirror_pnp_part1" />
    <geom name="openarmx_right_link0_visual_part0" pos="0 -0.031 0.735" quat="0.707105 0.707108 0 0" type="mesh" contype="0" conaffinity="0" group="1" density="0" rgba="0.5 0.5 0.55 1" mesh="arm_v10_visual_link0_part0" />
    <geom name="openarmx_right_link0_visual_part1" pos="0 -0.031 0.735" quat="0.707105 0.707108 0 0" type="mesh" contype="0" conaffinity="0" group="1" density="0" rgba="0.92 0.92 0.95 1" mesh="arm_v10_visual_link0_part1" />
    <body name="openarmx_left_link1" pos="0 0.089 0.735" quat="0.707105 -0.707108 0 0">
      <inertial pos="0.004452 2.5e-05 0.073323" quat="0.999503 0.000644393 -0.0315003 0.00114209" mass="1.68876" diaginertia="0.00346919 0.002551 0.00190982" />
      <joint name="openarmx_left_joint1" pos="0 0 0" axis="0 0 1" range="-3.3444 0.905604" actuatorfrcrange="-120 120" damping="18.0" armature="0.03" frictionloss="0.15" />
      <geom name="openarmx_left_link1_visual_part0" type="mesh" contype="0" conaffinity="0" group="1" density="0" rgba="0.5 0.5 0.55 1" mesh="arm_v10_visual_link1_mirror_pnp_part0" />
      <geom name="openarmx_left_link1_visual_part1" type="mesh" contype="0" conaffinity="0" group="1" density="0" rgba="0.92 0.92 0.95 1" mesh="arm_v10_visual_link1_mirror_pnp_part1" />
      <body name="openarmx_left_link2" pos="-0.0205 0 0.081" quat="0.707105 -0.707108 0 0">
        <inertial pos="-0.003787 -0.000221 0.04901" quat="0.986716 -0.00145381 -0.161354 -0.0188355" mass="0.396704" diaginertia="0.000891196 0.000821946 0.000327857" />
        <joint name="openarmx_left_joint2" pos="0 0 0" axis="-1 0 0" range="-3.2708 0.129204" actuatorfrcrange="-120 120" damping="18.0" armature="0.03" frictionloss="0.15" />
        <geom name="openarmx_left_link2_visual_part0" type="mesh" contype="0" conaffinity="0" group="1" density="0" rgba="0.5 0.5 0.55 1" mesh="arm_v10_visual_link2_mirror_pnp_part0" />
        <geom name="openarmx_left_link2_visual_part1" type="mesh" contype="0" conaffinity="0" group="1" density="0" rgba="0.15 0.65 0.7 1" mesh="arm_v10_visual_link2_mirror_pnp_part1" />
        <body name="openarmx_left_link3" pos="0.02 0 0.099">
          <inertial pos="-0.000828 -0.000236 0.083336" quat="0.946133 0.00530809 0.00424656 -0.323707" mass="2.49278" diaginertia="0.0103641 0.0103322 0.00300164" />
          <joint name="openarmx_left_joint3" pos="0 0 0" axis="0 0 1" range="-1.57 1.57" actuatorfrcrange="-60 60" damping="18.0" armature="0.03" frictionloss="0.15" />
          <geom name="openarmx_left_link3_visual_part0" type="mesh" contype="0" conaffinity="0" group="1" density="0" rgba="0.5 0.5 0.55 1" mesh="arm_v10_visual_link3_mirror_pnp_part0" />
          <geom name="openarmx_left_link3_visual_part1" type="mesh" contype="0" conaffinity="0" group="1" density="0" rgba="0.92 0.92 0.95 1" mesh="arm_v10_visual_link3_mirror_pnp_part1" />
          <body name="openarmx_left_link4" pos="0 0.031002 0.14181">
            <inertial pos="-0.002591 -0.030135 0.07147" quat="0.999683 -0.0233783 -0.00922341 -0.00115143" mass="0.779755" diaginertia="0.00201543 0.00162187 0.000765704" />
            <joint name="openarmx_left_joint4" pos="0 0 0" axis="0 1 0" range="0 1.8" actuatorfrcrange="-60 60" damping="18.0" armature="0.03" frictionloss="0.15" />
            <geom name="openarmx_left_link4_visual_part0" type="mesh" contype="0" conaffinity="0" group="1" density="0" rgba="0.5 0.5 0.55 1" mesh="arm_v10_visual_link4_part0" />
            <geom name="openarmx_left_link4_visual_part1" type="mesh" contype="0" conaffinity="0" group="1" density="0" rgba="0.15 0.65 0.7 1" mesh="arm_v10_visual_link4_part1" />
            <body name="openarmx_left_link5" pos="0 -0.0309 0.126">
              <inertial pos="-0.002256 -0.000305 0.0533" quat="0.714458 -0.0122081 -0.0110113 0.699485" mass="0.687255" diaginertia="0.00106611 0.000831256 0.000495637" />
              <joint name="openarmx_left_joint5" pos="0 0 0" axis="0 0 1" range="-1.5 1.5" actuatorfrcrange="-14 14" damping="18.0" armature="0.03" frictionloss="0.15" />
              <geom name="openarmx_left_link5_visual_part0" type="mesh" contype="0" conaffinity="0" group="1" density="0" rgba="0.5 0.5 0.55 1" mesh="arm_v10_visual_link5_mirror_pnp_part0" />
              <geom name="openarmx_left_link5_visual_part1" type="mesh" contype="0" conaffinity="0" group="1" density="0" rgba="0.92 0.92 0.95 1" mesh="arm_v10_visual_link5_mirror_pnp_part1" />
              <body name="openarmx_left_link6" pos="0.037426 0 0.131">
                <inertial pos="-0.03564 0.005114 -0.003582" quat="0.945265 0.038546 0.187709 -0.26411" mass="0.384836" diaginertia="0.000317632 0.000265263 0.000212105" />
                <joint name="openarmx_left_joint6" pos="0 0 0" axis="1 0 0" range="-0.75 0.75" actuatorfrcrange="-14 14" damping="18.0" armature="0.03" frictionloss="0.15" />
                <geom name="openarmx_left_link6_visual_part0" type="mesh" contype="0" conaffinity="0" group="1" density="0" rgba="0.5 0.5 0.55 1" mesh="arm_v10_visual_link6_mirror_pnp_part0" />
                <geom name="openarmx_left_link6_visual_part1" type="mesh" contype="0" conaffinity="0" group="1" density="0" rgba="0.8 0.8 0.82 1" mesh="arm_v10_visual_link6_mirror_pnp_part1" />
                <body name="openarmx_left_link7" pos="-0.0375 0 0">
                  <inertial pos="0.000153865 -0.0365798 0.0698705" quat="0.471362 0.881718 -0.0189266 0.00575458" mass="0.974972" diaginertia="0.00476254 0.00404439 0.000991057" />
                  <joint name="openarmx_left_joint7" pos="0 0 0" axis="0 -1 0" range="-1.4 1.4" actuatorfrcrange="-14 14" damping="18.0" armature="0.03" frictionloss="0.15" />
                  <geom name="openarmx_left_link7_visual_part0" type="mesh" contype="0" conaffinity="0" group="1" density="0" rgba="0.5 0.5 0.55 1" mesh="arm_v10_visual_link7_mirror_pnp_part0" />
                  <geom name="openarmx_left_link7_visual_part1" type="mesh" contype="0" conaffinity="0" group="1" density="0" rgba="0.3 0.7 1 1" mesh="arm_v10_visual_link7_mirror_pnp_part1" />
                  <geom name="openarmx_left_hand_visual_part0" pos="0 0 -0.5584" quat="1 0 0 0" type="mesh" contype="0" conaffinity="0" group="1" density="0" rgba="0.5 0.5 0.55 1" mesh="ee_openarmx_hand_visual_hand_part0" />
                  <geom name="openarmx_left_hand_visual_part1" pos="0 0 -0.5584" quat="1 0 0 0" type="mesh" contype="0" conaffinity="0" group="1" density="0" rgba="0.92 0.92 0.95 1" mesh="ee_openarmx_hand_visual_hand_part1" />
                  <body name="openarmx_left_right_finger" pos="0 -0.006 0.1151">
                    <inertial pos="0.0064528 -0.01702 0.0219685" mass="0.0360255" diaginertia="2.375e-06 2.375e-06 7.5e-07" />
                    <joint name="openarmx_left_finger_joint1" pos="0 0 0" axis="0 -1 0" type="slide" range="0 0.044" actuatorfrcrange="-333 333" damping="2.0" armature="0.002" frictionloss="0.02" />
                    <geom name="openarmx_left_right_finger_visual_part0" pos="0 0.05 -0.673001" quat="1 0 0 0" type="mesh" contype="0" conaffinity="0" group="1" density="0" rgba="0.5 0.5 0.55 1" mesh="ee_openarmx_hand_visual_finger_mirror_pnp_part0" />
                    <geom name="openarmx_left_right_finger_visual_part1" pos="0 0.05 -0.673001" quat="1 0 0 0" type="mesh" contype="0" conaffinity="0" group="1" density="0" rgba="0.25 0.25 0.25 1" mesh="ee_openarmx_hand_visual_finger_mirror_pnp_part1" />
                  </body>
                  <body name="openarmx_left_left_finger" pos="0 0.006 0.1151">
                    <inertial pos="0.0064528 0.01702 0.0219685" mass="0.0360255" diaginertia="2.375e-06 2.375e-06 7.5e-07" />
                    <joint name="openarmx_left_finger_joint2" pos="0 0 0" axis="0 1 0" type="slide" range="0 0.044" actuatorfrcrange="-333 333" damping="2.0" armature="0.002" frictionloss="0.02" />
                    <geom name="openarmx_left_left_finger_visual_part0" pos="0 -0.05 -0.673001" quat="1 0 0 0" type="mesh" contype="0" conaffinity="0" group="1" density="0" rgba="0.5 0.5 0.55 1" mesh="ee_openarmx_hand_visual_finger_part0" />
                    <geom name="openarmx_left_left_finger_visual_part1" pos="0 -0.05 -0.673001" quat="1 0 0 0" type="mesh" contype="0" conaffinity="0" group="1" density="0" rgba="0.25 0.25 0.25 1" mesh="ee_openarmx_hand_visual_finger_part1" />
                  </body>
                </body>
              </body>
            </body>
          </body>
        </body>
      </body>
    </body>
    <body name="openarmx_right_link1" pos="0 -0.089 0.735" quat="0.707105 0.707108 0 0">
      <inertial pos="0.004452 -2.5e-05 0.073323" quat="0.999503 0.000644393 -0.0315003 0.00114209" mass="1.68876" diaginertia="0.00346919 0.002551 0.00190982" />
      <joint name="openarmx_right_joint1" pos="0 0 0" axis="0 0 1" range="-1.25 3" actuatorfrcrange="-120 120" damping="18.0" armature="0.03" frictionloss="0.15" />
      <geom name="openarmx_right_link1_visual_part0" type="mesh" contype="0" conaffinity="0" group="1" density="0" rgba="0.5 0.5 0.55 1" mesh="arm_v10_visual_link1_part0" />
      <geom name="openarmx_right_link1_visual_part1" type="mesh" contype="0" conaffinity="0" group="1" density="0" rgba="0.92 0.92 0.95 1" mesh="arm_v10_visual_link1_part1" />
      <body name="openarmx_right_link2" pos="-0.0205 0 0.081" quat="0.707105 0.707108 0 0">
        <inertial pos="-0.003787 0.000221 0.04901" quat="0.986716 -0.00145381 -0.161354 -0.0188355" mass="0.396704" diaginertia="0.000891196 0.000821946 0.000327857" />
        <joint name="openarmx_right_joint2" pos="0 0 0" axis="-1 0 0" range="-0.129204 3.2708" actuatorfrcrange="-120 120" damping="18.0" armature="0.03" frictionloss="0.15" />
        <geom name="openarmx_right_link2_visual_part0" type="mesh" contype="0" conaffinity="0" group="1" density="0" rgba="0.5 0.5 0.55 1" mesh="arm_v10_visual_link2_part0" />
        <geom name="openarmx_right_link2_visual_part1" type="mesh" contype="0" conaffinity="0" group="1" density="0" rgba="0.15 0.65 0.7 1" mesh="arm_v10_visual_link2_part1" />
        <body name="openarmx_right_link3" pos="0.02 0 0.099">
          <inertial pos="-0.000828 0.000236 0.083336" quat="0.946133 0.00530809 0.00424656 -0.323707" mass="2.49278" diaginertia="0.0103641 0.0103322 0.00300164" />
          <joint name="openarmx_right_joint3" pos="0 0 0" axis="0 0 1" range="-1.57 1.57" actuatorfrcrange="-60 60" damping="18.0" armature="0.03" frictionloss="0.15" />
          <geom name="openarmx_right_link3_visual_part0" type="mesh" contype="0" conaffinity="0" group="1" density="0" rgba="0.5 0.5 0.55 1" mesh="arm_v10_visual_link3_part0" />
          <geom name="openarmx_right_link3_visual_part1" type="mesh" contype="0" conaffinity="0" group="1" density="0" rgba="0.92 0.92 0.95 1" mesh="arm_v10_visual_link3_part1" />
          <body name="openarmx_right_link4" pos="0 0.031002 0.14181">
            <inertial pos="-0.002591 -0.030135 0.07147" quat="0.999683 -0.0233783 -0.00922341 -0.00115143" mass="0.779755" diaginertia="0.00201543 0.00162187 0.000765704" />
            <joint name="openarmx_right_joint4" pos="0 0 0" axis="0 1 0" range="0 1.8" actuatorfrcrange="-60 60" damping="18.0" armature="0.03" frictionloss="0.15" />
            <geom name="openarmx_right_link4_visual_part0" type="mesh" contype="0" conaffinity="0" group="1" density="0" rgba="0.5 0.5 0.55 1" mesh="arm_v10_visual_link4_part0" />
            <geom name="openarmx_right_link4_visual_part1" type="mesh" contype="0" conaffinity="0" group="1" density="0" rgba="0.15 0.65 0.7 1" mesh="arm_v10_visual_link4_part1" />
            <body name="openarmx_right_link5" pos="0 -0.0309 0.126">
              <inertial pos="-0.002256 0.000305 0.0533" quat="0.714458 -0.0122081 -0.0110113 0.699485" mass="0.687255" diaginertia="0.00106611 0.000831256 0.000495637" />
              <joint name="openarmx_right_joint5" pos="0 0 0" axis="0 0 1" range="-1.5 1.5" actuatorfrcrange="-14 14" damping="18.0" armature="0.03" frictionloss="0.15" />
              <geom name="openarmx_right_link5_visual_part0" type="mesh" contype="0" conaffinity="0" group="1" density="0" rgba="0.5 0.5 0.55 1" mesh="arm_v10_visual_link5_part0" />
              <geom name="openarmx_right_link5_visual_part1" type="mesh" contype="0" conaffinity="0" group="1" density="0" rgba="0.92 0.92 0.95 1" mesh="arm_v10_visual_link5_part1" />
              <body name="openarmx_right_link6" pos="0.037426 0 0.131">
                <inertial pos="-0.03564 -0.005114 -0.003582" quat="0.945265 0.038546 0.187709 -0.26411" mass="0.384836" diaginertia="0.000317632 0.000265263 0.000212105" />
                <joint name="openarmx_right_joint6" pos="0 0 0" axis="1 0 0" range="-0.75 0.75" actuatorfrcrange="-14 14" damping="18.0" armature="0.03" frictionloss="0.15" />
                <geom name="openarmx_right_link6_visual_part0" type="mesh" contype="0" conaffinity="0" group="1" density="0" rgba="0.5 0.5 0.55 1" mesh="arm_v10_visual_link6_part0" />
                <geom name="openarmx_right_link6_visual_part1" type="mesh" contype="0" conaffinity="0" group="1" density="0" rgba="0.8 0.8 0.82 1" mesh="arm_v10_visual_link6_part1" />
                <body name="openarmx_right_link7" pos="-0.0375 0 0">
                  <inertial pos="0.000153865 -0.0338517 0.0698705" quat="0.480064 0.877024 -0.0182521 0.00578127" mass="0.974972" diaginertia="0.00494981 0.00422951 0.000993346" />
                  <joint name="openarmx_right_joint7" pos="0 0 0" axis="0 1 0" range="-1.4 1.4" actuatorfrcrange="-14 14" damping="18.0" armature="0.03" frictionloss="0.15" />
                  <geom name="openarmx_right_link7_visual_part0" type="mesh" contype="0" conaffinity="0" group="1" density="0" rgba="0.5 0.5 0.55 1" mesh="arm_v10_visual_link7_part0" />
                  <geom name="openarmx_right_link7_visual_part1" type="mesh" contype="0" conaffinity="0" group="1" density="0" rgba="0.3 0.7 1 1" mesh="arm_v10_visual_link7_part1" />
                  <geom name="openarmx_right_hand_visual_part0" pos="0 0 -0.5584" quat="1 0 0 0" type="mesh" contype="0" conaffinity="0" group="1" density="0" rgba="0.5 0.5 0.55 1" mesh="ee_openarmx_hand_visual_hand_part0" />
                  <geom name="openarmx_right_hand_visual_part1" pos="0 0 -0.5584" quat="1 0 0 0" type="mesh" contype="0" conaffinity="0" group="1" density="0" rgba="0.92 0.92 0.95 1" mesh="ee_openarmx_hand_visual_hand_part1" />
                  <body name="openarmx_right_right_finger" pos="0 -0.006 0.1151">
                    <inertial pos="0.0064528 -0.01702 0.0219685" mass="0.0360255" diaginertia="2.375e-06 2.375e-06 7.5e-07" />
                    <joint name="openarmx_right_finger_joint1" pos="0 0 0" axis="0 -1 0" type="slide" range="0 0.044" actuatorfrcrange="-333 333" damping="2.0" armature="0.002" frictionloss="0.02" />
                    <geom name="openarmx_right_right_finger_visual_part0" pos="0 0.05 -0.673001" quat="1 0 0 0" type="mesh" contype="0" conaffinity="0" group="1" density="0" rgba="0.5 0.5 0.55 1" mesh="ee_openarmx_hand_visual_finger_mirror_pnp_part0" />
                    <geom name="openarmx_right_right_finger_visual_part1" pos="0 0.05 -0.673001" quat="1 0 0 0" type="mesh" contype="0" conaffinity="0" group="1" density="0" rgba="0.25 0.25 0.25 1" mesh="ee_openarmx_hand_visual_finger_mirror_pnp_part1" />
                  </body>
                  <body name="openarmx_right_left_finger" pos="0 0.006 0.1151">
                    <inertial pos="0.0064528 0.01702 0.0219685" mass="0.0360255" diaginertia="2.375e-06 2.375e-06 7.5e-07" />
                    <joint name="openarmx_right_finger_joint2" pos="0 0 0" axis="0 1 0" type="slide" range="0 0.044" actuatorfrcrange="-333 333" damping="2.0" armature="0.002" frictionloss="0.02" />
                    <geom name="openarmx_right_left_finger_visual_part0" pos="0 -0.05 -0.673001" quat="1 0 0 0" type="mesh" contype="0" conaffinity="0" group="1" density="0" rgba="0.5 0.5 0.55 1" mesh="ee_openarmx_hand_visual_finger_part0" />
                    <geom name="openarmx_right_left_finger_visual_part1" pos="0 -0.05 -0.673001" quat="1 0 0 0" type="mesh" contype="0" conaffinity="0" group="1" density="0" rgba="0.25 0.25 0.25 1" mesh="ee_openarmx_hand_visual_finger_part1" />
                  </body>
                </body>
              </body>
            </body>
          </body>
        </body>
      </body>
    </body>
  </body><light name="key_light" pos="-1.4 -2.2 3.2" dir="0.35 0.55 -1" directional="true" diffuse="0.95 0.92 0.86" specular="0.35 0.35 0.35" />
<light name="fill_light" pos="1.8 1.4 2.2" dir="-0.45 -0.35 -1" directional="true" diffuse="0.35 0.45 0.65" specular="0.12 0.12 0.16" />
<light name="rim_light" pos="0 2.2 1.8" dir="0 -1 -0.45" directional="true" diffuse="0.55 0.65 0.85" specular="0.20 0.22 0.28" />
<geom name="floor" type="plane" pos="0 0 -0.012" size="2.4 2.4 0.02" material="floor_mat" /></worldbody>
<visual><headlight diffuse="0.55 0.55 0.55" ambient="0.24 0.24 0.26" specular="0.25 0.25 0.25" />
  <map znear="0.01" zfar="8" />
  <scale forcewidth="0.06" contactwidth="0.05" />
  <rgba haze="0.03 0.035 0.045 1" />
</visual><equality><joint joint1="openarmx_left_finger_joint1" joint2="openarmx_left_finger_joint2" solimp="0.95 0.99 0.001" solref="0.005 1" /><joint joint1="openarmx_right_finger_joint1" joint2="openarmx_right_finger_joint2" solimp="0.95 0.99 0.001" solref="0.005 1" /></equality><actuator><position name="openarmx_left_joint1_pos" joint="openarmx_left_joint1" kp="180" ctrllimited="true" ctrlrange="-3.344396 0.9056039999999999" /><position name="openarmx_left_joint2_pos" joint="openarmx_left_joint2" kp="180" ctrllimited="true" ctrlrange="-3.2707963267948967 0.1292036732051034" /><position name="openarmx_left_joint3_pos" joint="openarmx_left_joint3" kp="180" ctrllimited="true" ctrlrange="-1.57 1.57" /><position name="openarmx_left_joint4_pos" joint="openarmx_left_joint4" kp="180" ctrllimited="true" ctrlrange="0.0 1.8" /><position name="openarmx_left_joint5_pos" joint="openarmx_left_joint5" kp="180" ctrllimited="true" ctrlrange="-1.5 1.5" /><position name="openarmx_left_joint6_pos" joint="openarmx_left_joint6" kp="180" ctrllimited="true" ctrlrange="-0.75 0.75" /><position name="openarmx_left_joint7_pos" joint="openarmx_left_joint7" kp="180" ctrllimited="true" ctrlrange="-1.4 1.4" /><position name="openarmx_left_finger_joint1_pos" joint="openarmx_left_finger_joint1" kp="80" ctrllimited="true" ctrlrange="0.0 0.044" /><position name="openarmx_right_joint1_pos" joint="openarmx_right_joint1" kp="180" ctrllimited="true" ctrlrange="-1.25 3.0" /><position name="openarmx_right_joint2_pos" joint="openarmx_right_joint2" kp="180" ctrllimited="true" ctrlrange="-0.1292036732051034 3.2707963267948967" /><position name="openarmx_right_joint3_pos" joint="openarmx_right_joint3" kp="180" ctrllimited="true" ctrlrange="-1.57 1.57" /><position name="openarmx_right_joint4_pos" joint="openarmx_right_joint4" kp="180" ctrllimited="true" ctrlrange="0.0 1.8" /><position name="openarmx_right_joint5_pos" joint="openarmx_right_joint5" kp="180" ctrllimited="true" ctrlrange="-1.5 1.5" /><position name="openarmx_right_joint6_pos" joint="openarmx_right_joint6" kp="180" ctrllimited="true" ctrlrange="-0.75 0.75" /><position name="openarmx_right_joint7_pos" joint="openarmx_right_joint7" kp="180" ctrllimited="true" ctrlrange="-1.4 1.4" /><position name="openarmx_right_finger_joint1_pos" joint="openarmx_right_finger_joint1" kp="80" ctrllimited="true" ctrlrange="0.0 0.044" /></actuator></mujoco>