<?xml version='1.0' encoding='utf-8'?>
<mujoco model="openarmx_integrated">
  <compiler angle="radian" />

  <asset>
    <mesh name="packages_openflex_chassis_swerve_description_meshes_base_link" file="mujoco_meshes/packages_openflex_chassis_swerve_description_meshes_base_link.obj" />
    <mesh name="packages_openflex_chassis_swerve_description_meshes_fl_wheel_link" file="mujoco_meshes/packages_openflex_chassis_swerve_description_meshes_fl_wheel_link.obj" scale="0.001 0.001 0.001" />
    <mesh name="packages_openflex_chassis_swerve_description_meshes_fr_wheel_link" file="mujoco_meshes/packages_openflex_chassis_swerve_description_meshes_fr_wheel_link.obj" scale="0.001 0.001 0.001" />
    <mesh name="packages_openflex_chassis_swerve_description_meshes_bl_wheel_link" file="mujoco_meshes/packages_openflex_chassis_swerve_description_meshes_bl_wheel_link.obj" scale="0.001 0.001 0.001" />
    <mesh name="packages_openflex_chassis_swerve_description_meshes_br_wheel_link" file="mujoco_meshes/packages_openflex_chassis_swerve_description_meshes_br_wheel_link.obj" scale="0.001 0.001 0.001" />
    <mesh name="packages_openflex_chassis_swerve_description_meshes_mid360_link" file="mujoco_meshes/packages_openflex_chassis_swerve_description_meshes_mid360_link.obj" scale="0.001 0.001 0.001" />
    <mesh name="packages_openflex_chassis_swerve_description_meshes_d435_link" file="mujoco_meshes/packages_openflex_chassis_swerve_description_meshes_d435_link.obj" scale="0.001 0.001 0.001" />
    <mesh name="packages_lift_slide_description_meshes_lift_link" file="mujoco_meshes/packages_lift_slide_description_meshes_lift_link.obj" />
    <mesh name="packages_lift_slide_description_meshes_plate_link" file="mujoco_meshes/packages_lift_slide_description_meshes_plate_link.obj" />
    <mesh name="packages_lift_slide_description_meshes_chest_link" file="mujoco_meshes/packages_lift_slide_description_meshes_chest_link.obj" scale="0.001 0.001 0.001" />
    <mesh name="packages_lift_slide_description_meshes_left_link0_base" file="mujoco_meshes/packages_lift_slide_description_meshes_left_link0_base.obj" />
    <mesh name="packages_lift_slide_description_meshes_right_link0_base" file="mujoco_meshes/packages_lift_slide_description_meshes_right_link0_base.obj" />
    <mesh name="packages_openarmx_description_meshes_arm_v10_visual_link0_mirror_pnp_part0" file="mujoco_meshes/packages_openarmx_description_meshes_arm_v10_visual_link0_mirror_pnp_part0.obj" />
    <mesh name="packages_openarmx_description_meshes_arm_v10_visual_link0_mirror_pnp_part1" file="mujoco_meshes/packages_openarmx_description_meshes_arm_v10_visual_link0_mirror_pnp_part1.obj" />
    <mesh name="packages_openarmx_description_meshes_arm_v10_visual_link1_mirror_pnp_part0" file="mujoco_meshes/packages_openarmx_description_meshes_arm_v10_visual_link1_mirror_pnp_part0.obj" />
    <mesh name="packages_openarmx_description_meshes_arm_v10_visual_link1_mirror_pnp_part1" file="mujoco_meshes/packages_openarmx_description_meshes_arm_v10_visual_link1_mirror_pnp_part1.obj" />
    <mesh name="packages_openarmx_description_meshes_arm_v10_visual_link2_mirror_pnp_part0" file="mujoco_meshes/packages_openarmx_description_meshes_arm_v10_visual_link2_mirror_pnp_part0.obj" />
    <mesh name="packages_openarmx_description_meshes_arm_v10_visual_link2_mirror_pnp_part1" file="mujoco_meshes/packages_openarmx_description_meshes_arm_v10_visual_link2_mirror_pnp_part1.obj" />
    <mesh name="packages_openarmx_description_meshes_arm_v10_visual_link3_mirror_pnp_part0" file="mujoco_meshes/packages_openarmx_description_meshes_arm_v10_visual_link3_mirror_pnp_part0.obj" />
    <mesh name="packages_openarmx_description_meshes_arm_v10_visual_link3_mirror_pnp_part1" file="mujoco_meshes/packages_openarmx_description_meshes_arm_v10_visual_link3_mirror_pnp_part1.obj" />
    <mesh name="packages_openarmx_description_meshes_arm_v10_visual_link4_part0" file="mujoco_meshes/packages_openarmx_description_meshes_arm_v10_visual_link4_part0.obj" />
    <mesh name="packages_openarmx_description_meshes_arm_v10_visual_link4_part1" file="mujoco_meshes/packages_openarmx_description_meshes_arm_v10_visual_link4_part1.obj" />
    <mesh name="packages_openarmx_description_meshes_arm_v10_visual_link5_mirror_pnp_part0" file="mujoco_meshes/packages_openarmx_description_meshes_arm_v10_visual_link5_mirror_pnp_part0.obj" />
    <mesh name="packages_openarmx_description_meshes_arm_v10_visual_link5_mirror_pnp_part1" file="mujoco_meshes/packages_openarmx_description_meshes_arm_v10_visual_link5_mirror_pnp_part1.obj" />
    <mesh name="packages_openarmx_description_meshes_arm_v10_visual_link6_mirror_pnp_part0" file="mujoco_meshes/packages_openarmx_description_meshes_arm_v10_visual_link6_mirror_pnp_part0.obj" />
    <mesh name="packages_openarmx_description_meshes_arm_v10_visual_link6_mirror_pnp_part1" file="mujoco_meshes/packages_openarmx_description_meshes_arm_v10_visual_link6_mirror_pnp_part1.obj" />
    <mesh name="packages_openarmx_description_meshes_arm_v10_visual_link7_mirror_pnp_part0" file="mujoco_meshes/packages_openarmx_description_meshes_arm_v10_visual_link7_mirror_pnp_part0.obj" />
    <mesh name="packages_openarmx_description_meshes_arm_v10_visual_link7_mirror_pnp_part1" file="mujoco_meshes/packages_openarmx_description_meshes_arm_v10_visual_link7_mirror_pnp_part1.obj" />
    <mesh name="packages_openarmx_description_meshes_arm_v10_visual_link0_part0" file="mujoco_meshes/packages_openarmx_description_meshes_arm_v10_visual_link0_part0.obj" />
    <mesh name="packages_openarmx_description_meshes_arm_v10_visual_link0_part1" file="mujoco_meshes/packages_openarmx_description_meshes_arm_v10_visual_link0_part1.obj" />
    <mesh name="packages_openarmx_description_meshes_arm_v10_visual_link1_part0" file="mujoco_meshes/packages_openarmx_description_meshes_arm_v10_visual_link1_part0.obj" />
    <mesh name="packages_openarmx_description_meshes_arm_v10_visual_link1_part1" file="mujoco_meshes/packages_openarmx_description_meshes_arm_v10_visual_link1_part1.obj" />
    <mesh name="packages_openarmx_description_meshes_arm_v10_visual_link2_part0" file="mujoco_meshes/packages_openarmx_description_meshes_arm_v10_visual_link2_part0.obj" />
    <mesh name="packages_openarmx_description_meshes_arm_v10_visual_link2_part1" file="mujoco_meshes/packages_openarmx_description_meshes_arm_v10_visual_link2_part1.obj" />
    <mesh name="packages_openarmx_description_meshes_arm_v10_visual_link3_part0" file="mujoco_meshes/packages_openarmx_description_meshes_arm_v10_visual_link3_part0.obj" />
    <mesh name="packages_openarmx_description_meshes_arm_v10_visual_link3_part1" file="mujoco_meshes/packages_openarmx_description_meshes_arm_v10_visual_link3_part1.obj" />
    <mesh name="packages_openarmx_description_meshes_arm_v10_visual_link5_part0" file="mujoco_meshes/packages_openarmx_description_meshes_arm_v10_visual_link5_part0.obj" />
    <mesh name="packages_openarmx_description_meshes_arm_v10_visual_link5_part1" file="mujoco_meshes/packages_openarmx_description_meshes_arm_v10_visual_link5_part1.obj" />
    <mesh name="packages_openarmx_description_meshes_arm_v10_visual_link6_part0" file="mujoco_meshes/packages_openarmx_description_meshes_arm_v10_visual_link6_part0.obj" />
    <mesh name="packages_openarmx_description_meshes_arm_v10_visual_link6_part1" file="mujoco_meshes/packages_openarmx_description_meshes_arm_v10_visual_link6_part1.obj" />
    <mesh name="packages_openarmx_description_meshes_arm_v10_visual_link7_part0" file="mujoco_meshes/packages_openarmx_description_meshes_arm_v10_visual_link7_part0.obj" />
    <mesh name="packages_openarmx_description_meshes_arm_v10_visual_link7_part1" file="mujoco_meshes/packages_openarmx_description_meshes_arm_v10_visual_link7_part1.obj" />
    <mesh name="packages_openarmx_description_meshes_ee_openarmx_hand_visual_hand_part0" file="mujoco_meshes/packages_openarmx_description_meshes_ee_openarmx_hand_visual_hand_part0.obj" scale="0.001 0.001 0.001" />
    <mesh name="packages_openarmx_description_meshes_ee_openarmx_hand_visual_hand_part1" file="mujoco_meshes/packages_openarmx_description_meshes_ee_openarmx_hand_visual_hand_part1.obj" scale="0.001 0.001 0.001" />
    <mesh name="packages_openarmx_description_meshes_ee_openarmx_hand_visual_finger_part0" file="mujoco_meshes/packages_openarmx_description_meshes_ee_openarmx_hand_visual_finger_part0.obj" scale="0.001 0.001 0.001" />
    <mesh name="packages_openarmx_description_meshes_ee_openarmx_hand_visual_finger_part1" file="mujoco_meshes/packages_openarmx_description_meshes_ee_openarmx_hand_visual_finger_part1.obj" scale="0.001 0.001 0.001" />
    <mesh name="packages_openarmx_description_meshes_ee_openarmx_hand_visual_finger_mirror_pnp_part0" file="mujoco_meshes/packages_openarmx_description_meshes_ee_openarmx_hand_visual_finger_mirror_pnp_part0.obj" scale="0.001 0.001 0.001" />
    <mesh name="packages_openarmx_description_meshes_ee_openarmx_hand_visual_finger_mirror_pnp_part1" file="mujoco_meshes/packages_openarmx_description_meshes_ee_openarmx_hand_visual_finger_mirror_pnp_part1.obj" scale="0.001 0.001 0.001" />
    <mesh name="packages_openarmx_head_description_meshes_visual_TBBJ-04_neck_mount" file="mujoco_meshes/packages_openarmx_head_description_meshes_visual_TBBJ-04_neck_mount.obj" scale="0.001 0.001 0.001" />
    <mesh name="packages_openarmx_head_description_meshes_visual_TBBJ-02_neck_bracket" file="mujoco_meshes/packages_openarmx_head_description_meshes_visual_TBBJ-02_neck_bracket.obj" scale="0.001 0.001 0.001" />
    <mesh name="packages_openarmx_head_description_meshes_visual_TBBJ-06_neck_limit" file="mujoco_meshes/packages_openarmx_head_description_meshes_visual_TBBJ-06_neck_limit.obj" scale="0.001 0.001 0.001" />
    <mesh name="packages_openarmx_head_description_meshes_visual_RS00_motor_2" file="mujoco_meshes/packages_openarmx_head_description_meshes_visual_RS00_motor_2.obj" scale="0.001 0.001 0.001" />
    <mesh name="packages_openarmx_head_description_meshes_visual_DY-03_neck_cover" file="mujoco_meshes/packages_openarmx_head_description_meshes_visual_DY-03_neck_cover.obj" scale="0.001 0.001 0.001" />
    <mesh name="packages_openarmx_head_description_meshes_visual_RS00_motor_1" file="mujoco_meshes/packages_openarmx_head_description_meshes_visual_RS00_motor_1.obj" scale="0.001 0.001 0.001" />
    <mesh name="packages_openarmx_head_description_meshes_visual_TB-01_head_connector" file="mujoco_meshes/packages_openarmx_head_description_meshes_visual_TB-01_head_connector.obj" scale="0.001 0.001 0.001" />
    <mesh name="packages_openarmx_head_description_meshes_visual_TBBJ-03_guard_plate" file="mujoco_meshes/packages_openarmx_head_description_meshes_visual_TBBJ-03_guard_plate.obj" scale="0.001 0.001 0.001" />
    <mesh name="packages_openarmx_head_description_meshes_visual_TBBJ-01_head_bracket" file="mujoco_meshes/packages_openarmx_head_description_meshes_visual_TBBJ-01_head_bracket.obj" scale="0.001 0.001 0.001" />
    <mesh name="packages_openarmx_head_description_meshes_visual_TBBJ-05_head_limit" file="mujoco_meshes/packages_openarmx_head_description_meshes_visual_TBBJ-05_head_limit.obj" scale="0.001 0.001 0.001" />
    <mesh name="packages_openarmx_head_description_meshes_visual_DY-01_head_front_shell" file="mujoco_meshes/packages_openarmx_head_description_meshes_visual_DY-01_head_front_shell.obj" scale="0.001 0.001 0.001" />
    <mesh name="packages_openarmx_head_description_meshes_visual_DY-02_head_rear_shell" file="mujoco_meshes/packages_openarmx_head_description_meshes_visual_DY-02_head_rear_shell.obj" scale="0.001 0.001 0.001" />
    <mesh name="packages_openarmx_head_description_meshes_visual_femto_bolt_camera" file="mujoco_meshes/packages_openarmx_head_description_meshes_visual_femto_bolt_camera.obj" scale="0.001 0.001 0.001" />
  <texture name="sky" type="skybox" builtin="gradient" rgb1="0.08 0.10 0.14" rgb2="0.01 0.012 0.018" width="512" height="512" />
  <texture name="floor_grid" type="2d" builtin="checker" rgb1="0.18 0.20 0.23" rgb2="0.26 0.29 0.33" width="1024" height="1024" mark="edge" markrgb="0.55 0.60 0.68" />
  <material name="floor_mat" texture="floor_grid" texrepeat="8 8" reflectance="0.20" shininess="0.30" specular="0.20" />
</asset>

  <worldbody>
    <camera name="front" pos="0 -4.0 1.1" xyaxes="1 0 0 0 0 1" fovy="50"/>
    <body name="openflex_robot_yaw_root" pos="0 0 0.17" euler="0 0 -1.57079632679"><body name="base_link">
      <inertial pos="0 0 0" quat="0 0.707107 0 0.707107" mass="20" diaginertia="0.683333 0.449333 0.299333" />
      <geom quat="0.707105 0.707108 0 0" type="mesh" contype="3" conaffinity="3" group="1" density="0" rgba="0.28 0.28 0.28 1" mesh="packages_openflex_chassis_swerve_description_meshes_base_link" />
      <body name="base_footprint" pos="0 0 -0.17">
        <inertial pos="0 0 0" mass="0.5" diaginertia="0.002 0.002 0.002" />
      </body>
      <body name="fl_steering_link" pos="0.21 0.2735 -0.07">
        <inertial pos="0 0 0" quat="0.5 0.5 -0.5 0.5" mass="0.5" diaginertia="0.000225 0.000216667 0.000216667" />
        <joint name="fl_steering_joint" pos="0 0 0" axis="0 0 1" range="-1.5708 1.5708" actuatorfrcrange="-10 10" damping="3.0" armature="0.005" frictionloss="0.1" />
        <body name="fl_wheel_link" pos="0 0 -0.025">
          <inertial pos="0 0 0" quat="0.5 0.5 -0.5 0.5" mass="2" diaginertia="0.005625 0.0034125 0.0034125" />
          <joint name="fl_wheel_joint" pos="0 0 0" axis="0 1 0" damping="1.0" armature="0.02" frictionloss="0.0" />
          <geom pos="0.075 0.045 -0.075" quat="-0.499999 -0.500001 0.500001 0.499999" type="mesh" contype="3" conaffinity="3" group="1" density="0" rgba="0.1 0.1 0.1 1" mesh="packages_openflex_chassis_swerve_description_meshes_fl_wheel_link" />
        </body>
      </body>
      <body name="fr_steering_link" pos="0.21 -0.2735 -0.07">
        <inertial pos="0 0 0" quat="0.5 0.5 -0.5 0.5" mass="0.5" diaginertia="0.000225 0.000216667 0.000216667" />
        <joint name="fr_steering_joint" pos="0 0 0" axis="0 0 1" range="-1.5708 1.5708" actuatorfrcrange="-10 10" damping="3.0" armature="0.005" frictionloss="0.1" />
        <body name="fr_wheel_link" pos="0 0 -0.025">
          <inertial pos="0 0 0" quat="0.5 0.5 -0.5 0.5" mass="2" diaginertia="0.005625 0.0034125 0.0034125" />
          <joint name="fr_wheel_joint" pos="0 0 0" axis="0 1 0" damping="1.0" armature="0.02" frictionloss="0.0" />
          <geom pos="-0.075 -0.045 -0.075" quat="0.499999 0.500001 0.500001 0.499999" type="mesh" contype="3" conaffinity="3" group="1" density="0" rgba="0.1 0.1 0.1 1" mesh="packages_openflex_chassis_swerve_description_meshes_fr_wheel_link" />
        </body>
      </body>
      <body name="bl_steering_link" pos="-0.21 0.2735 -0.07">
        <inertial pos="0 0 0" quat="0.5 0.5 -0.5 0.5" mass="0.5" diaginertia="0.000225 0.000216667 0.000216667" />
        <joint name="bl_steering_joint" pos="0 0 0" axis="0 0 1" range="-1.5708 1.5708" actuatorfrcrange="-10 10" damping="3.0" armature="0.005" frictionloss="0.1" />
        <body name="bl_wheel_link" pos="0 0 -0.025">
          <inertial pos="0 0 0" quat="0.5 0.5 -0.5 0.5" mass="2" diaginertia="0.005625 0.0034125 0.0034125" />
          <joint name="bl_wheel_joint" pos="0 0 0" axis="0 1 0" damping="1.0" armature="0.02" frictionloss="0.0" />
          <geom pos="0.075 0.045 -0.075" quat="-0.499999 -0.500001 0.500001 0.499999" type="mesh" contype="3" conaffinity="3" group="1" density="0" rgba="0.1 0.1 0.1 1" mesh="packages_openflex_chassis_swerve_description_meshes_bl_wheel_link" />
        </body>
      </body>
      <body name="br_steering_link" pos="-0.21 -0.2735 -0.07">
        <inertial pos="0 0 0" quat="0.5 0.5 -0.5 0.5" mass="0.5" diaginertia="0.000225 0.000216667 0.000216667" />
        <joint name="br_steering_joint" pos="0 0 0" axis="0 0 1" range="-1.5708 1.5708" actuatorfrcrange="-10 10" damping="3.0" armature="0.005" frictionloss="0.1" />
        <body name="br_wheel_link" pos="0 0 -0.025">
          <inertial pos="0 0 0" quat="0.5 0.5 -0.5 0.5" mass="2" diaginertia="0.005625 0.0034125 0.0034125" />
          <joint name="br_wheel_joint" pos="0 0 0" axis="0 1 0" damping="1.0" armature="0.02" frictionloss="0.0" />
          <geom pos="-0.075 -0.045 -0.075" quat="0.499999 0.500001 0.500001 0.499999" type="mesh" contype="3" conaffinity="3" group="1" density="0" rgba="0.1 0.1 0.1 1" mesh="packages_openflex_chassis_swerve_description_meshes_br_wheel_link" />
        </body>
      </body>
      <body name="mid360_link" pos="0.3 0 0.12" quat="0.683011 -0.183013 0.183013 -0.683014">
        <inertial pos="0 0 0" quat="0.5 0.5 -0.5 0.5" mass="0.35" diaginertia="0.000214375 0.000153854 0.000153854" />
        <geom pos="-0.0328 0.0346 -0.0435" quat="0.707105 0.707108 0 0" type="mesh" contype="3" conaffinity="3" group="1" density="0" rgba="0.2 0.4 0.9 1" mesh="packages_openflex_chassis_swerve_description_meshes_mid360_link" />
        <body name="livox_frame">
          <inertial pos="0 0 0" mass="0.5" diaginertia="0.002 0.002 0.002" />
        </body>
        <body name="imu_link">
          <inertial pos="0 0 0" mass="0.5" diaginertia="0.002 0.002 0.002" />
        </body>
      </body>
      <body name="d435_link" pos="0.36 0 0.055">
        <inertial pos="0 0 0" quat="0.707107 0.707107 0 0" mass="0.1" diaginertia="7.27083e-05 7.27083e-05 1.04167e-05" />
        <geom pos="0.0152 0.0447 -0.0129" quat="0.499999 0.500001 -0.500001 -0.499999" type="mesh" contype="3" conaffinity="3" group="1" density="0" rgba="0.1 0.1 0.1 1" mesh="packages_openflex_chassis_swerve_description_meshes_d435_link" />
        <body name="camera_link">
          <inertial pos="0 0 0" mass="0.5" diaginertia="0.002 0.002 0.002" />
          <body name="camera_depth_frame">
            <inertial pos="0 0 0" mass="0.5" diaginertia="0.002 0.002 0.002" />
            <body name="camera_depth_optical_frame" quat="0.5 -0.5 0.5 -0.5">
              <inertial pos="0 0 0" mass="0.5" diaginertia="0.002 0.002 0.002" />
            </body>
          </body>
          <body name="camera_rgb_frame">
            <inertial pos="0 0 0" mass="0.5" diaginertia="0.002 0.002 0.002" />
            <body name="camera_rgb_optical_frame" quat="0.5 -0.5 0.5 -0.5">
              <inertial pos="0 0 0" mass="0.5" diaginertia="0.002 0.002 0.002" />
            </body>
          </body>
        </body>
        <body name="d435_depth_frame">
          <inertial pos="0 0 0" mass="0.5" diaginertia="0.002 0.002 0.002" />
          <body name="d435_depth_optical_frame" quat="0.5 -0.5 0.5 -0.5">
            <inertial pos="0 0 0" mass="0.5" diaginertia="0.002 0.002 0.002" />
          </body>
        </body>
        <body name="d435_color_frame">
          <inertial pos="0 0 0" mass="0.5" diaginertia="0.002 0.002 0.002" />
          <body name="d435_color_optical_frame" quat="0.5 -0.5 0.5 -0.5">
            <inertial pos="0 0 0" mass="0.5" diaginertia="0.002 0.002 0.002" />
          </body>
        </body>
      </body>
      <body name="gps_link" pos="0.06 0 0.24">
        <inertial pos="0 0 0" mass="0.5" diaginertia="0.002 0.002 0.002" />
      </body>
      <body name="lift_base_link" pos="-0.033 0 0.07" quat="0.707105 0 0 -0.707108">
        <inertial pos="4.73423e-05 -0.017555 0.663555" quat="0.707116 0.000552974 -0.00055296 0.707097" mass="9.62227" diaginertia="1.49187 1.46902 0.0318312" />
        <geom type="mesh" contype="3" conaffinity="3" group="1" density="0" rgba="0.48 0.48 0.5 1" mesh="packages_lift_slide_description_meshes_lift_link" />
        <body name="lift_carriage_link" pos="0 0 0.96">
          <inertial pos="-0.00061635 0.0527963 0.0200912" quat="0.706475 0.000381723 -0.000356955 0.707737" mass="2.32322" diaginertia="0.00863611 0.00730306 0.00642289" />
          <joint name="lift_joint" pos="0 0 0" axis="0 0 1" type="slide" range="-0.8 0.15" actuatorfrcrange="-3000 3000" damping="60.0" frictionloss="2.0" armature="0.1" />
          <geom type="mesh" contype="3" conaffinity="3" group="1" density="0" rgba="0.79216 0.81961 0.93333 1" mesh="packages_lift_slide_description_meshes_plate_link" />
          <body name="chest_link" pos="0 0.143 0.018">
            <inertial pos="0 0 0" mass="0.5" diaginertia="0.002 0.002 0.002" />
            <geom pos="-0.1558 0.1 -0.15" quat="0.707105 0.707108 0 0" type="mesh" contype="3" conaffinity="3" group="1" density="0" rgba="0.92 0.92 0.94 1" mesh="packages_lift_slide_description_meshes_chest_link" />
          </body>
          <body name="left_link0_base" pos="-0.075 0.14555 0.025" quat="0.499998 -0.5 -0.500002 0.5">
            <inertial pos="-0.000217889 0 -0.00249049" quat="0.999048 0 0.0436194 0" mass="9.81748e-05" diaginertia="3.57929e-10 3.57929e-10 3.06796e-10" />
            <geom type="mesh" contype="3" conaffinity="3" group="1" density="0" rgba="0.79216 0.81961 0.93333 1" mesh="packages_lift_slide_description_meshes_left_link0_base" />
            <body name="openarmx_left_link0">
              <inertial pos="0.000319 -0.00067 0.029184" quat="0.497862 0.511796 -0.475431 0.513968" mass="1.77268" diaginertia="0.00341526 0.00246403 0.00195971" />
              <geom name="openarmx_left_link0_visual_part0" type="mesh" contype="3" conaffinity="3" group="1" density="0" rgba="0.5 0.5 0.55 1" mesh="packages_openarmx_description_meshes_arm_v10_visual_link0_mirror_pnp_part0" />
              <geom name="openarmx_left_link0_visual_part1" type="mesh" contype="3" conaffinity="3" group="1" density="0" rgba="0.92 0.92 0.95 1" mesh="packages_openarmx_description_meshes_arm_v10_visual_link0_mirror_pnp_part1" />
              <body name="openarmx_left_link1" pos="0 0 0.058">
                <inertial pos="0.004452 2.5e-05 0.073323" quat="0.999503 0.000644393 -0.0315003 0.00114209" mass="1.68876" diaginertia="0.00346919 0.002551 0.00190982" />
                <joint name="openarmx_left_joint1" pos="0 0 0" axis="0 0 1" range="-3.3444 0.905604" actuatorfrcrange="-120 120" damping="18.0" armature="0.03" frictionloss="0.15" />
                <geom name="openarmx_left_link1_visual_part0" type="mesh" contype="3" conaffinity="3" group="1" density="0" rgba="0.5 0.5 0.55 1" mesh="packages_openarmx_description_meshes_arm_v10_visual_link1_mirror_pnp_part0" />
                <geom name="openarmx_left_link1_visual_part1" type="mesh" contype="3" conaffinity="3" group="1" density="0" rgba="0.92 0.92 0.95 1" mesh="packages_openarmx_description_meshes_arm_v10_visual_link1_mirror_pnp_part1" />
                <body name="openarmx_left_link2" pos="-0.0205 0 0.081" quat="0.707105 -0.707108 0 0">
                  <inertial pos="-0.003787 -0.000221 0.04901" quat="0.986716 -0.00145381 -0.161354 -0.0188355" mass="0.396704" diaginertia="0.000891196 0.000821946 0.000327857" />
                  <joint name="openarmx_left_joint2" pos="0 0 0" axis="-1 0 0" range="-3.2708 0.129204" actuatorfrcrange="-120 120" damping="18.0" armature="0.03" frictionloss="0.15" />
                  <geom name="openarmx_left_link2_visual_part0" type="mesh" contype="3" conaffinity="3" group="1" density="0" rgba="0.5 0.5 0.55 1" mesh="packages_openarmx_description_meshes_arm_v10_visual_link2_mirror_pnp_part0" />
                  <geom name="openarmx_left_link2_visual_part1" type="mesh" contype="3" conaffinity="3" group="1" density="0" rgba="0.15 0.65 0.7 1" mesh="packages_openarmx_description_meshes_arm_v10_visual_link2_mirror_pnp_part1" />
                  <body name="openarmx_left_link3" pos="0.02 0 0.099">
                    <inertial pos="-0.000828 -0.000236 0.083336" quat="0.946133 0.00530809 0.00424656 -0.323707" mass="2.49278" diaginertia="0.0103641 0.0103322 0.00300164" />
                    <joint name="openarmx_left_joint3" pos="0 0 0" axis="0 0 1" range="-1.57 1.57" actuatorfrcrange="-60 60" damping="18.0" armature="0.03" frictionloss="0.15" />
                    <geom name="openarmx_left_link3_visual_part0" type="mesh" contype="3" conaffinity="3" group="1" density="0" rgba="0.5 0.5 0.55 1" mesh="packages_openarmx_description_meshes_arm_v10_visual_link3_mirror_pnp_part0" />
                    <geom name="openarmx_left_link3_visual_part1" type="mesh" contype="3" conaffinity="3" group="1" density="0" rgba="0.92 0.92 0.95 1" mesh="packages_openarmx_description_meshes_arm_v10_visual_link3_mirror_pnp_part1" />
                    <body name="openarmx_left_link4" pos="0 0.031002 0.14181">
                      <inertial pos="-0.002591 -0.030135 0.07147" quat="0.999683 -0.0233783 -0.00922341 -0.00115143" mass="0.779755" diaginertia="0.00201543 0.00162187 0.000765704" />
                      <joint name="openarmx_left_joint4" pos="0 0 0" axis="0 1 0" range="0 1.8" actuatorfrcrange="-60 60" damping="18.0" armature="0.03" frictionloss="0.15" />
                      <geom name="openarmx_left_link4_visual_part0" type="mesh" contype="3" conaffinity="3" group="1" density="0" rgba="0.5 0.5 0.55 1" mesh="packages_openarmx_description_meshes_arm_v10_visual_link4_part0" />
                      <geom name="openarmx_left_link4_visual_part1" type="mesh" contype="3" conaffinity="3" group="1" density="0" rgba="0.15 0.65 0.7 1" mesh="packages_openarmx_description_meshes_arm_v10_visual_link4_part1" />
                      <body name="openarmx_left_link4_ext" pos="0 -0.065 0">
                        <inertial pos="0 0 0" mass="0.5" diaginertia="0.002 0.002 0.002" />
                      </body>
                      <body name="openarmx_left_link5" pos="0 -0.0309 0.126">
                        <inertial pos="-0.002256 -0.000305 0.0533" quat="0.714458 -0.0122081 -0.0110113 0.699485" mass="0.687255" diaginertia="0.00106611 0.000831256 0.000495637" />
                        <joint name="openarmx_left_joint5" pos="0 0 0" axis="0 0 1" range="-1.5 1.5" actuatorfrcrange="-14 14" damping="18.0" armature="0.03" frictionloss="0.15" />
                        <geom name="openarmx_left_link5_visual_part0" type="mesh" contype="3" conaffinity="3" group="1" density="0" rgba="0.5 0.5 0.55 1" mesh="packages_openarmx_description_meshes_arm_v10_visual_link5_mirror_pnp_part0" />
                        <geom name="openarmx_left_link5_visual_part1" type="mesh" contype="3" conaffinity="3" group="1" density="0" rgba="0.92 0.92 0.95 1" mesh="packages_openarmx_description_meshes_arm_v10_visual_link5_mirror_pnp_part1" />
                        <body name="openarmx_left_link6" pos="0.037426 0 0.131">
                          <inertial pos="-0.03564 0.005114 -0.003582" quat="0.945265 0.038546 0.187709 -0.26411" mass="0.384836" diaginertia="0.000317632 0.000265263 0.000212105" />
                          <joint name="openarmx_left_joint6" pos="0 0 0" axis="1 0 0" range="-0.75 0.75" actuatorfrcrange="-14 14" damping="18.0" armature="0.03" frictionloss="0.15" />
                          <geom name="openarmx_left_link6_visual_part0" type="mesh" contype="3" conaffinity="3" group="1" density="0" rgba="0.5 0.5 0.55 1" mesh="packages_openarmx_description_meshes_arm_v10_visual_link6_mirror_pnp_part0" />
                          <geom name="openarmx_left_link6_visual_part1" type="mesh" contype="3" conaffinity="3" group="1" density="0" rgba="0.8 0.8 0.82 1" mesh="packages_openarmx_description_meshes_arm_v10_visual_link6_mirror_pnp_part1" />
                          <body name="openarmx_left_link7" pos="-0.0375 0 0">
                            <inertial pos="-3e-06 -0.002128 0.091961" quat="0.98918 -0.138774 0.00159491 -0.0475613" mass="0.624972" diaginertia="0.00160275 0.00108708 0.000759171" />
                            <joint name="openarmx_left_joint7" pos="0 0 0" axis="0 -1 0" range="-1.4 1.4" actuatorfrcrange="-14 14" damping="18.0" armature="0.03" frictionloss="0.15" />
                            <geom name="openarmx_left_link7_visual_part0" type="mesh" contype="3" conaffinity="3" group="1" density="0" rgba="0.5 0.5 0.55 1" mesh="packages_openarmx_description_meshes_arm_v10_visual_link7_mirror_pnp_part0" />
                            <geom name="openarmx_left_link7_visual_part1" type="mesh" contype="3" conaffinity="3" group="1" density="0" rgba="0.3 0.7 1 1" mesh="packages_openarmx_description_meshes_arm_v10_visual_link7_mirror_pnp_part1" />
                            <body name="openarmx_left_link7_pico" quat="2.59736e-06 -0.707103 -0.707111 -2.59733e-06">
                              <inertial pos="0 0 0" mass="0.5" diaginertia="0.002 0.002 0.002" />
                            </body>
                            <body name="openarmx_left_hand" pos="0 0 0.1001">
                              <inertial pos="0 0.002 0.03" quat="0.547194 0.546814 -0.44595 0.450224" mass="0.35" diaginertia="0.000252306 0.000247103 1.76214e-05" />
                              <geom name="openarmx_left_hand_visual_part0" pos="0 0 -0.6585" quat="1 0 0 0" type="mesh" contype="3" conaffinity="3" group="1" density="0" rgba="0.5 0.5 0.55 1" mesh="packages_openarmx_description_meshes_ee_openarmx_hand_visual_hand_part0" />
                              <geom name="openarmx_left_hand_visual_part1" pos="0 0 -0.6585" quat="1 0 0 0" type="mesh" contype="3" conaffinity="3" group="1" density="0" rgba="0.92 0.92 0.95 1" mesh="packages_openarmx_description_meshes_ee_openarmx_hand_visual_hand_part1" />
                              <body name="openarmx_left_hand_tcp" pos="0 0 0.08">
                                <inertial pos="0 0 0" mass="0.5" diaginertia="0.002 0.002 0.002" />
                              </body>
                              <body name="openarmx_left_right_finger" pos="0 -0.006 0.015">
                                <inertial pos="0.0064528 -0.01702 0.0219685" mass="0.0360255" diaginertia="2.375e-06 2.375e-06 7.5e-07" />
                                <joint name="openarmx_left_finger_joint1" pos="0 0 0" axis="0 -1 0" type="slide" range="0 0.044" actuatorfrcrange="-333 333" damping="2.0" armature="0.002" frictionloss="0.02" />
                                <geom name="openarmx_left_right_finger_visual_part0" pos="0 0.05 -0.673001" quat="1 0 0 0" type="mesh" contype="3" conaffinity="3" group="1" density="0" rgba="0.5 0.5 0.55 1" mesh="packages_openarmx_description_meshes_ee_openarmx_hand_visual_finger_mirror_pnp_part0" />
                                <geom name="openarmx_left_right_finger_visual_part1" pos="0 0.05 -0.673001" quat="1 0 0 0" type="mesh" contype="3" conaffinity="3" group="1" density="0" rgba="0.25 0.25 0.25 1" mesh="packages_openarmx_description_meshes_ee_openarmx_hand_visual_finger_mirror_pnp_part1" />
                              </body>
                              <body name="openarmx_left_left_finger" pos="0 0.006 0.015">
                                <inertial pos="0.0064528 0.01702 0.0219685" mass="0.0360255" diaginertia="2.375e-06 2.375e-06 7.5e-07" />
                                <joint name="openarmx_left_finger_joint2" pos="0 0 0" axis="0 1 0" type="slide" range="0 0.044" actuatorfrcrange="-333 333" />
                                <geom name="openarmx_left_left_finger_visual_part0" pos="0 -0.05 -0.673001" quat="1 0 0 0" type="mesh" contype="3" conaffinity="3" group="1" density="0" rgba="0.5 0.5 0.55 1" mesh="packages_openarmx_description_meshes_ee_openarmx_hand_visual_finger_part0" />
                                <geom name="openarmx_left_left_finger_visual_part1" pos="0 -0.05 -0.673001" quat="1 0 0 0" type="mesh" contype="3" conaffinity="3" group="1" density="0" rgba="0.25 0.25 0.25 1" mesh="packages_openarmx_description_meshes_ee_openarmx_hand_visual_finger_part1" />
                              </body>
                            </body>
                          </body>
                        </body>
                      </body>
                    </body>
                  </body>
                </body>
              </body>
            </body>
          </body>
          <body name="right_link0_base" pos="0.075 0.14555 0.025" quat="0.499998 0.5 0.500002 0.5">
            <inertial pos="-0.000217889 0 -0.00249049" quat="0.999048 0 0.0436194 0" mass="9.81748e-05" diaginertia="3.57929e-10 3.57929e-10 3.06796e-10" />
            <geom type="mesh" contype="3" conaffinity="3" group="1" density="0" rgba="0.79216 0.81961 0.93333 1" mesh="packages_lift_slide_description_meshes_right_link0_base" />
            <body name="openarmx_right_link0">
              <inertial pos="0.000319 0.00067 0.029184" quat="0.497862 0.511796 -0.475431 0.513968" mass="1.77268" diaginertia="0.00341526 0.00246403 0.00195971" />
              <geom name="openarmx_right_link0_visual_part0" type="mesh" contype="3" conaffinity="3" group="1" density="0" rgba="0.5 0.5 0.55 1" mesh="packages_openarmx_description_meshes_arm_v10_visual_link0_part0" />
              <geom name="openarmx_right_link0_visual_part1" type="mesh" contype="3" conaffinity="3" group="1" density="0" rgba="0.92 0.92 0.95 1" mesh="packages_openarmx_description_meshes_arm_v10_visual_link0_part1" />
              <body name="openarmx_right_link1" pos="0 0 0.058">
                <inertial pos="0.004452 -2.5e-05 0.073323" quat="0.999503 0.000644393 -0.0315003 0.00114209" mass="1.68876" diaginertia="0.00346919 0.002551 0.00190982" />
                <joint name="openarmx_right_joint1" pos="0 0 0" axis="0 0 1" range="-1.25 3" actuatorfrcrange="-120 120" damping="18.0" armature="0.03" frictionloss="0.15" />
                <geom name="openarmx_right_link1_visual_part0" type="mesh" contype="3" conaffinity="3" group="1" density="0" rgba="0.5 0.5 0.55 1" mesh="packages_openarmx_description_meshes_arm_v10_visual_link1_part0" />
                <geom name="openarmx_right_link1_visual_part1" type="mesh" contype="3" conaffinity="3" group="1" density="0" rgba="0.92 0.92 0.95 1" mesh="packages_openarmx_description_meshes_arm_v10_visual_link1_part1" />
                <body name="openarmx_right_link2" pos="-0.0205 0 0.081" quat="0.707105 0.707108 0 0">
                  <inertial pos="-0.003787 0.000221 0.04901" quat="0.986716 -0.00145381 -0.161354 -0.0188355" mass="0.396704" diaginertia="0.000891196 0.000821946 0.000327857" />
                  <joint name="openarmx_right_joint2" pos="0 0 0" axis="-1 0 0" range="-0.129204 3.2708" actuatorfrcrange="-120 120" damping="18.0" armature="0.03" frictionloss="0.15" />
                  <geom name="openarmx_right_link2_visual_part0" type="mesh" contype="3" conaffinity="3" group="1" density="0" rgba="0.5 0.5 0.55 1" mesh="packages_openarmx_description_meshes_arm_v10_visual_link2_part0" />
                  <geom name="openarmx_right_link2_visual_part1" type="mesh" contype="3" conaffinity="3" group="1" density="0" rgba="0.15 0.65 0.7 1" mesh="packages_openarmx_description_meshes_arm_v10_visual_link2_part1" />
                  <body name="openarmx_right_link3" pos="0.02 0 0.099">
                    <inertial pos="-0.000828 0.000236 0.083336" quat="0.946133 0.00530809 0.00424656 -0.323707" mass="2.49278" diaginertia="0.0103641 0.0103322 0.00300164" />
                    <joint name="openarmx_right_joint3" pos="0 0 0" axis="0 0 1" range="-1.57 1.57" actuatorfrcrange="-60 60" damping="18.0" armature="0.03" frictionloss="0.15" />
                    <geom name="openarmx_right_link3_visual_part0" type="mesh" contype="3" conaffinity="3" group="1" density="0" rgba="0.5 0.5 0.55 1" mesh="packages_openarmx_description_meshes_arm_v10_visual_link3_part0" />
                    <geom name="openarmx_right_link3_visual_part1" type="mesh" contype="3" conaffinity="3" group="1" density="0" rgba="0.92 0.92 0.95 1" mesh="packages_openarmx_description_meshes_arm_v10_visual_link3_part1" />
                    <body name="openarmx_right_link4" pos="0 0.031002 0.14181">
                      <inertial pos="-0.002591 -0.030135 0.07147" quat="0.999683 -0.0233783 -0.00922341 -0.00115143" mass="0.779755" diaginertia="0.00201543 0.00162187 0.000765704" />
                      <joint name="openarmx_right_joint4" pos="0 0 0" axis="0 1 0" range="0 1.8" actuatorfrcrange="-60 60" damping="18.0" armature="0.03" frictionloss="0.15" />
                      <geom name="openarmx_right_link4_visual_part0" type="mesh" contype="3" conaffinity="3" group="1" density="0" rgba="0.5 0.5 0.55 1" mesh="packages_openarmx_description_meshes_arm_v10_visual_link4_part0" />
                      <geom name="openarmx_right_link4_visual_part1" type="mesh" contype="3" conaffinity="3" group="1" density="0" rgba="0.15 0.65 0.7 1" mesh="packages_openarmx_description_meshes_arm_v10_visual_link4_part1" />
                      <body name="openarmx_right_link4_ext">
                        <inertial pos="0 0 0" mass="0.5" diaginertia="0.002 0.002 0.002" />
                      </body>
                      <body name="openarmx_right_link5" pos="0 -0.0309 0.126">
                        <inertial pos="-0.002256 0.000305 0.0533" quat="0.714458 -0.0122081 -0.0110113 0.699485" mass="0.687255" diaginertia="0.00106611 0.000831256 0.000495637" />
                        <joint name="openarmx_right_joint5" pos="0 0 0" axis="0 0 1" range="-1.5 1.5" actuatorfrcrange="-14 14" damping="18.0" armature="0.03" frictionloss="0.15" />
                        <geom name="openarmx_right_link5_visual_part0" type="mesh" contype="3" conaffinity="3" group="1" density="0" rgba="0.5 0.5 0.55 1" mesh="packages_openarmx_description_meshes_arm_v10_visual_link5_part0" />
                        <geom name="openarmx_right_link5_visual_part1" type="mesh" contype="3" conaffinity="3" group="1" density="0" rgba="0.92 0.92 0.95 1" mesh="packages_openarmx_description_meshes_arm_v10_visual_link5_part1" />
                        <body name="openarmx_right_link6" pos="0.037426 0 0.131">
                          <inertial pos="-0.03564 -0.005114 -0.003582" quat="0.945265 0.038546 0.187709 -0.26411" mass="0.384836" diaginertia="0.000317632 0.000265263 0.000212105" />
                          <joint name="openarmx_right_joint6" pos="0 0 0" axis="1 0 0" range="-0.75 0.75" actuatorfrcrange="-14 14" damping="18.0" armature="0.03" frictionloss="0.15" />
                          <geom name="openarmx_right_link6_visual_part0" type="mesh" contype="3" conaffinity="3" group="1" density="0" rgba="0.5 0.5 0.55 1" mesh="packages_openarmx_description_meshes_arm_v10_visual_link6_part0" />
                          <geom name="openarmx_right_link6_visual_part1" type="mesh" contype="3" conaffinity="3" group="1" density="0" rgba="0.8 0.8 0.82 1" mesh="packages_openarmx_description_meshes_arm_v10_visual_link6_part1" />
                          <body name="openarmx_right_link7" pos="-0.0375 0 0">
                            <inertial pos="-3e-06 0.002128 0.091961" quat="0.98918 -0.138774 0.00159491 -0.0475613" mass="0.624972" diaginertia="0.00160275 0.00108708 0.000759171" />
                            <joint name="openarmx_right_joint7" pos="0 0 0" axis="0 1 0" range="-1.4 1.4" actuatorfrcrange="-14 14" damping="18.0" armature="0.03" frictionloss="0.15" />
                            <geom name="openarmx_right_link7_visual_part0" type="mesh" contype="3" conaffinity="3" group="1" density="0" rgba="0.5 0.5 0.55 1" mesh="packages_openarmx_description_meshes_arm_v10_visual_link7_part0" />
                            <geom name="openarmx_right_link7_visual_part1" type="mesh" contype="3" conaffinity="3" group="1" density="0" rgba="0.3 0.7 1 1" mesh="packages_openarmx_description_meshes_arm_v10_visual_link7_part1" />
                            <body name="openarmx_right_link7_pico" quat="2.59736e-06 -0.707103 -0.707111 -2.59733e-06">
                              <inertial pos="0 0 0" mass="0.5" diaginertia="0.002 0.002 0.002" />
                            </body>
                            <body name="openarmx_right_hand" pos="0 0 0.1001">
                              <inertial pos="0 0.002 0.03" quat="0.547194 0.546814 -0.44595 0.450224" mass="0.35" diaginertia="0.000252306 0.000247103 1.76214e-05" />
                              <geom name="openarmx_right_hand_visual_part0" pos="0 0 -0.6585" quat="1 0 0 0" type="mesh" contype="3" conaffinity="3" group="1" density="0" rgba="0.5 0.5 0.55 1" mesh="packages_openarmx_description_meshes_ee_openarmx_hand_visual_hand_part0" />
                              <geom name="openarmx_right_hand_visual_part1" pos="0 0 -0.6585" quat="1 0 0 0" type="mesh" contype="3" conaffinity="3" group="1" density="0" rgba="0.92 0.92 0.95 1" mesh="packages_openarmx_description_meshes_ee_openarmx_hand_visual_hand_part1" />
                              <body name="openarmx_right_hand_tcp" pos="0 0 0.08">
                                <inertial pos="0 0 0" mass="0.5" diaginertia="0.002 0.002 0.002" />
                              </body>
                              <body name="openarmx_right_right_finger" pos="0 -0.006 0.015">
                                <inertial pos="0.0064528 -0.01702 0.0219685" mass="0.0360255" diaginertia="2.375e-06 2.375e-06 7.5e-07" />
                                <joint name="openarmx_right_finger_joint1" pos="0 0 0" axis="0 -1 0" type="slide" range="0 0.044" actuatorfrcrange="-333 333" damping="2.0" armature="0.002" frictionloss="0.02" />
                                <geom name="openarmx_right_right_finger_visual_part0" pos="0 0.05 -0.673001" quat="1 0 0 0" type="mesh" contype="3" conaffinity="3" group="1" density="0" rgba="0.5 0.5 0.55 1" mesh="packages_openarmx_description_meshes_ee_openarmx_hand_visual_finger_mirror_pnp_part0" />
                                <geom name="openarmx_right_right_finger_visual_part1" pos="0 0.05 -0.673001" quat="1 0 0 0" type="mesh" contype="3" conaffinity="3" group="1" density="0" rgba="0.25 0.25 0.25 1" mesh="packages_openarmx_description_meshes_ee_openarmx_hand_visual_finger_mirror_pnp_part1" />
                              </body>
                              <body name="openarmx_right_left_finger" pos="0 0.006 0.015">
                                <inertial pos="0.0064528 0.01702 0.0219685" mass="0.0360255" diaginertia="2.375e-06 2.375e-06 7.5e-07" />
                                <joint name="openarmx_right_finger_joint2" pos="0 0 0" axis="0 1 0" type="slide" range="0 0.044" actuatorfrcrange="-333 333" />
                                <geom name="openarmx_right_left_finger_visual_part0" pos="0 -0.05 -0.673001" quat="1 0 0 0" type="mesh" contype="3" conaffinity="3" group="1" density="0" rgba="0.5 0.5 0.55 1" mesh="packages_openarmx_description_meshes_ee_openarmx_hand_visual_finger_part0" />
                                <geom name="openarmx_right_left_finger_visual_part1" pos="0 -0.05 -0.673001" quat="1 0 0 0" type="mesh" contype="3" conaffinity="3" group="1" density="0" rgba="0.25 0.25 0.25 1" mesh="packages_openarmx_description_meshes_ee_openarmx_hand_visual_finger_part1" />
                              </body>
                            </body>
                          </body>
                        </body>
                      </body>
                    </body>
                  </body>
                </body>
              </body>
            </body>
          </body>
          <body name="head_base_link" pos="0 0.14 0.1">
            <inertial pos="0 0 0" mass="0.5" diaginertia="0.002 0.002 0.002" />
            <geom pos="-0.563 0.0866 0" quat="0.707107 0.707107 0 0" type="mesh" contype="3" conaffinity="3" group="1" density="0" mesh="packages_openarmx_head_description_meshes_visual_TBBJ-04_neck_mount" />
            <geom pos="-0.563 0.0866 0" quat="0.707107 0.707107 0 0" type="mesh" contype="3" conaffinity="3" group="1" density="0" mesh="packages_openarmx_head_description_meshes_visual_TBBJ-02_neck_bracket" />
            <geom pos="-0.563 0.0866 0" quat="0.707107 0.707107 0 0" type="mesh" contype="3" conaffinity="3" group="1" density="0" mesh="packages_openarmx_head_description_meshes_visual_TBBJ-06_neck_limit" />
            <geom pos="-0.563 0.0866 0" quat="0.707107 0.707107 0 0" type="mesh" contype="3" conaffinity="3" group="1" density="0" rgba="0.2 0.2 0.2 1" mesh="packages_openarmx_head_description_meshes_visual_RS00_motor_2" />
            <body name="head_pitch_link" pos="0.0001 0.0068 0.0395">
              <inertial pos="0 0 0" mass="0.5" diaginertia="0.002 0.002 0.002" />
              <joint name="openarmx_head_pitch_joint" pos="0 0 0" axis="1 0 0" range="-1.5708 1.5708" actuatorfrcrange="-14 14" damping="2.0" armature="0.01" frictionloss="0.05" />
              <geom pos="-0.5631 0.0798 -0.0395" quat="0.707107 0.707107 0 0" type="mesh" contype="3" conaffinity="3" group="1" density="0" rgba="0.9 0.9 0.9 1" mesh="packages_openarmx_head_description_meshes_visual_DY-03_neck_cover" />
              <geom pos="-0.5631 0.0798 -0.0395" quat="0.707107 0.707107 0 0" type="mesh" contype="3" conaffinity="3" group="1" density="0" rgba="0.2 0.2 0.2 1" mesh="packages_openarmx_head_description_meshes_visual_RS00_motor_1" />
              <geom pos="-0.5631 0.0798 -0.0395" quat="0.707107 0.707107 0 0" type="mesh" contype="3" conaffinity="3" group="1" density="0" mesh="packages_openarmx_head_description_meshes_visual_TB-01_head_connector" />
              <geom pos="-0.5631 0.0798 -0.0395" quat="0.707107 0.707107 0 0" type="mesh" contype="3" conaffinity="3" group="1" density="0" mesh="packages_openarmx_head_description_meshes_visual_TBBJ-03_guard_plate" />
              <body name="head_yaw_link" pos="0 -0.0026 0.0677">
                <inertial pos="0 0 0" mass="0.5" diaginertia="0.002 0.002 0.002" />
                <joint name="openarmx_head_yaw_joint" pos="0 0 0" axis="0 0 1" range="-1.5708 1.5708" actuatorfrcrange="-14 14" damping="2.0" armature="0.01" frictionloss="0.05" />
                <geom pos="-0.5631 0.0824 -0.1072" quat="0.707107 0.707107 0 0" type="mesh" contype="3" conaffinity="3" group="1" density="0" mesh="packages_openarmx_head_description_meshes_visual_TBBJ-01_head_bracket" />
                <geom pos="-0.5631 0.0824 -0.1072" quat="0.707107 0.707107 0 0" type="mesh" contype="3" conaffinity="3" group="1" density="0" mesh="packages_openarmx_head_description_meshes_visual_TBBJ-05_head_limit" />
                <geom pos="-0.5631 0.0824 -0.1072" quat="0.707107 0.707107 0 0" type="mesh" contype="3" conaffinity="3" group="1" density="0" rgba="0.9 0.9 0.9 1" mesh="packages_openarmx_head_description_meshes_visual_DY-01_head_front_shell" />
                <geom pos="-0.5631 0.0824 -0.1072" quat="0.707107 0.707107 0 0" type="mesh" contype="3" conaffinity="3" group="1" density="0" rgba="0.9 0.9 0.9 1" mesh="packages_openarmx_head_description_meshes_visual_DY-02_head_rear_shell" />
                <geom pos="-0.5631 0.0824 -0.1072" quat="0.707107 0.707107 0 0" type="mesh" contype="3" conaffinity="3" group="1" density="0" rgba="0.1 0.1 0.1 1" mesh="packages_openarmx_head_description_meshes_visual_femto_bolt_camera" />
              </body>
            </body>
          </body>
        </body>
      </body>
    </body>
  </body><light name="key_light" pos="-1.4 -2.2 3.2" dir="0.35 0.55 -1" directional="true" diffuse="0.95 0.92 0.86" specular="0.35 0.35 0.35" />
<light name="fill_light" pos="1.8 1.4 2.2" dir="-0.45 -0.35 -1" directional="true" diffuse="0.35 0.45 0.65" specular="0.12 0.12 0.16" />
<light name="rim_light" pos="0 2.2 1.8" dir="0 -1 -0.45" directional="true" diffuse="0.55 0.65 0.85" specular="0.20 0.22 0.28" />
<geom name="floor" type="plane" pos="0 0 0" size="2.4 2.4 0.02" material="floor_mat" contype="1" conaffinity="3" /></worldbody>
<visual><headlight diffuse="0.55 0.55 0.55" ambient="0.24 0.24 0.26" specular="0.25 0.25 0.25" />
  <map znear="0.01" zfar="8" />
  <scale forcewidth="0.06" contactwidth="0.05" />
  <rgba haze="0.03 0.035 0.045 1" />
</visual><contact><exclude body1="openflex_robot_yaw_root" body2="base_link" /><exclude body1="base_link" body2="base_footprint" /><exclude body1="base_link" body2="fl_steering_link" /><exclude body1="fl_steering_link" body2="fl_wheel_link" /><exclude body1="base_link" body2="fr_steering_link" /><exclude body1="fr_steering_link" body2="fr_wheel_link" /><exclude body1="base_link" body2="bl_steering_link" /><exclude body1="bl_steering_link" body2="bl_wheel_link" /><exclude body1="base_link" body2="br_steering_link" /><exclude body1="br_steering_link" body2="br_wheel_link" /><exclude body1="base_link" body2="mid360_link" /><exclude body1="mid360_link" body2="livox_frame" /><exclude body1="mid360_link" body2="imu_link" /><exclude body1="base_link" body2="d435_link" /><exclude body1="d435_link" body2="camera_link" /><exclude body1="camera_link" body2="camera_depth_frame" /><exclude body1="camera_depth_frame" body2="camera_depth_optical_frame" /><exclude body1="camera_link" body2="camera_rgb_frame" /><exclude body1="camera_rgb_frame" body2="camera_rgb_optical_frame" /><exclude body1="d435_link" body2="d435_depth_frame" /><exclude body1="d435_depth_frame" body2="d435_depth_optical_frame" /><exclude body1="d435_link" body2="d435_color_frame" /><exclude body1="d435_color_frame" body2="d435_color_optical_frame" /><exclude body1="base_link" body2="gps_link" /><exclude body1="base_link" body2="lift_base_link" /><exclude body1="lift_base_link" body2="lift_carriage_link" /><exclude body1="lift_carriage_link" body2="chest_link" /><exclude body1="lift_carriage_link" body2="left_link0_base" /><exclude body1="left_link0_base" body2="openarmx_left_link0" /><exclude body1="openarmx_left_link0" body2="openarmx_left_link1" /><exclude body1="openarmx_left_link1" body2="openarmx_left_link2" /><exclude body1="openarmx_left_link2" body2="openarmx_left_link3" /><exclude body1="openarmx_left_link3" body2="openarmx_left_link4" /><exclude body1="openarmx_left_link4" body2="openarmx_left_link4_ext" /><exclude body1="openarmx_left_link4" body2="openarmx_left_link5" /><exclude body1="openarmx_left_link5" body2="openarmx_left_link6" /><exclude body1="openarmx_left_link6" body2="openarmx_left_link7" /><exclude body1="openarmx_left_link7" body2="openarmx_left_link7_pico" /><exclude body1="openarmx_left_link7" body2="openarmx_left_hand" /><exclude body1="openarmx_left_hand" body2="openarmx_left_hand_tcp" /><exclude body1="openarmx_left_hand" body2="openarmx_left_right_finger" /><exclude body1="openarmx_left_hand" body2="openarmx_left_left_finger" /><exclude body1="lift_carriage_link" body2="right_link0_base" /><exclude body1="right_link0_base" body2="openarmx_right_link0" /><exclude body1="openarmx_right_link0" body2="openarmx_right_link1" /><exclude body1="openarmx_right_link1" body2="openarmx_right_link2" /><exclude body1="openarmx_right_link2" body2="openarmx_right_link3" /><exclude body1="openarmx_right_link3" body2="openarmx_right_link4" /><exclude body1="openarmx_right_link4" body2="openarmx_right_link4_ext" /><exclude body1="openarmx_right_link4" body2="openarmx_right_link5" /><exclude body1="openarmx_right_link5" body2="openarmx_right_link6" /><exclude body1="openarmx_right_link6" body2="openarmx_right_link7" /><exclude body1="openarmx_right_link7" body2="openarmx_right_link7_pico" /><exclude body1="openarmx_right_link7" body2="openarmx_right_hand" /><exclude body1="openarmx_right_hand" body2="openarmx_right_hand_tcp" /><exclude body1="openarmx_right_hand" body2="openarmx_right_right_finger" /><exclude body1="openarmx_right_hand" body2="openarmx_right_left_finger" /><exclude body1="lift_carriage_link" body2="head_base_link" /><exclude body1="head_base_link" body2="head_pitch_link" /><exclude body1="head_pitch_link" body2="head_yaw_link" /><exclude body1="world" body2="base_link" /><exclude body1="world" body2="base_footprint" /><exclude body1="world" body2="fl_steering_link" /><exclude body1="world" body2="fl_wheel_link" /><exclude body1="world" body2="fr_steering_link" /><exclude body1="world" body2="fr_wheel_link" /><exclude body1="world" body2="bl_steering_link" /><exclude body1="world" body2="bl_wheel_link" /><exclude body1="world" body2="br_steering_link" /><exclude body1="world" body2="br_wheel_link" /><exclude body1="world" body2="mid360_link" /><exclude body1="world" body2="livox_frame" /><exclude body1="world" body2="imu_link" /><exclude body1="world" body2="d435_link" /><exclude body1="world" body2="camera_link" /><exclude body1="world" body2="camera_depth_frame" /><exclude body1="world" body2="camera_depth_optical_frame" /><exclude body1="world" body2="camera_rgb_frame" /><exclude body1="world" body2="camera_rgb_optical_frame" /><exclude body1="world" body2="d435_depth_frame" /><exclude body1="world" body2="d435_depth_optical_frame" /><exclude body1="world" body2="d435_color_frame" /><exclude body1="world" body2="d435_color_optical_frame" /><exclude body1="world" body2="gps_link" /><exclude body1="world" body2="lift_base_link" /><exclude body1="world" body2="lift_carriage_link" /><exclude body1="world" body2="chest_link" /><exclude body1="world" body2="left_link0_base" /><exclude body1="world" body2="right_link0_base" /><exclude body1="world" body2="head_base_link" /><exclude body1="world" body2="head_pitch_link" /><exclude body1="world" body2="head_yaw_link" /><exclude body1="base_link" body2="base_footprint" /><exclude body1="base_link" body2="fl_steering_link" /><exclude body1="base_link" body2="fl_wheel_link" /><exclude body1="base_link" body2="fr_steering_link" /><exclude body1="base_link" body2="fr_wheel_link" /><exclude body1="base_link" body2="bl_steering_link" /><exclude body1="base_link" body2="bl_wheel_link" /><exclude body1="base_link" body2="br_steering_link" /><exclude body1="base_link" body2="br_wheel_link" /><exclude body1="base_link" body2="mid360_link" /><exclude body1="base_link" body2="livox_frame" /><exclude body1="base_link" body2="imu_link" /><exclude body1="base_link" body2="d435_link" /><exclude body1="base_link" body2="camera_link" /><exclude body1="base_link" body2="camera_depth_frame" /><exclude body1="base_link" body2="camera_depth_optical_frame" /><exclude body1="base_link" body2="camera_rgb_frame" /><exclude body1="base_link" body2="camera_rgb_optical_frame" /><exclude body1="base_link" body2="d435_depth_frame" /><exclude body1="base_link" body2="d435_depth_optical_frame" /><exclude body1="base_link" body2="d435_color_frame" /><exclude body1="base_link" body2="d435_color_optical_frame" /><exclude body1="base_link" body2="gps_link" /><exclude body1="base_link" body2="lift_base_link" /><exclude body1="base_link" body2="lift_carriage_link" /><exclude body1="base_link" body2="chest_link" /><exclude body1="base_link" body2="left_link0_base" /><exclude body1="base_link" body2="right_link0_base" /><exclude body1="base_link" body2="head_base_link" /><exclude body1="base_link" body2="head_pitch_link" /><exclude body1="base_link" body2="head_yaw_link" /><exclude body1="base_footprint" body2="fl_steering_link" /><exclude body1="base_footprint" body2="fl_wheel_link" /><exclude body1="base_footprint" body2="fr_steering_link" /><exclude body1="base_footprint" body2="fr_wheel_link" /><exclude body1="base_footprint" body2="bl_steering_link" /><exclude body1="base_footprint" body2="bl_wheel_link" /><exclude body1="base_footprint" body2="br_steering_link" /><exclude body1="base_footprint" body2="br_wheel_link" /><exclude body1="base_footprint" body2="mid360_link" /><exclude body1="base_footprint" body2="livox_frame" /><exclude body1="base_footprint" body2="imu_link" /><exclude body1="base_footprint" body2="d435_link" /><exclude body1="base_footprint" body2="camera_link" /><exclude body1="base_footprint" body2="camera_depth_frame" /><exclude body1="base_footprint" body2="camera_depth_optical_frame" /><exclude body1="base_footprint" body2="camera_rgb_frame" /><exclude body1="base_footprint" body2="camera_rgb_optical_frame" /><exclude body1="base_footprint" body2="d435_depth_frame" /><exclude body1="base_footprint" body2="d435_depth_optical_frame" /><exclude body1="base_footprint" body2="d435_color_frame" /><exclude body1="base_footprint" body2="d435_color_optical_frame" /><exclude body1="base_footprint" body2="gps_link" /><exclude body1="base_footprint" body2="lift_base_link" /><exclude body1="base_footprint" body2="lift_carriage_link" /><exclude body1="base_footprint" body2="chest_link" /><exclude body1="base_footprint" body2="left_link0_base" /><exclude body1="base_footprint" body2="right_link0_base" /><exclude body1="base_footprint" body2="head_base_link" /><exclude body1="base_footprint" body2="head_pitch_link" /><exclude body1="base_footprint" body2="head_yaw_link" /><exclude body1="fl_steering_link" body2="fl_wheel_link" /><exclude body1="fl_steering_link" body2="fr_steering_link" /><exclude body1="fl_steering_link" body2="fr_wheel_link" /><exclude body1="fl_steering_link" body2="bl_steering_link" /><exclude body1="fl_steering_link" body2="bl_wheel_link" /><exclude body1="fl_steering_link" body2="br_steering_link" /><exclude body1="fl_steering_link" body2="br_wheel_link" /><exclude body1="fl_steering_link" body2="mid360_link" /><exclude body1="fl_steering_link" body2="livox_frame" /><exclude body1="fl_steering_link" body2="imu_link" /><exclude body1="fl_steering_link" body2="d435_link" /><exclude body1="fl_steering_link" body2="camera_link" /><exclude body1="fl_steering_link" body2="camera_depth_frame" /><exclude body1="fl_steering_link" body2="camera_depth_optical_frame" /><exclude body1="fl_steering_link" body2="camera_rgb_frame" /><exclude body1="fl_steering_link" body2="camera_rgb_optical_frame" /><exclude body1="fl_steering_link" body2="d435_depth_frame" /><exclude body1="fl_steering_link" body2="d435_depth_optical_frame" /><exclude body1="fl_steering_link" body2="d435_color_frame" /><exclude body1="fl_steering_link" body2="d435_color_optical_frame" /><exclude body1="fl_steering_link" body2="gps_link" /><exclude body1="fl_steering_link" body2="lift_base_link" /><exclude body1="fl_steering_link" body2="lift_carriage_link" /><exclude body1="fl_steering_link" body2="chest_link" /><exclude body1="fl_steering_link" body2="left_link0_base" /><exclude body1="fl_steering_link" body2="right_link0_base" /><exclude body1="fl_steering_link" body2="head_base_link" /><exclude body1="fl_steering_link" body2="head_pitch_link" /><exclude body1="fl_steering_link" body2="head_yaw_link" /><exclude body1="fl_wheel_link" body2="fr_steering_link" /><exclude body1="fl_wheel_link" body2="fr_wheel_link" /><exclude body1="fl_wheel_link" body2="bl_steering_link" /><exclude body1="fl_wheel_link" body2="bl_wheel_link" /><exclude body1="fl_wheel_link" body2="br_steering_link" /><exclude body1="fl_wheel_link" body2="br_wheel_link" /><exclude body1="fl_wheel_link" body2="mid360_link" /><exclude body1="fl_wheel_link" body2="livox_frame" /><exclude body1="fl_wheel_link" body2="imu_link" /><exclude body1="fl_wheel_link" body2="d435_link" /><exclude body1="fl_wheel_link" body2="camera_link" /><exclude body1="fl_wheel_link" body2="camera_depth_frame" /><exclude body1="fl_wheel_link" body2="camera_depth_optical_frame" /><exclude body1="fl_wheel_link" body2="camera_rgb_frame" /><exclude body1="fl_wheel_link" body2="camera_rgb_optical_frame" /><exclude body1="fl_wheel_link" body2="d435_depth_frame" /><exclude body1="fl_wheel_link" body2="d435_depth_optical_frame" /><exclude body1="fl_wheel_link" body2="d435_color_frame" /><exclude body1="fl_wheel_link" body2="d435_color_optical_frame" /><exclude body1="fl_wheel_link" body2="gps_link" /><exclude body1="fl_wheel_link" body2="lift_base_link" /><exclude body1="fl_wheel_link" body2="lift_carriage_link" /><exclude body1="fl_wheel_link" body2="chest_link" /><exclude body1="fl_wheel_link" body2="left_link0_base" /><exclude body1="fl_wheel_link" body2="right_link0_base" /><exclude body1="fl_wheel_link" body2="head_base_link" /><exclude body1="fl_wheel_link" body2="head_pitch_link" /><exclude body1="fl_wheel_link" body2="head_yaw_link" /><exclude body1="fr_steering_link" body2="fr_wheel_link" /><exclude body1="fr_steering_link" body2="bl_steering_link" /><exclude body1="fr_steering_link" body2="bl_wheel_link" /><exclude body1="fr_steering_link" body2="br_steering_link" /><exclude body1="fr_steering_link" body2="br_wheel_link" /><exclude body1="fr_steering_link" body2="mid360_link" /><exclude body1="fr_steering_link" body2="livox_frame" /><exclude body1="fr_steering_link" body2="imu_link" /><exclude body1="fr_steering_link" body2="d435_link" /><exclude body1="fr_steering_link" body2="camera_link" /><exclude body1="fr_steering_link" body2="camera_depth_frame" /><exclude body1="fr_steering_link" body2="camera_depth_optical_frame" /><exclude body1="fr_steering_link" body2="camera_rgb_frame" /><exclude body1="fr_steering_link" body2="camera_rgb_optical_frame" /><exclude body1="fr_steering_link" body2="d435_depth_frame" /><exclude body1="fr_steering_link" body2="d435_depth_optical_frame" /><exclude body1="fr_steering_link" body2="d435_color_frame" /><exclude body1="fr_steering_link" body2="d435_color_optical_frame" /><exclude body1="fr_steering_link" body2="gps_link" /><exclude body1="fr_steering_link" body2="lift_base_link" /><exclude body1="fr_steering_link" body2="lift_carriage_link" /><exclude body1="fr_steering_link" body2="chest_link" /><exclude body1="fr_steering_link" body2="left_link0_base" /><exclude body1="fr_steering_link" body2="right_link0_base" /><exclude body1="fr_steering_link" body2="head_base_link" /><exclude body1="fr_steering_link" body2="head_pitch_link" /><exclude body1="fr_steering_link" body2="head_yaw_link" /><exclude body1="fr_wheel_link" body2="bl_steering_link" /><exclude body1="fr_wheel_link" body2="bl_wheel_link" /><exclude body1="fr_wheel_link" body2="br_steering_link" /><exclude body1="fr_wheel_link" body2="br_wheel_link" /><exclude body1="fr_wheel_link" body2="mid360_link" /><exclude body1="fr_wheel_link" body2="livox_frame" /><exclude body1="fr_wheel_link" body2="imu_link" /><exclude body1="fr_wheel_link" body2="d435_link" /><exclude body1="fr_wheel_link" body2="camera_link" /><exclude body1="fr_wheel_link" body2="camera_depth_frame" /><exclude body1="fr_wheel_link" body2="camera_depth_optical_frame" /><exclude body1="fr_wheel_link" body2="camera_rgb_frame" /><exclude body1="fr_wheel_link" body2="camera_rgb_optical_frame" /><exclude body1="fr_wheel_link" body2="d435_depth_frame" /><exclude body1="fr_wheel_link" body2="d435_depth_optical_frame" /><exclude body1="fr_wheel_link" body2="d435_color_frame" /><exclude body1="fr_wheel_link" body2="d435_color_optical_frame" /><exclude body1="fr_wheel_link" body2="gps_link" /><exclude body1="fr_wheel_link" body2="lift_base_link" /><exclude body1="fr_wheel_link" body2="lift_carriage_link" /><exclude body1="fr_wheel_link" body2="chest_link" /><exclude body1="fr_wheel_link" body2="left_link0_base" /><exclude body1="fr_wheel_link" body2="right_link0_base" /><exclude body1="fr_wheel_link" body2="head_base_link" /><exclude body1="fr_wheel_link" body2="head_pitch_link" /><exclude body1="fr_wheel_link" body2="head_yaw_link" /><exclude body1="bl_steering_link" body2="bl_wheel_link" /><exclude body1="bl_steering_link" body2="br_steering_link" /><exclude body1="bl_steering_link" body2="br_wheel_link" /><exclude body1="bl_steering_link" body2="mid360_link" /><exclude body1="bl_steering_link" body2="livox_frame" /><exclude body1="bl_steering_link" body2="imu_link" /><exclude body1="bl_steering_link" body2="d435_link" /><exclude body1="bl_steering_link" body2="camera_link" /><exclude body1="bl_steering_link" body2="camera_depth_frame" /><exclude body1="bl_steering_link" body2="camera_depth_optical_frame" /><exclude body1="bl_steering_link" body2="camera_rgb_frame" /><exclude body1="bl_steering_link" body2="camera_rgb_optical_frame" /><exclude body1="bl_steering_link" body2="d435_depth_frame" /><exclude body1="bl_steering_link" body2="d435_depth_optical_frame" /><exclude body1="bl_steering_link" body2="d435_color_frame" /><exclude body1="bl_steering_link" body2="d435_color_optical_frame" /><exclude body1="bl_steering_link" body2="gps_link" /><exclude body1="bl_steering_link" body2="lift_base_link" /><exclude body1="bl_steering_link" body2="lift_carriage_link" /><exclude body1="bl_steering_link" body2="chest_link" /><exclude body1="bl_steering_link" body2="left_link0_base" /><exclude body1="bl_steering_link" body2="right_link0_base" /><exclude body1="bl_steering_link" body2="head_base_link" /><exclude body1="bl_steering_link" body2="head_pitch_link" /><exclude body1="bl_steering_link" body2="head_yaw_link" /><exclude body1="bl_wheel_link" body2="br_steering_link" /><exclude body1="bl_wheel_link" body2="br_wheel_link" /><exclude body1="bl_wheel_link" body2="mid360_link" /><exclude body1="bl_wheel_link" body2="livox_frame" /><exclude body1="bl_wheel_link" body2="imu_link" /><exclude body1="bl_wheel_link" body2="d435_link" /><exclude body1="bl_wheel_link" body2="camera_link" /><exclude body1="bl_wheel_link" body2="camera_depth_frame" /><exclude body1="bl_wheel_link" body2="camera_depth_optical_frame" /><exclude body1="bl_wheel_link" body2="camera_rgb_frame" /><exclude body1="bl_wheel_link" body2="camera_rgb_optical_frame" /><exclude body1="bl_wheel_link" body2="d435_depth_frame" /><exclude body1="bl_wheel_link" body2="d435_depth_optical_frame" /><exclude body1="bl_wheel_link" body2="d435_color_frame" /><exclude body1="bl_wheel_link" body2="d435_color_optical_frame" /><exclude body1="bl_wheel_link" body2="gps_link" /><exclude body1="bl_wheel_link" body2="lift_base_link" /><exclude body1="bl_wheel_link" body2="lift_carriage_link" /><exclude body1="bl_wheel_link" body2="chest_link" /><exclude body1="bl_wheel_link" body2="left_link0_base" /><exclude body1="bl_wheel_link" body2="right_link0_base" /><exclude body1="bl_wheel_link" body2="head_base_link" /><exclude body1="bl_wheel_link" body2="head_pitch_link" /><exclude body1="bl_wheel_link" body2="head_yaw_link" /><exclude body1="br_steering_link" body2="br_wheel_link" /><exclude body1="br_steering_link" body2="mid360_link" /><exclude body1="br_steering_link" body2="livox_frame" /><exclude body1="br_steering_link" body2="imu_link" /><exclude body1="br_steering_link" body2="d435_link" /><exclude body1="br_steering_link" body2="camera_link" /><exclude body1="br_steering_link" body2="camera_depth_frame" /><exclude body1="br_steering_link" body2="camera_depth_optical_frame" /><exclude body1="br_steering_link" body2="camera_rgb_frame" /><exclude body1="br_steering_link" body2="camera_rgb_optical_frame" /><exclude body1="br_steering_link" body2="d435_depth_frame" /><exclude body1="br_steering_link" body2="d435_depth_optical_frame" /><exclude body1="br_steering_link" body2="d435_color_frame" /><exclude body1="br_steering_link" body2="d435_color_optical_frame" /><exclude body1="br_steering_link" body2="gps_link" /><exclude body1="br_steering_link" body2="lift_base_link" /><exclude body1="br_steering_link" body2="lift_carriage_link" /><exclude body1="br_steering_link" body2="chest_link" /><exclude body1="br_steering_link" body2="left_link0_base" /><exclude body1="br_steering_link" body2="right_link0_base" /><exclude body1="br_steering_link" body2="head_base_link" /><exclude body1="br_steering_link" body2="head_pitch_link" /><exclude body1="br_steering_link" body2="head_yaw_link" /><exclude body1="br_wheel_link" body2="mid360_link" /><exclude body1="br_wheel_link" body2="livox_frame" /><exclude body1="br_wheel_link" body2="imu_link" /><exclude body1="br_wheel_link" body2="d435_link" /><exclude body1="br_wheel_link" body2="camera_link" /><exclude body1="br_wheel_link" body2="camera_depth_frame" /><exclude body1="br_wheel_link" body2="camera_depth_optical_frame" /><exclude body1="br_wheel_link" body2="camera_rgb_frame" /><exclude body1="br_wheel_link" body2="camera_rgb_optical_frame" /><exclude body1="br_wheel_link" body2="d435_depth_frame" /><exclude body1="br_wheel_link" body2="d435_depth_optical_frame" /><exclude body1="br_wheel_link" body2="d435_color_frame" /><exclude body1="br_wheel_link" body2="d435_color_optical_frame" /><exclude body1="br_wheel_link" body2="gps_link" /><exclude body1="br_wheel_link" body2="lift_base_link" /><exclude body1="br_wheel_link" body2="lift_carriage_link" /><exclude body1="br_wheel_link" body2="chest_link" /><exclude body1="br_wheel_link" body2="left_link0_base" /><exclude body1="br_wheel_link" body2="right_link0_base" /><exclude body1="br_wheel_link" body2="head_base_link" /><exclude body1="br_wheel_link" body2="head_pitch_link" /><exclude body1="br_wheel_link" body2="head_yaw_link" /><exclude body1="mid360_link" body2="livox_frame" /><exclude body1="mid360_link" body2="imu_link" /><exclude body1="mid360_link" body2="d435_link" /><exclude body1="mid360_link" body2="camera_link" /><exclude body1="mid360_link" body2="camera_depth_frame" /><exclude body1="mid360_link" body2="camera_depth_optical_frame" /><exclude body1="mid360_link" body2="camera_rgb_frame" /><exclude body1="mid360_link" body2="camera_rgb_optical_frame" /><exclude body1="mid360_link" body2="d435_depth_frame" /><exclude body1="mid360_link" body2="d435_depth_optical_frame" /><exclude body1="mid360_link" body2="d435_color_frame" /><exclude body1="mid360_link" body2="d435_color_optical_frame" /><exclude body1="mid360_link" body2="gps_link" /><exclude body1="mid360_link" body2="lift_base_link" /><exclude body1="mid360_link" body2="lift_carriage_link" /><exclude body1="mid360_link" body2="chest_link" /><exclude body1="mid360_link" body2="left_link0_base" /><exclude body1="mid360_link" body2="right_link0_base" /><exclude body1="mid360_link" body2="head_base_link" /><exclude body1="mid360_link" body2="head_pitch_link" /><exclude body1="mid360_link" body2="head_yaw_link" /><exclude body1="livox_frame" body2="imu_link" /><exclude body1="livox_frame" body2="d435_link" /><exclude body1="livox_frame" body2="camera_link" /><exclude body1="livox_frame" body2="camera_depth_frame" /><exclude body1="livox_frame" body2="camera_depth_optical_frame" /><exclude body1="livox_frame" body2="camera_rgb_frame" /><exclude body1="livox_frame" body2="camera_rgb_optical_frame" /><exclude body1="livox_frame" body2="d435_depth_frame" /><exclude body1="livox_frame" body2="d435_depth_optical_frame" /><exclude body1="livox_frame" body2="d435_color_frame" /><exclude body1="livox_frame" body2="d435_color_optical_frame" /><exclude body1="livox_frame" body2="gps_link" /><exclude body1="livox_frame" body2="lift_base_link" /><exclude body1="livox_frame" body2="lift_carriage_link" /><exclude body1="livox_frame" body2="chest_link" /><exclude body1="livox_frame" body2="left_link0_base" /><exclude body1="livox_frame" body2="right_link0_base" /><exclude body1="livox_frame" body2="head_base_link" /><exclude body1="livox_frame" body2="head_pitch_link" /><exclude body1="livox_frame" body2="head_yaw_link" /><exclude body1="imu_link" body2="d435_link" /><exclude body1="imu_link" body2="camera_link" /><exclude body1="imu_link" body2="camera_depth_frame" /><exclude body1="imu_link" body2="camera_depth_optical_frame" /><exclude body1="imu_link" body2="camera_rgb_frame" /><exclude body1="imu_link" body2="camera_rgb_optical_frame" /><exclude body1="imu_link" body2="d435_depth_frame" /><exclude body1="imu_link" body2="d435_depth_optical_frame" /><exclude body1="imu_link" body2="d435_color_frame" /><exclude body1="imu_link" body2="d435_color_optical_frame" /><exclude body1="imu_link" body2="gps_link" /><exclude body1="imu_link" body2="lift_base_link" /><exclude body1="imu_link" body2="lift_carriage_link" /><exclude body1="imu_link" body2="chest_link" /><exclude body1="imu_link" body2="left_link0_base" /><exclude body1="imu_link" body2="right_link0_base" /><exclude body1="imu_link" body2="head_base_link" /><exclude body1="imu_link" body2="head_pitch_link" /><exclude body1="imu_link" body2="head_yaw_link" /><exclude body1="d435_link" body2="camera_link" /><exclude body1="d435_link" body2="camera_depth_frame" /><exclude body1="d435_link" body2="camera_depth_optical_frame" /><exclude body1="d435_link" body2="camera_rgb_frame" /><exclude body1="d435_link" body2="camera_rgb_optical_frame" /><exclude body1="d435_link" body2="d435_depth_frame" /><exclude body1="d435_link" body2="d435_depth_optical_frame" /><exclude body1="d435_link" body2="d435_color_frame" /><exclude body1="d435_link" body2="d435_color_optical_frame" /><exclude body1="d435_link" body2="gps_link" /><exclude body1="d435_link" body2="lift_base_link" /><exclude body1="d435_link" body2="lift_carriage_link" /><exclude body1="d435_link" body2="chest_link" /><exclude body1="d435_link" body2="left_link0_base" /><exclude body1="d435_link" body2="right_link0_base" /><exclude body1="d435_link" body2="head_base_link" /><exclude body1="d435_link" body2="head_pitch_link" /><exclude body1="d435_link" body2="head_yaw_link" /><exclude body1="camera_link" body2="camera_depth_frame" /><exclude body1="camera_link" body2="camera_depth_optical_frame" /><exclude body1="camera_link" body2="camera_rgb_frame" /><exclude body1="camera_link" body2="camera_rgb_optical_frame" /><exclude body1="camera_link" body2="d435_depth_frame" /><exclude body1="camera_link" body2="d435_depth_optical_frame" /><exclude body1="camera_link" body2="d435_color_frame" /><exclude body1="camera_link" body2="d435_color_optical_frame" /><exclude body1="camera_link" body2="gps_link" /><exclude body1="camera_link" body2="lift_base_link" /><exclude body1="camera_link" body2="lift_carriage_link" /><exclude body1="camera_link" body2="chest_link" /><exclude body1="camera_link" body2="left_link0_base" /><exclude body1="camera_link" body2="right_link0_base" /><exclude body1="camera_link" body2="head_base_link" /><exclude body1="camera_link" body2="head_pitch_link" /><exclude body1="camera_link" body2="head_yaw_link" /><exclude body1="camera_depth_frame" body2="camera_depth_optical_frame" /><exclude body1="camera_depth_frame" body2="camera_rgb_frame" /><exclude body1="camera_depth_frame" body2="camera_rgb_optical_frame" /><exclude body1="camera_depth_frame" body2="d435_depth_frame" /><exclude body1="camera_depth_frame" body2="d435_depth_optical_frame" /><exclude body1="camera_depth_frame" body2="d435_color_frame" /><exclude body1="camera_depth_frame" body2="d435_color_optical_frame" /><exclude body1="camera_depth_frame" body2="gps_link" /><exclude body1="camera_depth_frame" body2="lift_base_link" /><exclude body1="camera_depth_frame" body2="lift_carriage_link" /><exclude body1="camera_depth_frame" body2="chest_link" /><exclude body1="camera_depth_frame" body2="left_link0_base" /><exclude body1="camera_depth_frame" body2="right_link0_base" /><exclude body1="camera_depth_frame" body2="head_base_link" /><exclude body1="camera_depth_frame" body2="head_pitch_link" /><exclude body1="camera_depth_frame" body2="head_yaw_link" /><exclude body1="camera_depth_optical_frame" body2="camera_rgb_frame" /><exclude body1="camera_depth_optical_frame" body2="camera_rgb_optical_frame" /><exclude body1="camera_depth_optical_frame" body2="d435_depth_frame" /><exclude body1="camera_depth_optical_frame" body2="d435_depth_optical_frame" /><exclude body1="camera_depth_optical_frame" body2="d435_color_frame" /><exclude body1="camera_depth_optical_frame" body2="d435_color_optical_frame" /><exclude body1="camera_depth_optical_frame" body2="gps_link" /><exclude body1="camera_depth_optical_frame" body2="lift_base_link" /><exclude body1="camera_depth_optical_frame" body2="lift_carriage_link" /><exclude body1="camera_depth_optical_frame" body2="chest_link" /><exclude body1="camera_depth_optical_frame" body2="left_link0_base" /><exclude body1="camera_depth_optical_frame" body2="right_link0_base" /><exclude body1="camera_depth_optical_frame" body2="head_base_link" /><exclude body1="camera_depth_optical_frame" body2="head_pitch_link" /><exclude body1="camera_depth_optical_frame" body2="head_yaw_link" /><exclude body1="camera_rgb_frame" body2="camera_rgb_optical_frame" /><exclude body1="camera_rgb_frame" body2="d435_depth_frame" /><exclude body1="camera_rgb_frame" body2="d435_depth_optical_frame" /><exclude body1="camera_rgb_frame" body2="d435_color_frame" /><exclude body1="camera_rgb_frame" body2="d435_color_optical_frame" /><exclude body1="camera_rgb_frame" body2="gps_link" /><exclude body1="camera_rgb_frame" body2="lift_base_link" /><exclude body1="camera_rgb_frame" body2="lift_carriage_link" /><exclude body1="camera_rgb_frame" body2="chest_link" /><exclude body1="camera_rgb_frame" body2="left_link0_base" /><exclude body1="camera_rgb_frame" body2="right_link0_base" /><exclude body1="camera_rgb_frame" body2="head_base_link" /><exclude body1="camera_rgb_frame" body2="head_pitch_link" /><exclude body1="camera_rgb_frame" body2="head_yaw_link" /><exclude body1="camera_rgb_optical_frame" body2="d435_depth_frame" /><exclude body1="camera_rgb_optical_frame" body2="d435_depth_optical_frame" /><exclude body1="camera_rgb_optical_frame" body2="d435_color_frame" /><exclude body1="camera_rgb_optical_frame" body2="d435_color_optical_frame" /><exclude body1="camera_rgb_optical_frame" body2="gps_link" /><exclude body1="camera_rgb_optical_frame" body2="lift_base_link" /><exclude body1="camera_rgb_optical_frame" body2="lift_carriage_link" /><exclude body1="camera_rgb_optical_frame" body2="chest_link" /><exclude body1="camera_rgb_optical_frame" body2="left_link0_base" /><exclude body1="camera_rgb_optical_frame" body2="right_link0_base" /><exclude body1="camera_rgb_optical_frame" body2="head_base_link" /><exclude body1="camera_rgb_optical_frame" body2="head_pitch_link" /><exclude body1="camera_rgb_optical_frame" body2="head_yaw_link" /><exclude body1="d435_depth_frame" body2="d435_depth_optical_frame" /><exclude body1="d435_depth_frame" body2="d435_color_frame" /><exclude body1="d435_depth_frame" body2="d435_color_optical_frame" /><exclude body1="d435_depth_frame" body2="gps_link" /><exclude body1="d435_depth_frame" body2="lift_base_link" /><exclude body1="d435_depth_frame" body2="lift_carriage_link" /><exclude body1="d435_depth_frame" body2="chest_link" /><exclude body1="d435_depth_frame" body2="left_link0_base" /><exclude body1="d435_depth_frame" body2="right_link0_base" /><exclude body1="d435_depth_frame" body2="head_base_link" /><exclude body1="d435_depth_frame" body2="head_pitch_link" /><exclude body1="d435_depth_frame" body2="head_yaw_link" /><exclude body1="d435_depth_optical_frame" body2="d435_color_frame" /><exclude body1="d435_depth_optical_frame" body2="d435_color_optical_frame" /><exclude body1="d435_depth_optical_frame" body2="gps_link" /><exclude body1="d435_depth_optical_frame" body2="lift_base_link" /><exclude body1="d435_depth_optical_frame" body2="lift_carriage_link" /><exclude body1="d435_depth_optical_frame" body2="chest_link" /><exclude body1="d435_depth_optical_frame" body2="left_link0_base" /><exclude body1="d435_depth_optical_frame" body2="right_link0_base" /><exclude body1="d435_depth_optical_frame" body2="head_base_link" /><exclude body1="d435_depth_optical_frame" body2="head_pitch_link" /><exclude body1="d435_depth_optical_frame" body2="head_yaw_link" /><exclude body1="d435_color_frame" body2="d435_color_optical_frame" /><exclude body1="d435_color_frame" body2="gps_link" /><exclude body1="d435_color_frame" body2="lift_base_link" /><exclude body1="d435_color_frame" body2="lift_carriage_link" /><exclude body1="d435_color_frame" body2="chest_link" /><exclude body1="d435_color_frame" body2="left_link0_base" /><exclude body1="d435_color_frame" body2="right_link0_base" /><exclude body1="d435_color_frame" body2="head_base_link" /><exclude body1="d435_color_frame" body2="head_pitch_link" /><exclude body1="d435_color_frame" body2="head_yaw_link" /><exclude body1="d435_color_optical_frame" body2="gps_link" /><exclude body1="d435_color_optical_frame" body2="lift_base_link" /><exclude body1="d435_color_optical_frame" body2="lift_carriage_link" /><exclude body1="d435_color_optical_frame" body2="chest_link" /><exclude body1="d435_color_optical_frame" body2="left_link0_base" /><exclude body1="d435_color_optical_frame" body2="right_link0_base" /><exclude body1="d435_color_optical_frame" body2="head_base_link" /><exclude body1="d435_color_optical_frame" body2="head_pitch_link" /><exclude body1="d435_color_optical_frame" body2="head_yaw_link" /><exclude body1="gps_link" body2="lift_base_link" /><exclude body1="gps_link" body2="lift_carriage_link" /><exclude body1="gps_link" body2="chest_link" /><exclude body1="gps_link" body2="left_link0_base" /><exclude body1="gps_link" body2="right_link0_base" /><exclude body1="gps_link" body2="head_base_link" /><exclude body1="gps_link" body2="head_pitch_link" /><exclude body1="gps_link" body2="head_yaw_link" /><exclude body1="lift_base_link" body2="lift_carriage_link" /><exclude body1="lift_base_link" body2="chest_link" /><exclude body1="lift_base_link" body2="left_link0_base" /><exclude body1="lift_base_link" body2="right_link0_base" /><exclude body1="lift_base_link" body2="head_base_link" /><exclude body1="lift_base_link" body2="head_pitch_link" /><exclude body1="lift_base_link" body2="head_yaw_link" /><exclude body1="lift_carriage_link" body2="chest_link" /><exclude body1="lift_carriage_link" body2="left_link0_base" /><exclude body1="lift_carriage_link" body2="right_link0_base" /><exclude body1="lift_carriage_link" body2="head_base_link" /><exclude body1="lift_carriage_link" body2="head_pitch_link" /><exclude body1="lift_carriage_link" body2="head_yaw_link" /><exclude body1="chest_link" body2="left_link0_base" /><exclude body1="chest_link" body2="right_link0_base" /><exclude body1="chest_link" body2="head_base_link" /><exclude body1="chest_link" body2="head_pitch_link" /><exclude body1="chest_link" body2="head_yaw_link" /><exclude body1="left_link0_base" body2="right_link0_base" /><exclude body1="left_link0_base" body2="head_base_link" /><exclude body1="left_link0_base" body2="head_pitch_link" /><exclude body1="left_link0_base" body2="head_yaw_link" /><exclude body1="right_link0_base" body2="head_base_link" /><exclude body1="right_link0_base" body2="head_pitch_link" /><exclude body1="right_link0_base" body2="head_yaw_link" /><exclude body1="head_base_link" body2="head_pitch_link" /><exclude body1="head_base_link" body2="head_yaw_link" /><exclude body1="head_pitch_link" body2="head_yaw_link" /></contact><equality><joint joint1="openarmx_left_finger_joint1" joint2="openarmx_left_finger_joint2" solimp="0.95 0.99 0.001" solref="0.005 1" /><joint joint1="openarmx_right_finger_joint1" joint2="openarmx_right_finger_joint2" solimp="0.95 0.99 0.001" solref="0.005 1" /></equality><actuator><position name="fl_steering_joint_pos" joint="fl_steering_joint" kp="20" kv="4" ctrllimited="true" ctrlrange="-1.5708 1.5708" /><position name="fr_steering_joint_pos" joint="fr_steering_joint" kp="20" kv="4" ctrllimited="true" ctrlrange="-1.5708 1.5708" /><position name="bl_steering_joint_pos" joint="bl_steering_joint" kp="20" kv="4" ctrllimited="true" ctrlrange="-1.5708 1.5708" /><position name="br_steering_joint_pos" joint="br_steering_joint" kp="20" kv="4" ctrllimited="true" ctrlrange="-1.5708 1.5708" /><position name="lift_joint_pos" joint="lift_joint" kp="10000" kv="2000" ctrllimited="true" ctrlrange="-0.8 0.15" /><position name="openarmx_left_joint1_pos" joint="openarmx_left_joint1" kp="180" kv="20" ctrllimited="true" ctrlrange="-3.344396 0.9056039999999999" /><position name="openarmx_left_joint2_pos" joint="openarmx_left_joint2" kp="180" kv="20" ctrllimited="true" ctrlrange="-3.2707963267948967 0.1292036732051034" /><position name="openarmx_left_joint3_pos" joint="openarmx_left_joint3" kp="180" kv="20" ctrllimited="true" ctrlrange="-1.57 1.57" /><position name="openarmx_left_joint4_pos" joint="openarmx_left_joint4" kp="180" kv="20" ctrllimited="true" ctrlrange="0.0 1.8" /><position name="openarmx_left_joint5_pos" joint="openarmx_left_joint5" kp="180" kv="20" ctrllimited="true" ctrlrange="-1.5 1.5" /><position name="openarmx_left_joint6_pos" joint="openarmx_left_joint6" kp="180" kv="20" ctrllimited="true" ctrlrange="-0.75 0.75" /><position name="openarmx_left_joint7_pos" joint="openarmx_left_joint7" kp="180" kv="20" ctrllimited="true" ctrlrange="-1.4 1.4" /><position name="openarmx_left_finger_joint1_pos" joint="openarmx_left_finger_joint1" kp="80" kv="8" ctrllimited="true" ctrlrange="0.0 0.044" /><position name="openarmx_right_joint1_pos" joint="openarmx_right_joint1" kp="180" kv="20" ctrllimited="true" ctrlrange="-1.25 3.0" /><position name="openarmx_right_joint2_pos" joint="openarmx_right_joint2" kp="180" kv="20" ctrllimited="true" ctrlrange="-0.1292036732051034 3.2707963267948967" /><position name="openarmx_right_joint3_pos" joint="openarmx_right_joint3" kp="180" kv="20" ctrllimited="true" ctrlrange="-1.57 1.57" /><position name="openarmx_right_joint4_pos" joint="openarmx_right_joint4" kp="180" kv="20" ctrllimited="true" ctrlrange="0.0 1.8" /><position name="openarmx_right_joint5_pos" joint="openarmx_right_joint5" kp="180" kv="20" ctrllimited="true" ctrlrange="-1.5 1.5" /><position name="openarmx_right_joint6_pos" joint="openarmx_right_joint6" kp="180" kv="20" ctrllimited="true" ctrlrange="-0.75 0.75" /><position name="openarmx_right_joint7_pos" joint="openarmx_right_joint7" kp="180" kv="20" ctrllimited="true" ctrlrange="-1.4 1.4" /><position name="openarmx_right_finger_joint1_pos" joint="openarmx_right_finger_joint1" kp="80" kv="8" ctrllimited="true" ctrlrange="0.0 0.044" /><position name="openarmx_head_pitch_joint_pos" joint="openarmx_head_pitch_joint" kp="40" kv="4" ctrllimited="true" ctrlrange="-1.5708 1.5708" /><position name="openarmx_head_yaw_joint_pos" joint="openarmx_head_yaw_joint" kp="40" kv="4" ctrllimited="true" ctrlrange="-1.5708 1.5708" /></actuator></mujoco>