<?xml version='1.0' encoding='utf-8'?>
<mujoco model="openarmx_integrated">
  <compiler angle="radian" />

  <asset>
    <mesh name="packages_openflex_chassis_swerve_description_meshes_base_link" file="mujoco_meshes/packages_openflex_chassis_swerve_description_meshes_base_link.obj" />
    <mesh name="packages_openflex_chassis_swerve_description_meshes_fl_wheel_link" file="mujoco_meshes/packages_openflex_chassis_swerve_description_meshes_fl_wheel_link.obj" scale="0.001 0.001 0.001" />
    <mesh name="packages_openflex_chassis_swerve_description_meshes_fr_wheel_link" file="mujoco_meshes/packages_openflex_chassis_swerve_description_meshes_fr_wheel_link.obj" scale="0.001 0.001 0.001" />
    <mesh name="packages_openflex_chassis_swerve_description_meshes_bl_wheel_link" file="mujoco_meshes/packages_openflex_chassis_swerve_description_meshes_bl_wheel_link.obj" scale="0.001 0.001 0.001" />
    <mesh name="packages_openflex_chassis_swerve_description_meshes_br_wheel_link" file="mujoco_meshes/packages_openflex_chassis_swerve_description_meshes_br_wheel_link.obj" scale="0.001 0.001 0.001" />
    <mesh name="packages_openflex_chassis_swerve_description_meshes_mid360_link" file="mujoco_meshes/packages_openflex_chassis_swerve_description_meshes_mid360_link.obj" scale="0.001 0.001 0.001" />
    <mesh name="packages_openflex_chassis_swerve_description_meshes_d435_link" file="mujoco_meshes/packages_openflex_chassis_swerve_description_meshes_d435_link.obj" scale="0.001 0.001 0.001" />
    <mesh name="packages_lift_slide_description_meshes_lift_link" file="mujoco_meshes/packages_lift_slide_description_meshes_lift_link.obj" />
    <mesh name="packages_lift_slide_description_meshes_plate_link" file="mujoco_meshes/packages_lift_slide_description_meshes_plate_link.obj" />
    <mesh name="packages_lift_slide_description_meshes_chest_link" file="mujoco_meshes/packages_lift_slide_description_meshes_chest_link.obj" scale="0.001 0.001 0.001" />
    <mesh name="packages_lift_slide_description_meshes_left_link0_base" file="mujoco_meshes/packages_lift_slide_description_meshes_left_link0_base.obj" />
    <mesh name="packages_lift_slide_description_meshes_right_link0_base" file="mujoco_meshes/packages_lift_slide_description_meshes_right_link0_base.obj" />
    <mesh name="packages_openarmx_description_meshes_arm_v10_visual_link0_mirror_pnp_part0" file="mujoco_meshes/packages_openarmx_description_meshes_arm_v10_visual_link0_mirror_pnp_part0.obj" />
    <mesh name="packages_openarmx_description_meshes_arm_v10_visual_link0_mirror_pnp_part1" file="mujoco_meshes/packages_openarmx_description_meshes_arm_v10_visual_link0_mirror_pnp_part1.obj" />
    <mesh name="packages_openarmx_description_meshes_arm_v10_visual_link1_mirror_pnp_part0" file="mujoco_meshes/packages_openarmx_description_meshes_arm_v10_visual_link1_mirror_pnp_part0.obj" />
    <mesh name="packages_openarmx_description_meshes_arm_v10_visual_link1_mirror_pnp_part1" file="mujoco_meshes/packages_openarmx_description_meshes_arm_v10_visual_link1_mirror_pnp_part1.obj" />
    <mesh name="packages_openarmx_description_meshes_arm_v10_visual_link2_mirror_pnp_part0" file="mujoco_meshes/packages_openarmx_description_meshes_arm_v10_visual_link2_mirror_pnp_part0.obj" />
    <mesh name="packages_openarmx_description_meshes_arm_v10_visual_link2_mirror_pnp_part1" file="mujoco_meshes/packages_openarmx_description_meshes_arm_v10_visual_link2_mirror_pnp_part1.obj" />
    <mesh name="packages_openarmx_description_meshes_arm_v10_visual_link3_mirror_pnp_part0" file="mujoco_meshes/packages_openarmx_description_meshes_arm_v10_visual_link3_mirror_pnp_part0.obj" />
    <mesh name="packages_openarmx_description_meshes_arm_v10_visual_link3_mirror_pnp_part1" file="mujoco_meshes/packages_openarmx_description_meshes_arm_v10_visual_link3_mirror_pnp_part1.obj" />
    <mesh name="packages_openarmx_description_meshes_arm_v10_visual_link4_part0" file="mujoco_meshes/packages_openarmx_description_meshes_arm_v10_visual_link4_part0.obj" />
    <mesh name="packages_openarmx_description_meshes_arm_v10_visual_link4_part1" file="mujoco_meshes/packages_openarmx_description_meshes_arm_v10_visual_link4_part1.obj" />
    <mesh name="packages_openarmx_description_meshes_arm_v10_visual_link5_mirror_pnp_part0" file="mujoco_meshes/packages_openarmx_description_meshes_arm_v10_visual_link5_mirror_pnp_part0.obj" />
    <mesh name="packages_openarmx_description_meshes_arm_v10_visual_link5_mirror_pnp_part1" file="mujoco_meshes/packages_openarmx_description_meshes_arm_v10_visual_link5_mirror_pnp_part1.obj" />
    <mesh name="packages_openarmx_description_meshes_arm_v10_visual_link6_mirror_pnp_part0" file="mujoco_meshes/packages_openarmx_description_meshes_arm_v10_visual_link6_mirror_pnp_part0.obj" />
    <mesh name="packages_openarmx_description_meshes_arm_v10_visual_link6_mirror_pnp_part1" file="mujoco_meshes/packages_openarmx_description_meshes_arm_v10_visual_link6_mirror_pnp_part1.obj" />
    <mesh name="packages_openarmx_description_meshes_arm_v10_visual_link7_mirror_pnp_part0" file="mujoco_meshes/packages_openarmx_description_meshes_arm_v10_visual_link7_mirror_pnp_part0.obj" />
    <mesh name="packages_openarmx_description_meshes_arm_v10_visual_link7_mirror_pnp_part1" file="mujoco_meshes/packages_openarmx_description_meshes_arm_v10_visual_link7_mirror_pnp_part1.obj" />
    <mesh name="packages_openarmx_description_meshes_arm_v10_visual_link0_part0" file="mujoco_meshes/packages_openarmx_description_meshes_arm_v10_visual_link0_part0.obj" />
    <mesh name="packages_openarmx_description_meshes_arm_v10_visual_link0_part1" file="mujoco_meshes/packages_openarmx_description_meshes_arm_v10_visual_link0_part1.obj" />
    <mesh name="packages_openarmx_description_meshes_arm_v10_visual_link1_part0" file="mujoco_meshes/packages_openarmx_description_meshes_arm_v10_visual_link1_part0.obj" />
    <mesh name="packages_openarmx_description_meshes_arm_v10_visual_link1_part1" file="mujoco_meshes/packages_openarmx_description_meshes_arm_v10_visual_link1_part1.obj" />
    <mesh name="packages_openarmx_description_meshes_arm_v10_visual_link2_part0" file="mujoco_meshes/packages_openarmx_description_meshes_arm_v10_visual_link2_part0.obj" />
    <mesh name="packages_openarmx_description_meshes_arm_v10_visual_link2_part1" file="mujoco_meshes/packages_openarmx_description_meshes_arm_v10_visual_link2_part1.obj" />
    <mesh name="packages_openarmx_description_meshes_arm_v10_visual_link3_part0" file="mujoco_meshes/packages_openarmx_description_meshes_arm_v10_visual_link3_part0.obj" />
    <mesh name="packages_openarmx_description_meshes_arm_v10_visual_link3_part1" file="mujoco_meshes/packages_openarmx_description_meshes_arm_v10_visual_link3_part1.obj" />
    <mesh name="packages_openarmx_description_meshes_arm_v10_visual_link5_part0" file="mujoco_meshes/packages_openarmx_description_meshes_arm_v10_visual_link5_part0.obj" />
    <mesh name="packages_openarmx_description_meshes_arm_v10_visual_link5_part1" file="mujoco_meshes/packages_openarmx_description_meshes_arm_v10_visual_link5_part1.obj" />
    <mesh name="packages_openarmx_description_meshes_arm_v10_visual_link6_part0" file="mujoco_meshes/packages_openarmx_description_meshes_arm_v10_visual_link6_part0.obj" />
    <mesh name="packages_openarmx_description_meshes_arm_v10_visual_link6_part1" file="mujoco_meshes/packages_openarmx_description_meshes_arm_v10_visual_link6_part1.obj" />
    <mesh name="packages_openarmx_description_meshes_arm_v10_visual_link7_part0" file="mujoco_meshes/packages_openarmx_description_meshes_arm_v10_visual_link7_part0.obj" />
    <mesh name="packages_openarmx_description_meshes_arm_v10_visual_link7_part1" file="mujoco_meshes/packages_openarmx_description_meshes_arm_v10_visual_link7_part1.obj" />
    <mesh name="packages_openarmx_description_meshes_ee_openarmx_hand_visual_hand_part0" file="mujoco_meshes/packages_openarmx_description_meshes_ee_openarmx_hand_visual_hand_part0.obj" scale="0.001 0.001 0.001" />
    <mesh name="packages_openarmx_description_meshes_ee_openarmx_hand_visual_hand_part1" file="mujoco_meshes/packages_openarmx_description_meshes_ee_openarmx_hand_visual_hand_part1.obj" scale="0.001 0.001 0.001" />
    <mesh name="packages_openarmx_description_meshes_ee_openarmx_hand_visual_finger_part0" file="mujoco_meshes/packages_openarmx_description_meshes_ee_openarmx_hand_visual_finger_part0.obj" scale="0.001 0.001 0.001" />
    <mesh name="packages_openarmx_description_meshes_ee_openarmx_hand_visual_finger_part1" file="mujoco_meshes/packages_openarmx_description_meshes_ee_openarmx_hand_visual_finger_part1.obj" scale="0.001 0.001 0.001" />
    <mesh name="packages_openarmx_description_meshes_ee_openarmx_hand_visual_finger_mirror_pnp_part0" file="mujoco_meshes/packages_openarmx_description_meshes_ee_openarmx_hand_visual_finger_mirror_pnp_part0.obj" scale="0.001 0.001 0.001" />
    <mesh name="packages_openarmx_description_meshes_ee_openarmx_hand_visual_finger_mirror_pnp_part1" file="mujoco_meshes/packages_openarmx_description_meshes_ee_openarmx_hand_visual_finger_mirror_pnp_part1.obj" scale="0.001 0.001 0.001" />
    <mesh name="packages_openarmx_head_description_meshes_visual_TBBJ-04_neck_mount" file="mujoco_meshes/packages_openarmx_head_description_meshes_visual_TBBJ-04_neck_mount.obj" scale="0.001 0.001 0.001" />
    <mesh name="packages_openarmx_head_description_meshes_visual_TBBJ-02_neck_bracket" file="mujoco_meshes/packages_openarmx_head_description_meshes_visual_TBBJ-02_neck_bracket.obj" scale="0.001 0.001 0.001" />
    <mesh name="packages_openarmx_head_description_meshes_visual_TBBJ-06_neck_limit" file="mujoco_meshes/packages_openarmx_head_description_meshes_visual_TBBJ-06_neck_limit.obj" scale="0.001 0.001 0.001" />
    <mesh name="packages_openarmx_head_description_meshes_visual_RS00_motor_2" file="mujoco_meshes/packages_openarmx_head_description_meshes_visual_RS00_motor_2.obj" scale="0.001 0.001 0.001" />
    <mesh name="packages_openarmx_head_description_meshes_visual_DY-03_neck_cover" file="mujoco_meshes/packages_openarmx_head_description_meshes_visual_DY-03_neck_cover.obj" scale="0.001 0.001 0.001" />
    <mesh name="packages_openarmx_head_description_meshes_visual_RS00_motor_1" file="mujoco_meshes/packages_openarmx_head_description_meshes_visual_RS00_motor_1.obj" scale="0.001 0.001 0.001" />
    <mesh name="packages_openarmx_head_description_meshes_visual_TB-01_head_connector" file="mujoco_meshes/packages_openarmx_head_description_meshes_visual_TB-01_head_connector.obj" scale="0.001 0.001 0.001" />
    <mesh name="packages_openarmx_head_description_meshes_visual_TBBJ-03_guard_plate" file="mujoco_meshes/packages_openarmx_head_description_meshes_visual_TBBJ-03_guard_plate.obj" scale="0.001 0.001 0.001" />
    <mesh name="packages_openarmx_head_description_meshes_visual_TBBJ-01_head_bracket" file="mujoco_meshes/packages_openarmx_head_description_meshes_visual_TBBJ-01_head_bracket.obj" scale="0.001 0.001 0.001" />
    <mesh name="packages_openarmx_head_description_meshes_visual_TBBJ-05_head_limit" file="mujoco_meshes/packages_openarmx_head_description_meshes_visual_TBBJ-05_head_limit.obj" scale="0.001 0.001 0.001" />
    <mesh name="packages_openarmx_head_description_meshes_visual_DY-01_head_front_shell" file="mujoco_meshes/packages_openarmx_head_description_meshes_visual_DY-01_head_front_shell.obj" scale="0.001 0.001 0.001" />
    <mesh name="packages_openarmx_head_description_meshes_visual_DY-02_head_rear_shell" file="mujoco_meshes/packages_openarmx_head_description_meshes_visual_DY-02_head_rear_shell.obj" scale="0.001 0.001 0.001" />
    <mesh name="packages_openarmx_head_description_meshes_visual_femto_bolt_camera" file="mujoco_meshes/packages_openarmx_head_description_meshes_visual_femto_bolt_camera.obj" scale="0.001 0.001 0.001" />
  <texture name="sky" type="skybox" builtin="gradient" rgb1="0.08 0.10 0.14" rgb2="0.01 0.012 0.018" width="512" height="512" />
  <texture name="floor_grid" type="2d" builtin="checker" rgb1="0.18 0.20 0.23" rgb2="0.26 0.29 0.33" width="1024" height="1024" mark="edge" markrgb="0.55 0.60 0.68" />
  <material name="floor_mat" texture="floor_grid" texrepeat="8 8" reflectance="0.20" shininess="0.30" specular="0.20" />
<mesh name="ldjy_left_palm_visual_0" file="ldjy_hand/meshes/palm.stl" scale="-1 1 1" /><mesh name="ldjy_left_palm_collision" file="ldjy_hand/meshes/palm_collision.stl" scale="-1 1 1" /><mesh name="ldjy_left_finger1_link1_visual_0" file="ldjy_hand/meshes/finger1_link1.stl" scale="-1 1 1" /><mesh name="ldjy_left_finger1_link2_visual_0" file="ldjy_hand/meshes/finger1_link2.stl" scale="-1 1 1" /><mesh name="ldjy_left_finger1_link3_visual_0" file="ldjy_hand/meshes/finger1_link3.stl" scale="-1 1 1" /><mesh name="ldjy_left_finger1_link4_visual_0" file="ldjy_hand/meshes/finger1_link4.stl" scale="-1 1 1" /><mesh name="ldjy_left_finger1_link4_collision" file="ldjy_hand/meshes/finger1_link4_collision.stl" scale="-1 1 1" /><mesh name="ldjy_left_finger2_link1_visual_0" file="ldjy_hand/meshes/finger2_link1.stl" scale="-1 1 1" /><mesh name="ldjy_left_finger2_link2_visual_0" file="ldjy_hand/meshes/finger2_link2.stl" scale="-1 1 1" /><mesh name="ldjy_left_finger2_link3_visual_0" file="ldjy_hand/meshes/finger2_link3.stl" scale="-1 1 1" /><mesh name="ldjy_left_finger2_link4_visual_0" file="ldjy_hand/meshes/finger2_link4.stl" scale="-1 1 1" /><mesh name="ldjy_left_finger2_link4_collision" file="ldjy_hand/meshes/finger2_link4_collision.stl" scale="-1 1 1" /><mesh name="ldjy_left_finger3_link1_visual_0" file="ldjy_hand/meshes/finger3_link1.stl" scale="-1 1 1" /><mesh name="ldjy_left_finger3_link2_visual_0" file="ldjy_hand/meshes/finger3_link2.stl" scale="-1 1 1" /><mesh name="ldjy_left_finger3_link3_visual_0" file="ldjy_hand/meshes/finger3_link3.stl" scale="-1 1 1" /><mesh name="ldjy_left_finger3_link4_visual_0" file="ldjy_hand/meshes/finger3_link4.stl" scale="-1 1 1" /><mesh name="ldjy_left_finger3_link4_collision" file="ldjy_hand/meshes/finger3_link4_collision.stl" scale="-1 1 1" /><mesh name="ldjy_left_thumb_link1_visual_0" file="ldjy_hand/meshes/thumb_link1.stl" scale="-1 1 1" /><mesh name="ldjy_left_thumb_link2_visual_0" file="ldjy_hand/meshes/thumb_link2.stl" scale="-1 1 1" /><mesh name="ldjy_left_thumb_link3_visual_0" file="ldjy_hand/meshes/thumb_link3.stl" scale="-1 1 1" /><mesh name="ldjy_left_thumb_link4_visual_0" file="ldjy_hand/meshes/thumb_link4.stl" scale="-1 1 1" /><mesh name="ldjy_left_thumb_link4_collision" file="ldjy_hand/meshes/thumb_link4_collision.stl" scale="-1 1 1" /><mesh name="ldjy_left_finger4_link1_visual_0" file="ldjy_hand/meshes/finger4_link1.stl" scale="-1 1 1" /><mesh name="ldjy_left_finger4_link2_visual_0" file="ldjy_hand/meshes/finger4_link2.stl" scale="-1 1 1" /><mesh name="ldjy_left_finger4_link3_visual_0" file="ldjy_hand/meshes/finger4_link3.stl" scale="-1 1 1" /><mesh name="ldjy_left_finger4_link4_visual_0" file="ldjy_hand/meshes/finger4_link4.stl" scale="-1 1 1" /><mesh name="ldjy_left_finger4_link4_collision" file="ldjy_hand/meshes/finger4_link4_collision.stl" scale="-1 1 1" /><mesh name="ldjy_right_palm_visual_0" file="ldjy_hand/meshes/palm.stl" /><mesh name="ldjy_right_palm_collision" file="ldjy_hand/meshes/palm_collision.stl" /><mesh name="ldjy_right_finger1_link1_visual_0" file="ldjy_hand/meshes/finger1_link1.stl" /><mesh name="ldjy_right_finger1_link2_visual_0" file="ldjy_hand/meshes/finger1_link2.stl" /><mesh name="ldjy_right_finger1_link3_visual_0" file="ldjy_hand/meshes/finger1_link3.stl" /><mesh name="ldjy_right_finger1_link4_visual_0" file="ldjy_hand/meshes/finger1_link4.stl" /><mesh name="ldjy_right_finger1_link4_collision" file="ldjy_hand/meshes/finger1_link4_collision.stl" /><mesh name="ldjy_right_finger2_link1_visual_0" file="ldjy_hand/meshes/finger2_link1.stl" /><mesh name="ldjy_right_finger2_link2_visual_0" file="ldjy_hand/meshes/finger2_link2.stl" /><mesh name="ldjy_right_finger2_link3_visual_0" file="ldjy_hand/meshes/finger2_link3.stl" /><mesh name="ldjy_right_finger2_link4_visual_0" file="ldjy_hand/meshes/finger2_link4.stl" /><mesh name="ldjy_right_finger2_link4_collision" file="ldjy_hand/meshes/finger2_link4_collision.stl" /><mesh name="ldjy_right_finger3_link1_visual_0" file="ldjy_hand/meshes/finger3_link1.stl" /><mesh name="ldjy_right_finger3_link2_visual_0" file="ldjy_hand/meshes/finger3_link2.stl" /><mesh name="ldjy_right_finger3_link3_visual_0" file="ldjy_hand/meshes/finger3_link3.stl" /><mesh name="ldjy_right_finger3_link4_visual_0" file="ldjy_hand/meshes/finger3_link4.stl" /><mesh name="ldjy_right_finger3_link4_collision" file="ldjy_hand/meshes/finger3_link4_collision.stl" /><mesh name="ldjy_right_thumb_link1_visual_0" file="ldjy_hand/meshes/thumb_link1.stl" /><mesh name="ldjy_right_thumb_link2_visual_0" file="ldjy_hand/meshes/thumb_link2.stl" /><mesh name="ldjy_right_thumb_link3_visual_0" file="ldjy_hand/meshes/thumb_link3.stl" /><mesh name="ldjy_right_thumb_link4_visual_0" file="ldjy_hand/meshes/thumb_link4.stl" /><mesh name="ldjy_right_thumb_link4_collision" file="ldjy_hand/meshes/thumb_link4_collision.stl" /><mesh name="ldjy_right_finger4_link1_visual_0" file="ldjy_hand/meshes/finger4_link1.stl" /><mesh name="ldjy_right_finger4_link2_visual_0" file="ldjy_hand/meshes/finger4_link2.stl" /><mesh name="ldjy_right_finger4_link3_visual_0" file="ldjy_hand/meshes/finger4_link3.stl" /><mesh name="ldjy_right_finger4_link4_visual_0" file="ldjy_hand/meshes/finger4_link4.stl" /><mesh name="ldjy_right_finger4_link4_collision" file="ldjy_hand/meshes/finger4_link4_collision.stl" /></asset>

  <worldbody>
    <body name="openflex_robot_yaw_root" pos="0 0 0.17" euler="0 0 -1.57079632679"><body name="base_link">
      <inertial pos="0 0 0" quat="0 0.707107 0 0.707107" mass="20" diaginertia="0.683333 0.449333 0.299333" />
      <geom quat="0.707105 0.707108 0 0" type="mesh" contype="3" conaffinity="3" group="1" density="0" rgba="0.28 0.28 0.28 1" mesh="packages_openflex_chassis_swerve_description_meshes_base_link" />
      <body name="base_footprint" pos="0 0 -0.17">
        <inertial pos="0 0 0" mass="0.5" diaginertia="0.002 0.002 0.002" />
      </body>
      <body name="fl_steering_link" pos="0.21 0.2735 -0.07">
        <inertial pos="0 0 0" quat="0.5 0.5 -0.5 0.5" mass="0.5" diaginertia="0.000225 0.000216667 0.000216667" />
        <joint name="fl_steering_joint" pos="0 0 0" axis="0 0 1" range="-1.5708 1.5708" actuatorfrcrange="-10 10" damping="3.0" armature="0.005" frictionloss="0.1" />
        <body name="fl_wheel_link" pos="0 0 -0.025">
          <inertial pos="0 0 0" quat="0.5 0.5 -0.5 0.5" mass="2" diaginertia="0.005625 0.0034125 0.0034125" />
          <joint name="fl_wheel_joint" pos="0 0 0" axis="0 1 0" damping="1.0" armature="0.02" frictionloss="0.0" />
          <geom pos="0.075 0.045 -0.075" quat="-0.499999 -0.500001 0.500001 0.499999" type="mesh" contype="3" conaffinity="3" group="1" density="0" rgba="0.1 0.1 0.1 1" mesh="packages_openflex_chassis_swerve_description_meshes_fl_wheel_link" />
        </body>
      </body>
      <body name="fr_steering_link" pos="0.21 -0.2735 -0.07">
        <inertial pos="0 0 0" quat="0.5 0.5 -0.5 0.5" mass="0.5" diaginertia="0.000225 0.000216667 0.000216667" />
        <joint name="fr_steering_joint" pos="0 0 0" axis="0 0 1" range="-1.5708 1.5708" actuatorfrcrange="-10 10" damping="3.0" armature="0.005" frictionloss="0.1" />
        <body name="fr_wheel_link" pos="0 0 -0.025">
          <inertial pos="0 0 0" quat="0.5 0.5 -0.5 0.5" mass="2" diaginertia="0.005625 0.0034125 0.0034125" />
          <joint name="fr_wheel_joint" pos="0 0 0" axis="0 1 0" damping="1.0" armature="0.02" frictionloss="0.0" />
          <geom pos="-0.075 -0.045 -0.075" quat="0.499999 0.500001 0.500001 0.499999" type="mesh" contype="3" conaffinity="3" group="1" density="0" rgba="0.1 0.1 0.1 1" mesh="packages_openflex_chassis_swerve_description_meshes_fr_wheel_link" />
        </body>
      </body>
      <body name="bl_steering_link" pos="-0.21 0.2735 -0.07">
        <inertial pos="0 0 0" quat="0.5 0.5 -0.5 0.5" mass="0.5" diaginertia="0.000225 0.000216667 0.000216667" />
        <joint name="bl_steering_joint" pos="0 0 0" axis="0 0 1" range="-1.5708 1.5708" actuatorfrcrange="-10 10" damping="3.0" armature="0.005" frictionloss="0.1" />
        <body name="bl_wheel_link" pos="0 0 -0.025">
          <inertial pos="0 0 0" quat="0.5 0.5 -0.5 0.5" mass="2" diaginertia="0.005625 0.0034125 0.0034125" />
          <joint name="bl_wheel_joint" pos="0 0 0" axis="0 1 0" damping="1.0" armature="0.02" frictionloss="0.0" />
          <geom pos="0.075 0.045 -0.075" quat="-0.499999 -0.500001 0.500001 0.499999" type="mesh" contype="3" conaffinity="3" group="1" density="0" rgba="0.1 0.1 0.1 1" mesh="packages_openflex_chassis_swerve_description_meshes_bl_wheel_link" />
        </body>
      </body>
      <body name="br_steering_link" pos="-0.21 -0.2735 -0.07">
        <inertial pos="0 0 0" quat="0.5 0.5 -0.5 0.5" mass="0.5" diaginertia="0.000225 0.000216667 0.000216667" />
        <joint name="br_steering_joint" pos="0 0 0" axis="0 0 1" range="-1.5708 1.5708" actuatorfrcrange="-10 10" damping="3.0" armature="0.005" frictionloss="0.1" />
        <body name="br_wheel_link" pos="0 0 -0.025">
          <inertial pos="0 0 0" quat="0.5 0.5 -0.5 0.5" mass="2" diaginertia="0.005625 0.0034125 0.0034125" />
          <joint name="br_wheel_joint" pos="0 0 0" axis="0 1 0" damping="1.0" armature="0.02" frictionloss="0.0" />
          <geom pos="-0.075 -0.045 -0.075" quat="0.499999 0.500001 0.500001 0.499999" type="mesh" contype="3" conaffinity="3" group="1" density="0" rgba="0.1 0.1 0.1 1" mesh="packages_openflex_chassis_swerve_description_meshes_br_wheel_link" />
        </body>
      </body>
      <body name="mid360_link" pos="0.3 0 0.12" quat="0.683011 -0.183013 0.183013 -0.683014">
        <inertial pos="0 0 0" quat="0.5 0.5 -0.5 0.5" mass="0.35" diaginertia="0.000214375 0.000153854 0.000153854" />
        <geom pos="-0.0328 0.0346 -0.0435" quat="0.707105 0.707108 0 0" type="mesh" contype="3" conaffinity="3" group="1" density="0" rgba="0.2 0.4 0.9 1" mesh="packages_openflex_chassis_swerve_description_meshes_mid360_link" />
        <body name="livox_frame">
          <inertial pos="0 0 0" mass="0.5" diaginertia="0.002 0.002 0.002" />
        </body>
        <body name="imu_link">
          <inertial pos="0 0 0" mass="0.5" diaginertia="0.002 0.002 0.002" />
        </body>
      </body>
      <body name="d435_link" pos="0.36 0 0.055">
        <inertial pos="0 0 0" quat="0.707107 0.707107 0 0" mass="0.1" diaginertia="7.27083e-05 7.27083e-05 1.04167e-05" />
        <geom pos="0.0152 0.0447 -0.0129" quat="0.499999 0.500001 -0.500001 -0.499999" type="mesh" contype="3" conaffinity="3" group="1" density="0" rgba="0.1 0.1 0.1 1" mesh="packages_openflex_chassis_swerve_description_meshes_d435_link" />
        <body name="camera_link">
          <inertial pos="0 0 0" mass="0.5" diaginertia="0.002 0.002 0.002" />
          <body name="camera_depth_frame">
            <inertial pos="0 0 0" mass="0.5" diaginertia="0.002 0.002 0.002" />
            <body name="camera_depth_optical_frame" quat="0.5 -0.5 0.5 -0.5">
              <inertial pos="0 0 0" mass="0.5" diaginertia="0.002 0.002 0.002" />
            </body>
          </body>
          <body name="camera_rgb_frame">
            <inertial pos="0 0 0" mass="0.5" diaginertia="0.002 0.002 0.002" />
            <body name="camera_rgb_optical_frame" quat="0.5 -0.5 0.5 -0.5">
              <inertial pos="0 0 0" mass="0.5" diaginertia="0.002 0.002 0.002" />
            </body>
          </body>
        </body>
        <body name="d435_depth_frame">
          <inertial pos="0 0 0" mass="0.5" diaginertia="0.002 0.002 0.002" />
          <body name="d435_depth_optical_frame" quat="0.5 -0.5 0.5 -0.5">
            <inertial pos="0 0 0" mass="0.5" diaginertia="0.002 0.002 0.002" />
          </body>
        </body>
        <body name="d435_color_frame">
          <inertial pos="0 0 0" mass="0.5" diaginertia="0.002 0.002 0.002" />
          <body name="d435_color_optical_frame" quat="0.5 -0.5 0.5 -0.5">
            <inertial pos="0 0 0" mass="0.5" diaginertia="0.002 0.002 0.002" />
          </body>
        </body>
      </body>
      <body name="gps_link" pos="0.06 0 0.24">
        <inertial pos="0 0 0" mass="0.5" diaginertia="0.002 0.002 0.002" />
      </body>
      <body name="lift_base_link" pos="-0.033 0 0.07" quat="0.707105 0 0 -0.707108">
        <inertial pos="4.73423e-05 -0.017555 0.663555" quat="0.707116 0.000552974 -0.00055296 0.707097" mass="9.62227" diaginertia="1.49187 1.46902 0.0318312" />
        <geom type="mesh" contype="3" conaffinity="3" group="1" density="0" rgba="0.48 0.48 0.5 1" mesh="packages_lift_slide_description_meshes_lift_link" />
        <body name="lift_carriage_link" pos="0 0.055 0.81">
          <inertial pos="-0.00061635 0.0527963 0.0200912" quat="0.706475 0.000381723 -0.000356955 0.707737" mass="2.32322" diaginertia="0.00863611 0.00730306 0.00642289" />
          <joint name="lift_joint" pos="0 0 0" axis="0 0 1" type="slide" range="-0.65 0.3" actuatorfrcrange="-3000 3000" damping="60.0" frictionloss="2.0" armature="0.1" />
          <geom type="mesh" contype="3" conaffinity="3" group="1" density="0" rgba="0.79216 0.81961 0.93333 1" mesh="packages_lift_slide_description_meshes_plate_link" />
          <body name="chest_link" pos="0 0.143 0.018">
            <inertial pos="0 0 0" mass="0.5" diaginertia="0.002 0.002 0.002" />
            <geom pos="-0.1558 0.1 -0.15" quat="0.707105 0.707108 0 0" type="mesh" contype="3" conaffinity="3" group="1" density="0" rgba="0.92 0.92 0.94 1" mesh="packages_lift_slide_description_meshes_chest_link" />
          </body>
          <body name="left_link0_base" pos="-0.075 0.14555 0.025" quat="0.499998 -0.5 -0.500002 0.5">
            <inertial pos="-0.000217889 0 -0.00249049" quat="0.999048 0 0.0436194 0" mass="9.81748e-05" diaginertia="3.57929e-10 3.57929e-10 3.06796e-10" />
            <geom type="mesh" contype="3" conaffinity="3" group="1" density="0" rgba="0.79216 0.81961 0.93333 1" mesh="packages_lift_slide_description_meshes_left_link0_base" />
            <body name="openarmx_left_link0">
              <inertial pos="0.000319 -0.00067 0.029184" quat="0.497862 0.511796 -0.475431 0.513968" mass="1.77268" diaginertia="0.00341526 0.00246403 0.00195971" />
              <geom name="openarmx_left_link0_visual_part0" type="mesh" contype="3" conaffinity="3" group="1" density="0" rgba="0.5 0.5 0.55 1" mesh="packages_openarmx_description_meshes_arm_v10_visual_link0_mirror_pnp_part0" />
              <geom name="openarmx_left_link0_visual_part1" type="mesh" contype="3" conaffinity="3" group="1" density="0" rgba="0.92 0.92 0.95 1" mesh="packages_openarmx_description_meshes_arm_v10_visual_link0_mirror_pnp_part1" />
              <body name="openarmx_left_link1" pos="0 0 0.058">
                <inertial pos="0.004452 2.5e-05 0.073323" quat="0.999503 0.000644393 -0.0315003 0.00114209" mass="1.68876" diaginertia="0.00346919 0.002551 0.00190982" />
                <joint name="openarmx_left_joint1" pos="0 0 0" axis="0 0 1" range="-3.3444 0.905604" actuatorfrcrange="-120 120" damping="18.0" armature="0.03" frictionloss="0.15" />
                <geom name="openarmx_left_link1_visual_part0" type="mesh" contype="3" conaffinity="3" group="1" density="0" rgba="0.5 0.5 0.55 1" mesh="packages_openarmx_description_meshes_arm_v10_visual_link1_mirror_pnp_part0" />
                <geom name="openarmx_left_link1_visual_part1" type="mesh" contype="3" conaffinity="3" group="1" density="0" rgba="0.92 0.92 0.95 1" mesh="packages_openarmx_description_meshes_arm_v10_visual_link1_mirror_pnp_part1" />
                <body name="openarmx_left_link2" pos="-0.0205 0 0.081" quat="0.707105 -0.707108 0 0">
                  <inertial pos="-0.003787 -0.000221 0.04901" quat="0.986716 -0.00145381 -0.161354 -0.0188355" mass="0.396704" diaginertia="0.000891196 0.000821946 0.000327857" />
                  <joint name="openarmx_left_joint2" pos="0 0 0" axis="-1 0 0" range="-3.2708 0.129204" actuatorfrcrange="-120 120" damping="18.0" armature="0.03" frictionloss="0.15" />
                  <geom name="openarmx_left_link2_visual_part0" type="mesh" contype="3" conaffinity="3" group="1" density="0" rgba="0.5 0.5 0.55 1" mesh="packages_openarmx_description_meshes_arm_v10_visual_link2_mirror_pnp_part0" />
                  <geom name="openarmx_left_link2_visual_part1" type="mesh" contype="3" conaffinity="3" group="1" density="0" rgba="0.15 0.65 0.7 1" mesh="packages_openarmx_description_meshes_arm_v10_visual_link2_mirror_pnp_part1" />
                  <body name="openarmx_left_link3" pos="0.02 0 0.099">
                    <inertial pos="-0.000828 -0.000236 0.083336" quat="0.946133 0.00530809 0.00424656 -0.323707" mass="2.49278" diaginertia="0.0103641 0.0103322 0.00300164" />
                    <joint name="openarmx_left_joint3" pos="0 0 0" axis="0 0 1" range="-1.57 1.57" actuatorfrcrange="-60 60" damping="18.0" armature="0.03" frictionloss="0.15" />
                    <geom name="openarmx_left_link3_visual_part0" type="mesh" contype="3" conaffinity="3" group="1" density="0" rgba="0.5 0.5 0.55 1" mesh="packages_openarmx_description_meshes_arm_v10_visual_link3_mirror_pnp_part0" />
                    <geom name="openarmx_left_link3_visual_part1" type="mesh" contype="3" conaffinity="3" group="1" density="0" rgba="0.92 0.92 0.95 1" mesh="packages_openarmx_description_meshes_arm_v10_visual_link3_mirror_pnp_part1" />
                    <body name="openarmx_left_link4" pos="0 0.031002 0.14181">
                      <inertial pos="-0.002591 -0.030135 0.07147" quat="0.999683 -0.0233783 -0.00922341 -0.00115143" mass="0.779755" diaginertia="0.00201543 0.00162187 0.000765704" />
                      <joint name="openarmx_left_joint4" pos="0 0 0" axis="0 1 0" range="0 1.8" actuatorfrcrange="-60 60" damping="18.0" armature="0.03" frictionloss="0.15" />
                      <geom name="openarmx_left_link4_visual_part0" type="mesh" contype="3" conaffinity="3" group="1" density="0" rgba="0.5 0.5 0.55 1" mesh="packages_openarmx_description_meshes_arm_v10_visual_link4_part0" />
                      <geom name="openarmx_left_link4_visual_part1" type="mesh" contype="3" conaffinity="3" group="1" density="0" rgba="0.15 0.65 0.7 1" mesh="packages_openarmx_description_meshes_arm_v10_visual_link4_part1" />
                      <body name="openarmx_left_link4_ext" pos="0 -0.065 0">
                        <inertial pos="0 0 0" mass="0.5" diaginertia="0.002 0.002 0.002" />
                      </body>
                      <body name="openarmx_left_link5" pos="0 -0.0309 0.126">
                        <inertial pos="-0.002256 -0.000305 0.0533" quat="0.714458 -0.0122081 -0.0110113 0.699485" mass="0.687255" diaginertia="0.00106611 0.000831256 0.000495637" />
                        <joint name="openarmx_left_joint5" pos="0 0 0" axis="0 0 1" range="-1.5 1.5" actuatorfrcrange="-14 14" damping="18.0" armature="0.03" frictionloss="0.15" />
                        <geom name="openarmx_left_link5_visual_part0" type="mesh" contype="3" conaffinity="3" group="1" density="0" rgba="0.5 0.5 0.55 1" mesh="packages_openarmx_description_meshes_arm_v10_visual_link5_mirror_pnp_part0" />
                        <geom name="openarmx_left_link5_visual_part1" type="mesh" contype="3" conaffinity="3" group="1" density="0" rgba="0.92 0.92 0.95 1" mesh="packages_openarmx_description_meshes_arm_v10_visual_link5_mirror_pnp_part1" />
                        <body name="openarmx_left_link6" pos="0.037426 0 0.131">
                          <inertial pos="-0.03564 0.005114 -0.003582" quat="0.945265 0.038546 0.187709 -0.26411" mass="0.384836" diaginertia="0.000317632 0.000265263 0.000212105" />
                          <joint name="openarmx_left_joint6" pos="0 0 0" axis="1 0 0" range="-0.75 0.75" actuatorfrcrange="-14 14" damping="18.0" armature="0.03" frictionloss="0.15" />
                          <geom name="openarmx_left_link6_visual_part0" type="mesh" contype="3" conaffinity="3" group="1" density="0" rgba="0.5 0.5 0.55 1" mesh="packages_openarmx_description_meshes_arm_v10_visual_link6_mirror_pnp_part0" />
                          <geom name="openarmx_left_link6_visual_part1" type="mesh" contype="3" conaffinity="3" group="1" density="0" rgba="0.8 0.8 0.82 1" mesh="packages_openarmx_description_meshes_arm_v10_visual_link6_mirror_pnp_part1" />
                          <body name="openarmx_left_link7" pos="-0.0375 0 0">
                            <inertial pos="-3e-06 -0.002128 0.091961" quat="0.98918 -0.138774 0.00159491 -0.0475613" mass="0.624972" diaginertia="0.00160275 0.00108708 0.000759171" />
                            <joint name="openarmx_left_joint7" pos="0 0 0" axis="0 -1 0" range="-1.4 1.4" actuatorfrcrange="-14 14" damping="18.0" armature="0.03" frictionloss="0.15" />
                            <geom name="openarmx_left_link7_visual_part0" type="mesh" contype="3" conaffinity="3" group="1" density="0" rgba="0.5 0.5 0.55 1" mesh="packages_openarmx_description_meshes_arm_v10_visual_link7_mirror_pnp_part0" />
                            <body name="ldjy_left_palm" pos="0 0 0.0895" euler="0 0 3.14159265"><inertial pos="0.002100989686 -0.001688548819 0.01727660861" mass="0.200010115" fullinertia="0.0001400575215 0.0001960126545 9.28994431e-05 -3.300850571e-06 -1.303765852e-05 -1.969913402e-06" /><geom name="ldjy_left_palm_visual_0_geom" type="mesh" mesh="ldjy_left_palm_visual_0" pos="0.0 0.0 0.0" euler="0.0 0.0 0.0" contype="0" conaffinity="0" group="1" density="0" rgba="0.72 0.76 0.78 1" /><geom name="ldjy_left_palm_collision" rgba="0.55 0.7 0.9 0" friction="0.7 0.005 0.0001" solref="0.02 1.5" solimp="0.9 0.95 0.001 0.5 2.0" priority="1" condim="3" type="mesh" mesh="ldjy_left_palm_collision" pos="0.0 0.0 0.0" euler="0.0 0.0 0.0" contype="3" conaffinity="3" /><body name="ldjy_left_finger1_link1" pos="-0.0233 -0.00295 0.0495" euler="0.0 0.0 0.0"><inertial pos="-0.002552140053 -0.0002949597412 0.01500495062" mass="0.0150541391" fullinertia="2.363453405e-06 1.594218588e-06 1.446291259e-06 4.524555776e-08 -1.6055183e-07 2.654450928e-07" /><joint name="ldjy_left_finger1_joint1" axis="0.0 1.0 0.0" range="-0.37 0.37" actuatorfrcrange="-0.1822 0.1822" armature="0.0005" /><geom name="ldjy_left_finger1_link1_visual_0_geom" type="mesh" mesh="ldjy_left_finger1_link1_visual_0" pos="0.0233 0.00295 -0.0495" euler="0.0 0.0 0.0" contype="0" conaffinity="0" group="1" density="0" rgba="0.72 0.76 0.78 1" /><body name="ldjy_left_finger1_link2" pos="0.0009621741619 -0.0117 0.02207380139" euler="0.0 0.0 0.0"><inertial pos="-0.007529199598 -0.000357884412 0.01653624902" mass="0.01150473762" fullinertia="1.861515854e-06 1.970814569e-06 5.399282613e-07 5.501808106e-09 -2.315560267e-07 3.19692724e-08" /><joint name="ldjy_left_finger1_joint2" axis="-0.9858405936 0.0 -0.1676851933" range="-1.5604 0.0" actuatorfrcrange="-0.6188 0.6188" armature="0.0005" /><geom name="ldjy_left_finger1_link2_visual_0_geom" type="mesh" mesh="ldjy_left_finger1_link2_visual_0" pos="0.02233782584 0.01465 -0.07157380139" euler="0.0 0.0 0.0" contype="0" conaffinity="0" group="1" density="0" rgba="0.72 0.76 0.78 1" /><geom name="ldjy_left_finger1_link2_capsule_body" rgba="0.55 0.7 0.9 0" friction="0.7 0.005 0.0001" solref="0.02 1.5" solimp="0.9 0.95 0.001 0.5 2.0" priority="1" condim="3" type="capsule" fromto="-0.005864106671017739 -3.315357052071993e-05 0.0021571807155113445 -0.008643711232982262 0.0015634059923207199 0.029713695544488654" size="0.007647541322" contype="3" conaffinity="3" /><body name="ldjy_left_finger1_link3" pos="-0.005447258779 -0.0009862714603 0.03202506269" euler="0.0 0.0 0.0"><inertial pos="-0.007529199598 -0.000357884412 0.01653624902" mass="0.01150473762" fullinertia="1.861515854e-06 1.970814569e-06 5.399282613e-07 5.501808106e-09 -2.315560267e-07 3.19692724e-08" /><joint name="ldjy_left_finger1_joint3" axis="-0.9858405936 0.0 -0.1676851933" range="-1.5485 0.4777" actuatorfrcrange="-0.2251 0.2251" armature="0.0005" /><geom name="ldjy_left_finger1_link3_visual_0_geom" type="mesh" mesh="ldjy_left_finger1_link3_visual_0" pos="0.02778508462 0.01563627146 -0.1035988641" euler="0.0 0.0 0.0" contype="0" conaffinity="0" group="1" density="0" rgba="0.72 0.76 0.78 1" /><geom name="ldjy_left_finger1_link3_capsule_body" rgba="0.55 0.7 0.9 0" friction="0.7 0.005 0.0001" solref="0.02 1.5" solimp="0.9 0.95 0.001 0.5 2.0" priority="1" condim="3" type="capsule" fromto="-0.005864106671017739 -3.315357052071993e-05 0.0021571807155113445 -0.008643711232982262 0.0015634059923207199 0.029713695544488654" size="0.007647541322" contype="3" conaffinity="3" /><body name="ldjy_left_finger1_link4" pos="-0.005447258779 -0.0009862714603 0.03202506269" euler="0.0 0.0 0.0"><inertial pos="-0.006403231499 -0.0003803927588 0.009915921237" mass="0.007585938385" fullinertia="6.792669082e-07 7.730027699e-07 3.194495902e-07 2.470647307e-09 -6.30049988e-08 1.451842468e-08" /><joint name="ldjy_left_finger1_joint4" axis="-0.9858405936 0.0 -0.1676851933" range="-1.5753 0.4683" actuatorfrcrange="-0.217 0.217" armature="0.0005" /><geom name="ldjy_left_finger1_link4_visual_0_geom" type="mesh" mesh="ldjy_left_finger1_link4_visual_0" pos="0.0332323434 0.01662254292 -0.1356239268" euler="0.0 0.0 0.0" contype="0" conaffinity="0" group="1" density="0" rgba="0.72 0.76 0.78 1" /><geom name="ldjy_left_finger1_link4_collision" rgba="0.55 0.7 0.9 0" friction="0.7 0.005 0.0001" solref="0.02 1.5" solimp="0.9 0.95 0.001 0.5 2.0" priority="1" condim="3" type="mesh" mesh="ldjy_left_finger1_link4_collision" pos="0.0332323434 0.01662254292 -0.1356239268" euler="0.0 0.0 0.0" contype="3" conaffinity="3" /><site name="ldjy_left_finger1_link4_tip" pos="0 0 0.025" group="4" size="0.003" /></body></body></body></body><body name="ldjy_left_finger2_link1" pos="0.0 -0.00295 0.0545" euler="0.0 0.0 0.0"><inertial pos="0.0004261161081 -0.0002949597412 0.01521447952" mass="0.0150541391" fullinertia="2.389979737e-06 1.594218588e-06 1.419764927e-06 -7.443150302e-09 2.7281791e-08 2.691706844e-07" /><joint name="ldjy_left_finger2_joint1" axis="0.0 1.0 0.0" range="-0.37 0.37" actuatorfrcrange="-0.1827 0.1827" armature="0.0005" /><geom name="ldjy_left_finger2_link1_visual_0_geom" type="mesh" mesh="ldjy_left_finger2_link1_visual_0" pos="0.0 0.00295 -0.0545" euler="0.0 0.0 0.0" contype="0" conaffinity="0" group="1" density="0" rgba="0.72 0.76 0.78 1" /><body name="ldjy_left_finger2_link2" pos="0.005252746989 -0.0117 0.0214612939" euler="0.0 0.0 0.0"><inertial pos="-0.00415623752 -0.0003144280118 0.01768873326" mass="0.01150473762" fullinertia="1.899818734e-06 1.970966079e-06 5.014738708e-07 -7.431753573e-10 3.91233677e-08 2.879175918e-08" /><joint name="ldjy_left_finger2_joint2" axis="-0.9996082196 0.0 0.02798941517" range="-1.5516 0.0" actuatorfrcrange="-0.6494 0.6494" armature="0.0005" /><geom name="ldjy_left_finger2_link2_visual_0_geom" type="mesh" mesh="ldjy_left_finger2_link2_visual_0" pos="-0.005252746989 0.01465 -0.0759612939" euler="0.0 0.0 0.0" contype="0" conaffinity="0" group="1" density="0" rgba="0.72 0.76 0.78 1" /><geom name="ldjy_left_finger2_link2_capsule_body" rgba="0.55 0.7 0.9 0" friction="0.7 0.005 0.0001" solref="0.02 1.5" solimp="0.9 0.95 0.001 0.5 2.0" priority="1" condim="3" type="capsule" fromto="-0.005330175945664866 -2.5459360278297892e-05 0.0032604985870525113 -0.0026770375963351334 0.0016394585514782978 0.03082543317294749" size="0.007647541322" contype="3" conaffinity="3" /><body name="ldjy_left_finger2_link3" pos="0.0009093025454 -0.0009058997649 0.03247464418" euler="0.0 0.0 0.0"><inertial pos="-0.00415623752 -0.0003144280118 0.01768873326" mass="0.01150473762" fullinertia="1.899818734e-06 1.970966079e-06 5.014738708e-07 -7.431753573e-10 3.91233677e-08 2.879175918e-08" /><joint name="ldjy_left_finger2_joint3" axis="-0.9996082196 0.0 0.02798941517" range="-1.5512 0.4739" actuatorfrcrange="-0.2078 0.2078" armature="0.0005" /><geom name="ldjy_left_finger2_link3_visual_0_geom" type="mesh" mesh="ldjy_left_finger2_link3_visual_0" pos="-0.006162049534 0.01555589976 -0.1084359381" euler="0.0 0.0 0.0" contype="0" conaffinity="0" group="1" density="0" rgba="0.72 0.76 0.78 1" /><geom name="ldjy_left_finger2_link3_capsule_body" rgba="0.55 0.7 0.9 0" friction="0.7 0.005 0.0001" solref="0.02 1.5" solimp="0.9 0.95 0.001 0.5 2.0" priority="1" condim="3" type="capsule" fromto="-0.005330175945664866 -2.5459360278297892e-05 0.0032604985870525113 -0.0026770375963351334 0.0016394585514782978 0.03082543317294749" size="0.007647541322" contype="3" conaffinity="3" /><body name="ldjy_left_finger2_link4" pos="0.0009093025454 -0.0009058997649 0.03247464418" euler="0.0 0.0 0.0"><inertial pos="-0.004344301239 -0.0003535503261 0.01097604734" mass="0.007585938385" fullinertia="6.896804327e-07 7.730727985e-07 3.08966037e-07 -3.788620486e-10 1.068844763e-08 1.357307458e-08" /><joint name="ldjy_left_finger2_joint4" axis="-0.9996082196 0.0 0.02798941517" range="-1.5745 0.4684" actuatorfrcrange="-0.2018 0.2018" armature="0.0005" /><geom name="ldjy_left_finger2_link4_visual_0_geom" type="mesh" mesh="ldjy_left_finger2_link4_visual_0" pos="-0.00707135208 0.01646179953 -0.1409105823" euler="0.0 0.0 0.0" contype="0" conaffinity="0" group="1" density="0" rgba="0.72 0.76 0.78 1" /><geom name="ldjy_left_finger2_link4_collision" rgba="0.55 0.7 0.9 0" friction="0.7 0.005 0.0001" solref="0.02 1.5" solimp="0.9 0.95 0.001 0.5 2.0" priority="1" condim="3" type="mesh" mesh="ldjy_left_finger2_link4_collision" pos="-0.00707135208 0.01646179953 -0.1409105823" euler="0.0 0.0 0.0" contype="3" conaffinity="3" /><site name="ldjy_left_finger2_link4_tip" pos="0 0 0.025" group="4" size="0.003" /></body></body></body></body><body name="ldjy_left_finger3_link1" pos="0.0233 -0.00295 0.0445" euler="0.0 0.0 0.0"><inertial pos="0.002586982248 -0.0002951945879 0.01499906285" mass="0.01505382492" fullinertia="2.362593935e-06 1.5942064e-06 1.447056064e-06 -4.568916311e-08 1.628553627e-07 2.653544912e-07" /><joint name="ldjy_left_finger3_joint1" axis="0.0 1.0 0.0" range="-0.37 0.37" actuatorfrcrange="-0.1832 0.1832" armature="0.0005" /><geom name="ldjy_left_finger3_link1_visual_0_geom" type="mesh" mesh="ldjy_left_finger3_link1_visual_0" pos="-0.0233 0.00295 -0.0445" euler="0.0 0.0 0.0" contype="0" conaffinity="0" group="1" density="0" rgba="0.72 0.76 0.78 1" /><body name="ldjy_left_finger3_link2" pos="0.008253592832 -0.0117 0.02049528464" euler="0.0 0.0 0.0"><inertial pos="-0.001596931475 0.0004290719444 0.01809779453" mass="0.01150473762" fullinertia="1.860480436e-06 1.970768424e-06 5.410098243e-07 5.747964394e-09 2.344859304e-07 -3.297133497e-08" /><joint name="ldjy_left_finger3_joint2" axis="-0.98544992 0.0 0.1699660413" range="-1.5585 0.0" actuatorfrcrange="-0.6389 0.6389" armature="0.0005" /><geom name="ldjy_left_finger3_link2_visual_0_geom" type="mesh" mesh="ldjy_left_finger3_link2_visual_0" pos="-0.03155359283 0.01465 -0.06499528464" euler="0.0 0.0 0.0" contype="0" conaffinity="0" group="1" density="0" rgba="0.72 0.76 0.78 1" /><geom name="ldjy_left_finger3_link2_capsule_body" rgba="0.55 0.7 0.9 0" friction="0.7 0.005 0.0001" solref="0.02 1.5" solimp="0.9 0.95 0.001 0.5 2.0" priority="1" condim="3" type="capsule" fromto="-0.004812185541144998 0.00010615303547150366 0.003984203394555937 0.001720734881144998 0.0029385739125284962 0.030797167725444066" size="0.007647541322" contype="3" conaffinity="3" /><body name="ldjy_left_finger3_link3" pos="0.005523319931 0.0004694951803 0.0320237804" euler="0.0 0.0 0.0"><inertial pos="-0.001596931475 0.0004290719444 0.01809779453" mass="0.01150473762" fullinertia="1.860480436e-06 1.970768424e-06 5.410098243e-07 5.747964394e-09 2.344859304e-07 -3.297133497e-08" /><joint name="ldjy_left_finger3_joint3" axis="-0.98544992 0.0 0.1699660413" range="-1.5487 0.4765" actuatorfrcrange="-0.2249 0.2249" armature="0.0005" /><geom name="ldjy_left_finger3_link3_visual_0_geom" type="mesh" mesh="ldjy_left_finger3_link3_visual_0" pos="-0.03707691276 0.01418050482 -0.09701906504" euler="0.0 0.0 0.0" contype="0" conaffinity="0" group="1" density="0" rgba="0.72 0.76 0.78 1" /><geom name="ldjy_left_finger3_link3_capsule_body" rgba="0.55 0.7 0.9 0" friction="0.7 0.005 0.0001" solref="0.02 1.5" solimp="0.9 0.95 0.001 0.5 2.0" priority="1" condim="3" type="capsule" fromto="-0.004812185541144998 0.00010615303547150366 0.003984203394555937 0.001720734881144998 0.0029385739125284962 0.030797167725444066" size="0.007647541322" contype="3" conaffinity="3" /><body name="ldjy_left_finger3_link4" pos="0.005523319931 0.0004694951803 0.0320237804" euler="0.0 0.0 0.0"><inertial pos="-0.002737108666 0.0001058506004 0.01148775862" mass="0.007585938385" fullinertia="6.789489057e-07 7.733894034e-07 3.193809591e-07 1.039186966e-09 6.393916346e-08 -6.013182828e-09" /><joint name="ldjy_left_finger3_joint4" axis="-0.98544992 0.0 0.1699660413" range="-1.5634 0.4777" actuatorfrcrange="-0.2044 0.2044" armature="0.0005" /><geom name="ldjy_left_finger3_link4_visual_0_geom" type="mesh" mesh="ldjy_left_finger3_link4_visual_0" pos="-0.04260023269 0.01371100964 -0.1290428454" euler="0.0 0.0 0.0" contype="0" conaffinity="0" group="1" density="0" rgba="0.72 0.76 0.78 1" /><geom name="ldjy_left_finger3_link4_collision" rgba="0.55 0.7 0.9 0" friction="0.7 0.005 0.0001" solref="0.02 1.5" solimp="0.9 0.95 0.001 0.5 2.0" priority="1" condim="3" type="mesh" mesh="ldjy_left_finger3_link4_collision" pos="-0.04260023269 0.01371100964 -0.1290428454" euler="0.0 0.0 0.0" contype="3" conaffinity="3" /><site name="ldjy_left_finger3_link4_tip" pos="0 0 0.025" group="4" size="0.003" /></body></body></body></body><body name="ldjy_left_thumb_link1" pos="-0.0233 -0.00295 -0.0084" euler="0.0 0.0 0.0"><inertial pos="0.0008689005969 -0.003804801439 -0.001284419564" mass="0.009231749795" fullinertia="1.060881976e-06 4.170231492e-07 1.055511507e-06 5.894022963e-08 -1.130080766e-08 7.482297275e-08" /><joint name="ldjy_left_thumb_joint1" axis="0.0 1.0 0.0" range="-0.9250245036 1.5707963268" actuatorfrcrange="-0.4259 0.4259" armature="0.0005" /><geom name="ldjy_left_thumb_link1_visual_0_geom" type="mesh" mesh="ldjy_left_thumb_link1_visual_0" pos="0.0233 0.00295 0.0084" euler="0.0 0.0 0.0" contype="0" conaffinity="0" group="1" density="0" rgba="0.72 0.76 0.78 1" /><body name="ldjy_left_thumb_link2" pos="-0.002608560701 -0.0166 -0.001938533227" euler="0.0 0.0 0.0"><inertial pos="-0.008159715317 -0.000678399895 0.01634525189" mass="0.01361136422" fullinertia="2.067853631e-06 2.82551883e-06 1.405796287e-06 3.320375324e-08 -1.072979093e-06 4.507555487e-08" /><joint name="ldjy_left_thumb_joint2" axis="-0.8026340617 0.0 -0.5964717621" range="-1.6033 0.0" actuatorfrcrange="-0.4452 0.4452" armature="0.0005" /><geom name="ldjy_left_thumb_link2_visual_0_geom" type="mesh" mesh="ldjy_left_thumb_link2_visual_0" pos="0.0259085607 0.01955 0.01033853323" euler="0.0 0.0 0.0" contype="0" conaffinity="0" group="1" density="0" rgba="0.72 0.76 0.78 1" /><geom name="ldjy_left_thumb_link2_capsule_body" rgba="0.55 0.7 0.9 0" friction="0.7 0.005 0.0001" solref="0.02 1.5" solimp="0.9 0.95 0.001 0.5 2.0" priority="1" condim="3" type="capsule" fromto="0.0012674068890160713 -0.003368696520349595 0.004496985802651246 -0.01835717003901607 0.0006926715583495948 0.030009979377348756" size="0.007912057707" contype="3" conaffinity="3" /><body name="ldjy_left_thumb_link3" pos="-0.02024684923 -0.006366194767 0.03269360274" euler="0.0 0.0 0.0"><inertial pos="-0.008158821575 0.004675488222 0.01269274767" mass="0.01150473762" fullinertia="1.569176561e-06 1.899515634e-06 9.035664892e-07 2.301654039e-08 -6.555138346e-07 3.775871711e-08" /><joint name="ldjy_left_thumb_joint3" axis="-0.01888221858 0.9994988069 0.02540859896" range="0.0 1.5707963268" actuatorfrcrange="-0.1888 0.1888" armature="0.0005" /><geom name="ldjy_left_thumb_link3_visual_0_geom" type="mesh" mesh="ldjy_left_thumb_link3_visual_0" pos="0.04615540993 0.02591619477 -0.02235506952" euler="0.0 0.0 0.0" contype="0" conaffinity="0" group="1" density="0" rgba="0.72 0.76 0.78 1" /><geom name="ldjy_left_thumb_link3_capsule_body" rgba="0.55 0.7 0.9 0" friction="0.7 0.005 0.0001" solref="0.02 1.5" solimp="0.9 0.95 0.001 0.5 2.0" priority="1" condim="3" type="capsule" fromto="-0.0031561761038444896 0.003973012588344725 0.0003210599958376435 -0.01573803159815551 0.0049888195556552755 0.025025346304162355" size="0.007647541322" contype="3" conaffinity="3" /><body name="ldjy_left_thumb_link4" pos="-0.01722211724 -0.001025525643 0.02754263922" euler="0.0 0.0 0.0"><inertial pos="-0.006524915211 0.00468820306 0.0134094626" mass="0.01143731998" fullinertia="1.670475431e-06 1.858111984e-06 7.407043888e-07 1.736442301e-08 -5.39596932e-07 3.864265835e-08" /><joint name="ldjy_left_thumb_joint4" axis="-0.01888221858 0.9994988069 0.02540859896" range="0.0 1.5707963268" actuatorfrcrange="-0.1468 0.1468" armature="0.0005" /><geom name="ldjy_left_thumb_link4_visual_0_geom" type="mesh" mesh="ldjy_left_thumb_link4_visual_0" pos="0.06337752717 0.02694172041 -0.04989770873" euler="0.0 0.0 0.0" contype="0" conaffinity="0" group="1" density="0" rgba="0.72 0.76 0.78 1" /><geom name="ldjy_left_thumb_link4_collision" rgba="0.55 0.7 0.9 0" friction="0.7 0.005 0.0001" solref="0.02 1.5" solimp="0.9 0.95 0.001 0.5 2.0" priority="1" condim="3" type="mesh" mesh="ldjy_left_thumb_link4_collision" pos="0.06337752717 0.02694172041 -0.04989770873" euler="0.0 0.0 0.0" contype="3" conaffinity="3" /><site name="ldjy_left_thumb_link4_tip" pos="0 0 0.025" group="4" size="0.003" /></body></body></body></body><body name="ldjy_left_finger4_link1" pos="0.0233 -0.0136 -0.00335" euler="0.0 0.0 0.0"><inertial pos="0.01635947532 0.0003022085593 0.01584337601" mass="0.02634208642" fullinertia="8.041665618e-06 9.603291865e-06 2.681265216e-06 2.877050045e-08 2.017341866e-06 -3.162593458e-08" /><joint name="ldjy_left_finger4_joint1" axis="0.0 0.0 1.0" range="-1.0471975511965976 0.0" actuatorfrcrange="-0.1798 0.1798" armature="0.0005" /><geom name="ldjy_left_finger4_link1_visual_0_geom" type="mesh" mesh="ldjy_left_finger4_link1_visual_0" pos="-0.0233 0.0136 0.00335" euler="0.0 0.0 0.0" contype="0" conaffinity="0" group="1" density="0" rgba="0.72 0.76 0.78 1" /><geom name="ldjy_left_finger4_link1_l_lower_body" rgba="0.55 0.7 0.9 0" friction="0.7 0.005 0.0001" solref="0.02 1.5" solimp="0.9 0.95 0.001 0.5 2.0" priority="1" condim="3" type="capsule" fromto="0.003267485672213381 8.358832052791327e-05 -0.009744681730066118 0.023885122387786617 0.0004408267940720868 0.007181010764066119" size="0.007121991075" contype="3" conaffinity="3" /><geom name="ldjy_left_finger4_link1_l_upper_body" rgba="0.55 0.7 0.9 0" friction="0.7 0.005 0.0001" solref="0.02 1.5" solimp="0.9 0.95 0.001 0.5 2.0" priority="1" condim="3" type="capsule" fromto="0.023614543657127906 3.906772957551863e-05 0.02177814756457811 0.026287592602872095 -0.00015601330679551864 0.04060698019542189" size="0.007839284308" contype="3" conaffinity="3" /><body name="ldjy_left_finger4_link2" pos="0.02339748876 -0.004742100776 0.0434" euler="0.0 0.0 0.0"><inertial pos="0.004459969685 0.005238464661 0.01000947843" mass="0.00822987786" fullinertia="7.197019922e-07 7.920318456e-07 4.435674176e-07 1.413809552e-09 1.587952065e-07 -3.11691908e-09" /><joint name="ldjy_left_finger4_joint2" axis="-0.01960941425 0.999807717 0.0" range="-0.3665191429 0.3665191429" actuatorfrcrange="-0.6441 0.6441" armature="0.0005" /><geom name="ldjy_left_finger4_link2_visual_0_geom" type="mesh" mesh="ldjy_left_finger4_link2_visual_0" pos="-0.04669748876 0.01834210078 -0.04005" euler="0.0 0.0 0.0" contype="0" conaffinity="0" group="1" density="0" rgba="0.72 0.76 0.78 1" /><geom name="ldjy_left_finger4_link2_capsule_body" rgba="0.55 0.7 0.9 0" friction="0.7 0.005 0.0001" solref="0.02 1.5" solimp="0.9 0.95 0.001 0.5 2.0" priority="1" condim="3" type="capsule" fromto="0.000379027462771523 0.006169885515716631 0.0030490395542072998 0.008689386565228477 0.004545450360283369 0.0169117013837927" size="0.007571680637" contype="3" conaffinity="3" /><body name="ldjy_left_finger4_link3" pos="0.004335573131 0.005236024848 0.02215472522" euler="0.0 0.0 0.0"><inertial pos="0.01088390563 -0.0004228266351 0.01144090115" mass="0.01150473762" fullinertia="1.659605194e-06 1.967140451e-06 7.455130385e-07 -3.218862917e-08 5.280480303e-07 7.332310364e-08" /><joint name="ldjy_left_finger4_joint3" axis="-0.9097776159 -0.01784363717 0.4147123029" range="-1.549 0.4768" actuatorfrcrange="-0.2384 0.2384" armature="0.0005" /><geom name="ldjy_left_finger4_link3_visual_0_geom" type="mesh" mesh="ldjy_left_finger4_link3_visual_0" pos="-0.05103306189 0.01310607593 -0.06220472522" euler="0.0 0.0 0.0" contype="0" conaffinity="0" group="1" density="0" rgba="0.72 0.76 0.78 1" /><geom name="ldjy_left_finger4_link3_capsule_body" rgba="0.55 0.7 0.9 0" friction="0.7 0.005 0.0001" solref="0.02 1.5" solimp="0.9 0.95 0.001 0.5 2.0" priority="1" condim="3" type="capsule" fromto="0.004436865187758943 0.0024805852068378463 0.00010139237783623675 0.01758502777224106 -0.0011909087612378463 0.024252638022163764" size="0.007647541322" contype="3" conaffinity="3" /><body name="ldjy_left_finger4_link4" pos="0.01349028053 -0.001501340608 0.02952978679" euler="0.0 0.0 0.0"><inertial pos="0.01079974174 0.000441005848 0.01129328197" mass="0.01143731415" fullinertia="1.624273381e-06 1.917800986e-06 7.272121268e-07 2.463588289e-09 5.160034856e-07 -3.052853862e-09" /><joint name="ldjy_left_finger4_joint4" axis="-0.9097776159 -0.01784363717 0.4147123029" range="-1.5735 0.4683" actuatorfrcrange="-0.1866 0.1866" armature="0.0005" /><geom name="ldjy_left_finger4_link4_visual_0_geom" type="mesh" mesh="ldjy_left_finger4_link4_visual_0" pos="-0.06452334242 0.01460741654 -0.091734512" euler="0.0 0.0 0.0" contype="0" conaffinity="0" group="1" density="0" rgba="0.72 0.76 0.78 1" /><geom name="ldjy_left_finger4_link4_collision" rgba="0.55 0.7 0.9 0" friction="0.7 0.005 0.0001" solref="0.02 1.5" solimp="0.9 0.95 0.001 0.5 2.0" priority="1" condim="3" type="mesh" mesh="ldjy_left_finger4_link4_collision" pos="-0.06452334242 0.01460741654 -0.091734512" euler="0.0 0.0 0.0" contype="3" conaffinity="3" /><site name="ldjy_left_finger4_link4_tip" pos="0 0 0.025" group="4" size="0.003" /></body></body></body></body></body></body>
                        </body>
                      </body>
                    </body>
                  </body>
                </body>
              </body>
            </body>
          </body>
          <body name="right_link0_base" pos="0.075 0.14555 0.025" quat="0.499998 0.5 0.500002 0.5">
            <inertial pos="-0.000217889 0 -0.00249049" quat="0.999048 0 0.0436194 0" mass="9.81748e-05" diaginertia="3.57929e-10 3.57929e-10 3.06796e-10" />
            <geom type="mesh" contype="3" conaffinity="3" group="1" density="0" rgba="0.79216 0.81961 0.93333 1" mesh="packages_lift_slide_description_meshes_right_link0_base" />
            <body name="openarmx_right_link0">
              <inertial pos="0.000319 0.00067 0.029184" quat="0.497862 0.511796 -0.475431 0.513968" mass="1.77268" diaginertia="0.00341526 0.00246403 0.00195971" />
              <geom name="openarmx_right_link0_visual_part0" type="mesh" contype="3" conaffinity="3" group="1" density="0" rgba="0.5 0.5 0.55 1" mesh="packages_openarmx_description_meshes_arm_v10_visual_link0_part0" />
              <geom name="openarmx_right_link0_visual_part1" type="mesh" contype="3" conaffinity="3" group="1" density="0" rgba="0.92 0.92 0.95 1" mesh="packages_openarmx_description_meshes_arm_v10_visual_link0_part1" />
              <body name="openarmx_right_link1" pos="0 0 0.058">
                <inertial pos="0.004452 -2.5e-05 0.073323" quat="0.999503 0.000644393 -0.0315003 0.00114209" mass="1.68876" diaginertia="0.00346919 0.002551 0.00190982" />
                <joint name="openarmx_right_joint1" pos="0 0 0" axis="0 0 1" range="-1.25 3" actuatorfrcrange="-120 120" damping="18.0" armature="0.03" frictionloss="0.15" />
                <geom name="openarmx_right_link1_visual_part0" type="mesh" contype="3" conaffinity="3" group="1" density="0" rgba="0.5 0.5 0.55 1" mesh="packages_openarmx_description_meshes_arm_v10_visual_link1_part0" />
                <geom name="openarmx_right_link1_visual_part1" type="mesh" contype="3" conaffinity="3" group="1" density="0" rgba="0.92 0.92 0.95 1" mesh="packages_openarmx_description_meshes_arm_v10_visual_link1_part1" />
                <body name="openarmx_right_link2" pos="-0.0205 0 0.081" quat="0.707105 0.707108 0 0">
                  <inertial pos="-0.003787 0.000221 0.04901" quat="0.986716 -0.00145381 -0.161354 -0.0188355" mass="0.396704" diaginertia="0.000891196 0.000821946 0.000327857" />
                  <joint name="openarmx_right_joint2" pos="0 0 0" axis="-1 0 0" range="-0.129204 3.2708" actuatorfrcrange="-120 120" damping="18.0" armature="0.03" frictionloss="0.15" />
                  <geom name="openarmx_right_link2_visual_part0" type="mesh" contype="3" conaffinity="3" group="1" density="0" rgba="0.5 0.5 0.55 1" mesh="packages_openarmx_description_meshes_arm_v10_visual_link2_part0" />
                  <geom name="openarmx_right_link2_visual_part1" type="mesh" contype="3" conaffinity="3" group="1" density="0" rgba="0.15 0.65 0.7 1" mesh="packages_openarmx_description_meshes_arm_v10_visual_link2_part1" />
                  <body name="openarmx_right_link3" pos="0.02 0 0.099">
                    <inertial pos="-0.000828 0.000236 0.083336" quat="0.946133 0.00530809 0.00424656 -0.323707" mass="2.49278" diaginertia="0.0103641 0.0103322 0.00300164" />
                    <joint name="openarmx_right_joint3" pos="0 0 0" axis="0 0 1" range="-1.57 1.57" actuatorfrcrange="-60 60" damping="18.0" armature="0.03" frictionloss="0.15" />
                    <geom name="openarmx_right_link3_visual_part0" type="mesh" contype="3" conaffinity="3" group="1" density="0" rgba="0.5 0.5 0.55 1" mesh="packages_openarmx_description_meshes_arm_v10_visual_link3_part0" />
                    <geom name="openarmx_right_link3_visual_part1" type="mesh" contype="3" conaffinity="3" group="1" density="0" rgba="0.92 0.92 0.95 1" mesh="packages_openarmx_description_meshes_arm_v10_visual_link3_part1" />
                    <body name="openarmx_right_link4" pos="0 0.031002 0.14181">
                      <inertial pos="-0.002591 -0.030135 0.07147" quat="0.999683 -0.0233783 -0.00922341 -0.00115143" mass="0.779755" diaginertia="0.00201543 0.00162187 0.000765704" />
                      <joint name="openarmx_right_joint4" pos="0 0 0" axis="0 1 0" range="0 1.8" actuatorfrcrange="-60 60" damping="18.0" armature="0.03" frictionloss="0.15" />
                      <geom name="openarmx_right_link4_visual_part0" type="mesh" contype="3" conaffinity="3" group="1" density="0" rgba="0.5 0.5 0.55 1" mesh="packages_openarmx_description_meshes_arm_v10_visual_link4_part0" />
                      <geom name="openarmx_right_link4_visual_part1" type="mesh" contype="3" conaffinity="3" group="1" density="0" rgba="0.15 0.65 0.7 1" mesh="packages_openarmx_description_meshes_arm_v10_visual_link4_part1" />
                      <body name="openarmx_right_link4_ext">
                        <inertial pos="0 0 0" mass="0.5" diaginertia="0.002 0.002 0.002" />
                      </body>
                      <body name="openarmx_right_link5" pos="0 -0.0309 0.126">
                        <inertial pos="-0.002256 0.000305 0.0533" quat="0.714458 -0.0122081 -0.0110113 0.699485" mass="0.687255" diaginertia="0.00106611 0.000831256 0.000495637" />
                        <joint name="openarmx_right_joint5" pos="0 0 0" axis="0 0 1" range="-1.5 1.5" actuatorfrcrange="-14 14" damping="18.0" armature="0.03" frictionloss="0.15" />
                        <geom name="openarmx_right_link5_visual_part0" type="mesh" contype="3" conaffinity="3" group="1" density="0" rgba="0.5 0.5 0.55 1" mesh="packages_openarmx_description_meshes_arm_v10_visual_link5_part0" />
                        <geom name="openarmx_right_link5_visual_part1" type="mesh" contype="3" conaffinity="3" group="1" density="0" rgba="0.92 0.92 0.95 1" mesh="packages_openarmx_description_meshes_arm_v10_visual_link5_part1" />
                        <body name="openarmx_right_link6" pos="0.037426 0 0.131">
                          <inertial pos="-0.03564 -0.005114 -0.003582" quat="0.945265 0.038546 0.187709 -0.26411" mass="0.384836" diaginertia="0.000317632 0.000265263 0.000212105" />
                          <joint name="openarmx_right_joint6" pos="0 0 0" axis="1 0 0" range="-0.75 0.75" actuatorfrcrange="-14 14" damping="18.0" armature="0.03" frictionloss="0.15" />
                          <geom name="openarmx_right_link6_visual_part0" type="mesh" contype="3" conaffinity="3" group="1" density="0" rgba="0.5 0.5 0.55 1" mesh="packages_openarmx_description_meshes_arm_v10_visual_link6_part0" />
                          <geom name="openarmx_right_link6_visual_part1" type="mesh" contype="3" conaffinity="3" group="1" density="0" rgba="0.8 0.8 0.82 1" mesh="packages_openarmx_description_meshes_arm_v10_visual_link6_part1" />
                          <body name="openarmx_right_link7" pos="-0.0375 0 0">
                            <inertial pos="-3e-06 0.002128 0.091961" quat="0.98918 -0.138774 0.00159491 -0.0475613" mass="0.624972" diaginertia="0.00160275 0.00108708 0.000759171" />
                            <joint name="openarmx_right_joint7" pos="0 0 0" axis="0 1 0" range="-1.4 1.4" actuatorfrcrange="-14 14" damping="18.0" armature="0.03" frictionloss="0.15" />
                            <geom name="openarmx_right_link7_visual_part0" type="mesh" contype="3" conaffinity="3" group="1" density="0" rgba="0.5 0.5 0.55 1" mesh="packages_openarmx_description_meshes_arm_v10_visual_link7_part0" />
                            <body name="ldjy_right_palm" pos="0 0 0.0895"><inertial pos="-0.002100989686 -0.001688548819 0.01727660861" mass="0.200010115" fullinertia="0.0001400575215 0.0001960126545 9.28994431e-05 -3.300850571e-06 -1.303765852e-05 -1.969913402e-06" /><geom name="ldjy_right_palm_visual_0_geom" type="mesh" mesh="ldjy_right_palm_visual_0" pos="0 0 0" euler="0 0 0" contype="0" conaffinity="0" group="1" density="0" rgba="0.72 0.76 0.78 1" /><geom name="ldjy_right_palm_collision" rgba="0.55 0.7 0.9 0" friction="0.7 0.005 0.0001" solref="0.02 1.5" solimp="0.9 0.95 0.001 0.5 2.0" priority="1" condim="3" type="mesh" mesh="ldjy_right_palm_collision" pos="0 0 0" euler="0 0 0" contype="3" conaffinity="3" /><body name="ldjy_right_finger1_link1" pos="0.0233 -0.00295 0.0495" euler="0 0 0"><inertial pos="0.002552140053 -0.0002949597412 0.01500495062" mass="0.0150541391" fullinertia="2.363453405e-06 1.594218588e-06 1.446291259e-06 4.524555776e-08 -1.6055183e-07 2.654450928e-07" /><joint name="ldjy_right_finger1_joint1" axis="0 1 0" range="-0.37 0.37" actuatorfrcrange="-0.1822 0.1822" armature="0.0005" /><geom name="ldjy_right_finger1_link1_visual_0_geom" type="mesh" mesh="ldjy_right_finger1_link1_visual_0" pos="-0.0233 0.00295 -0.0495" euler="0 0 0" contype="0" conaffinity="0" group="1" density="0" rgba="0.72 0.76 0.78 1" /><body name="ldjy_right_finger1_link2" pos="-0.0009621741619 -0.0117 0.02207380139" euler="0 0 0"><inertial pos="0.007529199598 -0.000357884412 0.01653624902" mass="0.01150473762" fullinertia="1.861515854e-06 1.970814569e-06 5.399282613e-07 5.501808106e-09 -2.315560267e-07 3.19692724e-08" /><joint name="ldjy_right_finger1_joint2" axis="0.9858405936 0 -0.1676851933" range="0.0 1.5604" actuatorfrcrange="-0.6188 0.6188" armature="0.0005" /><geom name="ldjy_right_finger1_link2_visual_0_geom" type="mesh" mesh="ldjy_right_finger1_link2_visual_0" pos="-0.02233782584 0.01465 -0.07157380139" euler="0 0 0" contype="0" conaffinity="0" group="1" density="0" rgba="0.72 0.76 0.78 1" /><geom name="ldjy_right_finger1_link2_capsule_body" rgba="0.55 0.7 0.9 0" friction="0.7 0.005 0.0001" solref="0.02 1.5" solimp="0.9 0.95 0.001 0.5 2.0" priority="1" condim="3" type="capsule" fromto="0.005864106671017739 -3.315357052071993e-05 0.0021571807155113445 0.008643711232982262 0.0015634059923207199 0.029713695544488654" size="0.007647541322" contype="3" conaffinity="3" /><body name="ldjy_right_finger1_link3" pos="0.005447258779 -0.0009862714603 0.03202506269" euler="0 0 0"><inertial pos="0.007529199598 -0.000357884412 0.01653624902" mass="0.01150473762" fullinertia="1.861515854e-06 1.970814569e-06 5.399282613e-07 5.501808106e-09 -2.315560267e-07 3.19692724e-08" /><joint name="ldjy_right_finger1_joint3" axis="0.9858405936 0 -0.1676851933" range="-0.4777 1.5485" actuatorfrcrange="-0.2251 0.2251" armature="0.0005" /><geom name="ldjy_right_finger1_link3_visual_0_geom" type="mesh" mesh="ldjy_right_finger1_link3_visual_0" pos="-0.02778508462 0.01563627146 -0.1035988641" euler="0 0 0" contype="0" conaffinity="0" group="1" density="0" rgba="0.72 0.76 0.78 1" /><geom name="ldjy_right_finger1_link3_capsule_body" rgba="0.55 0.7 0.9 0" friction="0.7 0.005 0.0001" solref="0.02 1.5" solimp="0.9 0.95 0.001 0.5 2.0" priority="1" condim="3" type="capsule" fromto="0.005864106671017739 -3.315357052071993e-05 0.0021571807155113445 0.008643711232982262 0.0015634059923207199 0.029713695544488654" size="0.007647541322" contype="3" conaffinity="3" /><body name="ldjy_right_finger1_link4" pos="0.005447258779 -0.0009862714603 0.03202506269" euler="0 0 0"><inertial pos="0.006403231499 -0.0003803927588 0.009915921237" mass="0.007585938385" fullinertia="6.792669082e-07 7.730027699e-07 3.194495902e-07 2.470647307e-09 -6.30049988e-08 1.451842468e-08" /><joint name="ldjy_right_finger1_joint4" axis="0.9858405936 0 -0.1676851933" range="-0.4683 1.5753" actuatorfrcrange="-0.217 0.217" armature="0.0005" /><geom name="ldjy_right_finger1_link4_visual_0_geom" type="mesh" mesh="ldjy_right_finger1_link4_visual_0" pos="-0.0332323434 0.01662254292 -0.1356239268" euler="0 0 0" contype="0" conaffinity="0" group="1" density="0" rgba="0.72 0.76 0.78 1" /><geom name="ldjy_right_finger1_link4_collision" rgba="0.55 0.7 0.9 0" friction="0.7 0.005 0.0001" solref="0.02 1.5" solimp="0.9 0.95 0.001 0.5 2.0" priority="1" condim="3" type="mesh" mesh="ldjy_right_finger1_link4_collision" pos="-0.0332323434 0.01662254292 -0.1356239268" euler="0 0 0" contype="3" conaffinity="3" /><site name="ldjy_right_finger1_link4_tip" pos="0 0 0.025" group="4" size="0.003" /></body></body></body></body><body name="ldjy_right_finger2_link1" pos="0 -0.00295 0.0545" euler="0 0 0"><inertial pos="-0.0004261161081 -0.0002949597412 0.01521447952" mass="0.0150541391" fullinertia="2.389979737e-06 1.594218588e-06 1.419764927e-06 -7.443150302e-09 2.7281791e-08 2.691706844e-07" /><joint name="ldjy_right_finger2_joint1" axis="0 1 0" range="-0.37 0.37" actuatorfrcrange="-0.1827 0.1827" armature="0.0005" /><geom name="ldjy_right_finger2_link1_visual_0_geom" type="mesh" mesh="ldjy_right_finger2_link1_visual_0" pos="0 0.00295 -0.0545" euler="0 0 0" contype="0" conaffinity="0" group="1" density="0" rgba="0.72 0.76 0.78 1" /><body name="ldjy_right_finger2_link2" pos="-0.005252746989 -0.0117 0.0214612939" euler="0 0 0"><inertial pos="0.00415623752 -0.0003144280118 0.01768873326" mass="0.01150473762" fullinertia="1.899818734e-06 1.970966079e-06 5.014738708e-07 -7.431753573e-10 3.91233677e-08 2.879175918e-08" /><joint name="ldjy_right_finger2_joint2" axis="0.9996082196 0 0.02798941517" range="0.0 1.5516" actuatorfrcrange="-0.6494 0.6494" armature="0.0005" /><geom name="ldjy_right_finger2_link2_visual_0_geom" type="mesh" mesh="ldjy_right_finger2_link2_visual_0" pos="0.005252746989 0.01465 -0.0759612939" euler="0 0 0" contype="0" conaffinity="0" group="1" density="0" rgba="0.72 0.76 0.78 1" /><geom name="ldjy_right_finger2_link2_capsule_body" rgba="0.55 0.7 0.9 0" friction="0.7 0.005 0.0001" solref="0.02 1.5" solimp="0.9 0.95 0.001 0.5 2.0" priority="1" condim="3" type="capsule" fromto="0.005330175945664866 -2.5459360278297892e-05 0.0032604985870525113 0.0026770375963351334 0.0016394585514782978 0.03082543317294749" size="0.007647541322" contype="3" conaffinity="3" /><body name="ldjy_right_finger2_link3" pos="-0.0009093025454 -0.0009058997649 0.03247464418" euler="0 0 0"><inertial pos="0.00415623752 -0.0003144280118 0.01768873326" mass="0.01150473762" fullinertia="1.899818734e-06 1.970966079e-06 5.014738708e-07 -7.431753573e-10 3.91233677e-08 2.879175918e-08" /><joint name="ldjy_right_finger2_joint3" axis="0.9996082196 0 0.02798941517" range="-0.4739 1.5512" actuatorfrcrange="-0.2078 0.2078" armature="0.0005" /><geom name="ldjy_right_finger2_link3_visual_0_geom" type="mesh" mesh="ldjy_right_finger2_link3_visual_0" pos="0.006162049534 0.01555589976 -0.1084359381" euler="0 0 0" contype="0" conaffinity="0" group="1" density="0" rgba="0.72 0.76 0.78 1" /><geom name="ldjy_right_finger2_link3_capsule_body" rgba="0.55 0.7 0.9 0" friction="0.7 0.005 0.0001" solref="0.02 1.5" solimp="0.9 0.95 0.001 0.5 2.0" priority="1" condim="3" type="capsule" fromto="0.005330175945664866 -2.5459360278297892e-05 0.0032604985870525113 0.0026770375963351334 0.0016394585514782978 0.03082543317294749" size="0.007647541322" contype="3" conaffinity="3" /><body name="ldjy_right_finger2_link4" pos="-0.0009093025454 -0.0009058997649 0.03247464418" euler="0 0 0"><inertial pos="0.004344301239 -0.0003535503261 0.01097604734" mass="0.007585938385" fullinertia="6.896804327e-07 7.730727985e-07 3.08966037e-07 -3.788620486e-10 1.068844763e-08 1.357307458e-08" /><joint name="ldjy_right_finger2_joint4" axis="0.9996082196 0 0.02798941517" range="-0.4684 1.5745" actuatorfrcrange="-0.2018 0.2018" armature="0.0005" /><geom name="ldjy_right_finger2_link4_visual_0_geom" type="mesh" mesh="ldjy_right_finger2_link4_visual_0" pos="0.00707135208 0.01646179953 -0.1409105823" euler="0 0 0" contype="0" conaffinity="0" group="1" density="0" rgba="0.72 0.76 0.78 1" /><geom name="ldjy_right_finger2_link4_collision" rgba="0.55 0.7 0.9 0" friction="0.7 0.005 0.0001" solref="0.02 1.5" solimp="0.9 0.95 0.001 0.5 2.0" priority="1" condim="3" type="mesh" mesh="ldjy_right_finger2_link4_collision" pos="0.00707135208 0.01646179953 -0.1409105823" euler="0 0 0" contype="3" conaffinity="3" /><site name="ldjy_right_finger2_link4_tip" pos="0 0 0.025" group="4" size="0.003" /></body></body></body></body><body name="ldjy_right_finger3_link1" pos="-0.0233 -0.00295 0.0445" euler="0 0 0"><inertial pos="-0.002586982248 -0.0002951945879 0.01499906285" mass="0.01505382492" fullinertia="2.362593935e-06 1.5942064e-06 1.447056064e-06 -4.568916311e-08 1.628553627e-07 2.653544912e-07" /><joint name="ldjy_right_finger3_joint1" axis="0 1 0" range="-0.37 0.37" actuatorfrcrange="-0.1832 0.1832" armature="0.0005" /><geom name="ldjy_right_finger3_link1_visual_0_geom" type="mesh" mesh="ldjy_right_finger3_link1_visual_0" pos="0.0233 0.00295 -0.0445" euler="0 0 0" contype="0" conaffinity="0" group="1" density="0" rgba="0.72 0.76 0.78 1" /><body name="ldjy_right_finger3_link2" pos="-0.008253592832 -0.0117 0.02049528464" euler="0 0 0"><inertial pos="0.001596931475 0.0004290719444 0.01809779453" mass="0.01150473762" fullinertia="1.860480436e-06 1.970768424e-06 5.410098243e-07 5.747964394e-09 2.344859304e-07 -3.297133497e-08" /><joint name="ldjy_right_finger3_joint2" axis="0.98544992 0 0.1699660413" range="0.0 1.5585" actuatorfrcrange="-0.6389 0.6389" armature="0.0005" /><geom name="ldjy_right_finger3_link2_visual_0_geom" type="mesh" mesh="ldjy_right_finger3_link2_visual_0" pos="0.03155359283 0.01465 -0.06499528464" euler="0 0 0" contype="0" conaffinity="0" group="1" density="0" rgba="0.72 0.76 0.78 1" /><geom name="ldjy_right_finger3_link2_capsule_body" rgba="0.55 0.7 0.9 0" friction="0.7 0.005 0.0001" solref="0.02 1.5" solimp="0.9 0.95 0.001 0.5 2.0" priority="1" condim="3" type="capsule" fromto="0.004812185541144998 0.00010615303547150366 0.003984203394555937 -0.001720734881144998 0.0029385739125284962 0.030797167725444066" size="0.007647541322" contype="3" conaffinity="3" /><body name="ldjy_right_finger3_link3" pos="-0.005523319931 0.0004694951803 0.0320237804" euler="0 0 0"><inertial pos="0.001596931475 0.0004290719444 0.01809779453" mass="0.01150473762" fullinertia="1.860480436e-06 1.970768424e-06 5.410098243e-07 5.747964394e-09 2.344859304e-07 -3.297133497e-08" /><joint name="ldjy_right_finger3_joint3" axis="0.98544992 0 0.1699660413" range="-0.4765 1.5487" actuatorfrcrange="-0.2249 0.2249" armature="0.0005" /><geom name="ldjy_right_finger3_link3_visual_0_geom" type="mesh" mesh="ldjy_right_finger3_link3_visual_0" pos="0.03707691276 0.01418050482 -0.09701906504" euler="0 0 0" contype="0" conaffinity="0" group="1" density="0" rgba="0.72 0.76 0.78 1" /><geom name="ldjy_right_finger3_link3_capsule_body" rgba="0.55 0.7 0.9 0" friction="0.7 0.005 0.0001" solref="0.02 1.5" solimp="0.9 0.95 0.001 0.5 2.0" priority="1" condim="3" type="capsule" fromto="0.004812185541144998 0.00010615303547150366 0.003984203394555937 -0.001720734881144998 0.0029385739125284962 0.030797167725444066" size="0.007647541322" contype="3" conaffinity="3" /><body name="ldjy_right_finger3_link4" pos="-0.005523319931 0.0004694951803 0.0320237804" euler="0 0 0"><inertial pos="0.002737108666 0.0001058506004 0.01148775862" mass="0.007585938385" fullinertia="6.789489057e-07 7.733894034e-07 3.193809591e-07 1.039186966e-09 6.393916346e-08 -6.013182828e-09" /><joint name="ldjy_right_finger3_joint4" axis="0.98544992 0 0.1699660413" range="-0.4777 1.5634" actuatorfrcrange="-0.2044 0.2044" armature="0.0005" /><geom name="ldjy_right_finger3_link4_visual_0_geom" type="mesh" mesh="ldjy_right_finger3_link4_visual_0" pos="0.04260023269 0.01371100964 -0.1290428454" euler="0 0 0" contype="0" conaffinity="0" group="1" density="0" rgba="0.72 0.76 0.78 1" /><geom name="ldjy_right_finger3_link4_collision" rgba="0.55 0.7 0.9 0" friction="0.7 0.005 0.0001" solref="0.02 1.5" solimp="0.9 0.95 0.001 0.5 2.0" priority="1" condim="3" type="mesh" mesh="ldjy_right_finger3_link4_collision" pos="0.04260023269 0.01371100964 -0.1290428454" euler="0 0 0" contype="3" conaffinity="3" /><site name="ldjy_right_finger3_link4_tip" pos="0 0 0.025" group="4" size="0.003" /></body></body></body></body><body name="ldjy_right_thumb_link1" pos="0.0233 -0.00295 -0.0084" euler="0 0 0"><inertial pos="-0.0008689005969 -0.003804801439 -0.001284419564" mass="0.009231749795" fullinertia="1.060881976e-06 4.170231492e-07 1.055511507e-06 5.894022963e-08 -1.130080766e-08 7.482297275e-08" /><joint name="ldjy_right_thumb_joint1" axis="0 1 0" range="-1.5707963268 0.9250245036" actuatorfrcrange="-0.4259 0.4259" armature="0.0005" /><geom name="ldjy_right_thumb_link1_visual_0_geom" type="mesh" mesh="ldjy_right_thumb_link1_visual_0" pos="-0.0233 0.00295 0.0084" euler="0 0 0" contype="0" conaffinity="0" group="1" density="0" rgba="0.72 0.76 0.78 1" /><body name="ldjy_right_thumb_link2" pos="0.002608560701 -0.0166 -0.001938533227" euler="0 0 0"><inertial pos="0.008159715317 -0.000678399895 0.01634525189" mass="0.01361136422" fullinertia="2.067853631e-06 2.82551883e-06 1.405796287e-06 3.320375324e-08 -1.072979093e-06 4.507555487e-08" /><joint name="ldjy_right_thumb_joint2" axis="0.8026340617 0 -0.5964717621" range="0.0 1.6033" actuatorfrcrange="-0.4452 0.4452" armature="0.0005" /><geom name="ldjy_right_thumb_link2_visual_0_geom" type="mesh" mesh="ldjy_right_thumb_link2_visual_0" pos="-0.0259085607 0.01955 0.01033853323" euler="0 0 0" contype="0" conaffinity="0" group="1" density="0" rgba="0.72 0.76 0.78 1" /><geom name="ldjy_right_thumb_link2_capsule_body" rgba="0.55 0.7 0.9 0" friction="0.7 0.005 0.0001" solref="0.02 1.5" solimp="0.9 0.95 0.001 0.5 2.0" priority="1" condim="3" type="capsule" fromto="-0.0012674068890160713 -0.003368696520349595 0.004496985802651246 0.01835717003901607 0.0006926715583495948 0.030009979377348756" size="0.007912057707" contype="3" conaffinity="3" /><body name="ldjy_right_thumb_link3" pos="0.02024684923 -0.006366194767 0.03269360274" euler="0 0 0"><inertial pos="0.008158821575 0.004675488222 0.01269274767" mass="0.01150473762" fullinertia="1.569176561e-06 1.899515634e-06 9.035664892e-07 2.301654039e-08 -6.555138346e-07 3.775871711e-08" /><joint name="ldjy_right_thumb_joint3" axis="0.01888221858 0.9994988069 0.02540859896" range="-1.5707963268 0.0" actuatorfrcrange="-0.1888 0.1888" armature="0.0005" /><geom name="ldjy_right_thumb_link3_visual_0_geom" type="mesh" mesh="ldjy_right_thumb_link3_visual_0" pos="-0.04615540993 0.02591619477 -0.02235506952" euler="0 0 0" contype="0" conaffinity="0" group="1" density="0" rgba="0.72 0.76 0.78 1" /><geom name="ldjy_right_thumb_link3_capsule_body" rgba="0.55 0.7 0.9 0" friction="0.7 0.005 0.0001" solref="0.02 1.5" solimp="0.9 0.95 0.001 0.5 2.0" priority="1" condim="3" type="capsule" fromto="0.0031561761038444896 0.003973012588344725 0.0003210599958376435 0.01573803159815551 0.0049888195556552755 0.025025346304162355" size="0.007647541322" contype="3" conaffinity="3" /><body name="ldjy_right_thumb_link4" pos="0.01722211724 -0.001025525643 0.02754263922" euler="0 0 0"><inertial pos="0.006524915211 0.00468820306 0.0134094626" mass="0.01143731998" fullinertia="1.670475431e-06 1.858111984e-06 7.407043888e-07 1.736442301e-08 -5.39596932e-07 3.864265835e-08" /><joint name="ldjy_right_thumb_joint4" axis="0.01888221858 0.9994988069 0.02540859896" range="-1.5707963268 0.0" actuatorfrcrange="-0.1468 0.1468" armature="0.0005" /><geom name="ldjy_right_thumb_link4_visual_0_geom" type="mesh" mesh="ldjy_right_thumb_link4_visual_0" pos="-0.06337752717 0.02694172041 -0.04989770873" euler="0 0 0" contype="0" conaffinity="0" group="1" density="0" rgba="0.72 0.76 0.78 1" /><geom name="ldjy_right_thumb_link4_collision" rgba="0.55 0.7 0.9 0" friction="0.7 0.005 0.0001" solref="0.02 1.5" solimp="0.9 0.95 0.001 0.5 2.0" priority="1" condim="3" type="mesh" mesh="ldjy_right_thumb_link4_collision" pos="-0.06337752717 0.02694172041 -0.04989770873" euler="0 0 0" contype="3" conaffinity="3" /><site name="ldjy_right_thumb_link4_tip" pos="0 0 0.025" group="4" size="0.003" /></body></body></body></body><body name="ldjy_right_finger4_link1" pos="-0.0233 -0.0136 -0.00335" euler="0 0 0"><inertial pos="-0.01635947532 0.0003022085593 0.01584337601" mass="0.02634208642" fullinertia="8.041665618e-06 9.603291865e-06 2.681265216e-06 2.877050045e-08 2.017341866e-06 -3.162593458e-08" /><joint name="ldjy_right_finger4_joint1" axis="0 0 1" range="0.0 1.0471975511965976" actuatorfrcrange="-0.1798 0.1798" armature="0.0005" /><geom name="ldjy_right_finger4_link1_visual_0_geom" type="mesh" mesh="ldjy_right_finger4_link1_visual_0" pos="0.0233 0.0136 0.00335" euler="0 0 0" contype="0" conaffinity="0" group="1" density="0" rgba="0.72 0.76 0.78 1" /><geom name="ldjy_right_finger4_link1_l_lower_body" rgba="0.55 0.7 0.9 0" friction="0.7 0.005 0.0001" solref="0.02 1.5" solimp="0.9 0.95 0.001 0.5 2.0" priority="1" condim="3" type="capsule" fromto="-0.003267485672213381 8.358832052791327e-05 -0.009744681730066118 -0.023885122387786617 0.0004408267940720868 0.007181010764066119" size="0.007121991075" contype="3" conaffinity="3" /><geom name="ldjy_right_finger4_link1_l_upper_body" rgba="0.55 0.7 0.9 0" friction="0.7 0.005 0.0001" solref="0.02 1.5" solimp="0.9 0.95 0.001 0.5 2.0" priority="1" condim="3" type="capsule" fromto="-0.023614543657127906 3.906772957551863e-05 0.02177814756457811 -0.026287592602872095 -0.00015601330679551864 0.04060698019542189" size="0.007839284308" contype="3" conaffinity="3" /><body name="ldjy_right_finger4_link2" pos="-0.02339748876 -0.004742100776 0.0434" euler="0 0 0"><inertial pos="-0.004459969685 0.005238464661 0.01000947843" mass="0.00822987786" fullinertia="7.197019922e-07 7.920318456e-07 4.435674176e-07 1.413809552e-09 1.587952065e-07 -3.11691908e-09" /><joint name="ldjy_right_finger4_joint2" axis="0.01960941425 0.999807717 0" range="-0.3665191429 0.3665191429" actuatorfrcrange="-0.6441 0.6441" armature="0.0005" /><geom name="ldjy_right_finger4_link2_visual_0_geom" type="mesh" mesh="ldjy_right_finger4_link2_visual_0" pos="0.04669748876 0.01834210078 -0.04005" euler="0 0 0" contype="0" conaffinity="0" group="1" density="0" rgba="0.72 0.76 0.78 1" /><geom name="ldjy_right_finger4_link2_capsule_body" rgba="0.55 0.7 0.9 0" friction="0.7 0.005 0.0001" solref="0.02 1.5" solimp="0.9 0.95 0.001 0.5 2.0" priority="1" condim="3" type="capsule" fromto="-0.000379027462771523 0.006169885515716631 0.0030490395542072998 -0.008689386565228477 0.004545450360283369 0.0169117013837927" size="0.007571680637" contype="3" conaffinity="3" /><body name="ldjy_right_finger4_link3" pos="-0.004335573131 0.005236024848 0.02215472522" euler="0 0 0"><inertial pos="-0.01088390563 -0.0004228266351 0.01144090115" mass="0.01150473762" fullinertia="1.659605194e-06 1.967140451e-06 7.455130385e-07 -3.218862917e-08 5.280480303e-07 7.332310364e-08" /><joint name="ldjy_right_finger4_joint3" axis="0.9097776159 -0.01784363717 0.4147123029" range="-0.4768 1.549" actuatorfrcrange="-0.2384 0.2384" armature="0.0005" /><geom name="ldjy_right_finger4_link3_visual_0_geom" type="mesh" mesh="ldjy_right_finger4_link3_visual_0" pos="0.05103306189 0.01310607593 -0.06220472522" euler="0 0 0" contype="0" conaffinity="0" group="1" density="0" rgba="0.72 0.76 0.78 1" /><geom name="ldjy_right_finger4_link3_capsule_body" rgba="0.55 0.7 0.9 0" friction="0.7 0.005 0.0001" solref="0.02 1.5" solimp="0.9 0.95 0.001 0.5 2.0" priority="1" condim="3" type="capsule" fromto="-0.004436865187758943 0.0024805852068378463 0.00010139237783623675 -0.01758502777224106 -0.0011909087612378463 0.024252638022163764" size="0.007647541322" contype="3" conaffinity="3" /><body name="ldjy_right_finger4_link4" pos="-0.01349028053 -0.001501340608 0.02952978679" euler="0 0 0"><inertial pos="-0.01079974174 0.000441005848 0.01129328197" mass="0.01143731415" fullinertia="1.624273381e-06 1.917800986e-06 7.272121268e-07 2.463588289e-09 5.160034856e-07 -3.052853862e-09" /><joint name="ldjy_right_finger4_joint4" axis="0.9097776159 -0.01784363717 0.4147123029" range="-0.4683 1.5735" actuatorfrcrange="-0.1866 0.1866" armature="0.0005" /><geom name="ldjy_right_finger4_link4_visual_0_geom" type="mesh" mesh="ldjy_right_finger4_link4_visual_0" pos="0.06452334242 0.01460741654 -0.091734512" euler="0 0 0" contype="0" conaffinity="0" group="1" density="0" rgba="0.72 0.76 0.78 1" /><geom name="ldjy_right_finger4_link4_collision" rgba="0.55 0.7 0.9 0" friction="0.7 0.005 0.0001" solref="0.02 1.5" solimp="0.9 0.95 0.001 0.5 2.0" priority="1" condim="3" type="mesh" mesh="ldjy_right_finger4_link4_collision" pos="0.06452334242 0.01460741654 -0.091734512" euler="0 0 0" contype="3" conaffinity="3" /><site name="ldjy_right_finger4_link4_tip" pos="0 0 0.025" group="4" size="0.003" /></body></body></body></body></body></body>
                        </body>
                      </body>
                    </body>
                  </body>
                </body>
              </body>
            </body>
          </body>
          <body name="head_base_link" pos="0 0.14 0.1">
            <inertial pos="0 0 0" mass="0.5" diaginertia="0.002 0.002 0.002" />
            <geom pos="-0.563 0.0866 0" quat="0.707107 0.707107 0 0" type="mesh" contype="3" conaffinity="3" group="1" density="0" mesh="packages_openarmx_head_description_meshes_visual_TBBJ-04_neck_mount" />
            <geom pos="-0.563 0.0866 0" quat="0.707107 0.707107 0 0" type="mesh" contype="3" conaffinity="3" group="1" density="0" mesh="packages_openarmx_head_description_meshes_visual_TBBJ-02_neck_bracket" />
            <geom pos="-0.563 0.0866 0" quat="0.707107 0.707107 0 0" type="mesh" contype="3" conaffinity="3" group="1" density="0" mesh="packages_openarmx_head_description_meshes_visual_TBBJ-06_neck_limit" />
            <geom pos="-0.563 0.0866 0" quat="0.707107 0.707107 0 0" type="mesh" contype="3" conaffinity="3" group="1" density="0" rgba="0.2 0.2 0.2 1" mesh="packages_openarmx_head_description_meshes_visual_RS00_motor_2" />
            <body name="head_pitch_link" pos="0.0001 0.0068 0.0395">
              <inertial pos="0 0 0" mass="0.5" diaginertia="0.002 0.002 0.002" />
              <joint name="openarmx_head_pitch_joint" pos="0 0 0" axis="1 0 0" range="-1.5708 1.5708" actuatorfrcrange="-14 14" damping="2.0" armature="0.01" frictionloss="0.05" />
              <geom pos="-0.5631 0.0798 -0.0395" quat="0.707107 0.707107 0 0" type="mesh" contype="3" conaffinity="3" group="1" density="0" rgba="0.9 0.9 0.9 1" mesh="packages_openarmx_head_description_meshes_visual_DY-03_neck_cover" />
              <geom pos="-0.5631 0.0798 -0.0395" quat="0.707107 0.707107 0 0" type="mesh" contype="3" conaffinity="3" group="1" density="0" rgba="0.2 0.2 0.2 1" mesh="packages_openarmx_head_description_meshes_visual_RS00_motor_1" />
              <geom pos="-0.5631 0.0798 -0.0395" quat="0.707107 0.707107 0 0" type="mesh" contype="3" conaffinity="3" group="1" density="0" mesh="packages_openarmx_head_description_meshes_visual_TB-01_head_connector" />
              <geom pos="-0.5631 0.0798 -0.0395" quat="0.707107 0.707107 0 0" type="mesh" contype="3" conaffinity="3" group="1" density="0" mesh="packages_openarmx_head_description_meshes_visual_TBBJ-03_guard_plate" />
              <body name="head_yaw_link" pos="0 -0.0026 0.0677">
                <inertial pos="0 0 0" mass="0.5" diaginertia="0.002 0.002 0.002" />
                <joint name="openarmx_head_yaw_joint" pos="0 0 0" axis="0 0 1" range="-1.5708 1.5708" actuatorfrcrange="-14 14" damping="2.0" armature="0.01" frictionloss="0.05" />
                <geom pos="-0.5631 0.0824 -0.1072" quat="0.707107 0.707107 0 0" type="mesh" contype="3" conaffinity="3" group="1" density="0" mesh="packages_openarmx_head_description_meshes_visual_TBBJ-01_head_bracket" />
                <geom pos="-0.5631 0.0824 -0.1072" quat="0.707107 0.707107 0 0" type="mesh" contype="3" conaffinity="3" group="1" density="0" mesh="packages_openarmx_head_description_meshes_visual_TBBJ-05_head_limit" />
                <geom pos="-0.5631 0.0824 -0.1072" quat="0.707107 0.707107 0 0" type="mesh" contype="3" conaffinity="3" group="1" density="0" rgba="0.9 0.9 0.9 1" mesh="packages_openarmx_head_description_meshes_visual_DY-01_head_front_shell" />
                <geom pos="-0.5631 0.0824 -0.1072" quat="0.707107 0.707107 0 0" type="mesh" contype="3" conaffinity="3" group="1" density="0" rgba="0.9 0.9 0.9 1" mesh="packages_openarmx_head_description_meshes_visual_DY-02_head_rear_shell" />
                <geom pos="-0.5631 0.0824 -0.1072" quat="0.707107 0.707107 0 0" type="mesh" contype="3" conaffinity="3" group="1" density="0" rgba="0.1 0.1 0.1 1" mesh="packages_openarmx_head_description_meshes_visual_femto_bolt_camera" />
              </body>
            </body>
          </body>
        </body>
      </body>
    </body>
  </body><light name="key_light" pos="-1.4 -2.2 3.2" dir="0.35 0.55 -1" directional="true" diffuse="0.95 0.92 0.86" specular="0.35 0.35 0.35" />
<light name="fill_light" pos="1.8 1.4 2.2" dir="-0.45 -0.35 -1" directional="true" diffuse="0.35 0.45 0.65" specular="0.12 0.12 0.16" />
<light name="rim_light" pos="0 2.2 1.8" dir="0 -1 -0.45" directional="true" diffuse="0.55 0.65 0.85" specular="0.20 0.22 0.28" />
<geom name="floor" type="plane" pos="0 0 0" size="2.4 2.4 0.02" material="floor_mat" contype="1" conaffinity="3" /></worldbody>
<visual><headlight diffuse="0.55 0.55 0.55" ambient="0.24 0.24 0.26" specular="0.25 0.25 0.25" />
  <map znear="0.01" zfar="8" />
  <scale forcewidth="0.06" contactwidth="0.05" />
  <rgba haze="0.03 0.035 0.045 1" />
</visual><contact><exclude body1="openflex_robot_yaw_root" body2="base_link" /><exclude body1="base_link" body2="base_footprint" /><exclude body1="base_link" body2="fl_steering_link" /><exclude body1="fl_steering_link" body2="fl_wheel_link" /><exclude body1="base_link" body2="fr_steering_link" /><exclude body1="fr_steering_link" body2="fr_wheel_link" /><exclude body1="base_link" body2="bl_steering_link" /><exclude body1="bl_steering_link" body2="bl_wheel_link" /><exclude body1="base_link" body2="br_steering_link" /><exclude body1="br_steering_link" body2="br_wheel_link" /><exclude body1="base_link" body2="mid360_link" /><exclude body1="mid360_link" body2="livox_frame" /><exclude body1="mid360_link" body2="imu_link" /><exclude body1="base_link" body2="d435_link" /><exclude body1="d435_link" body2="camera_link" /><exclude body1="camera_link" body2="camera_depth_frame" /><exclude body1="camera_depth_frame" body2="camera_depth_optical_frame" /><exclude body1="camera_link" body2="camera_rgb_frame" /><exclude body1="camera_rgb_frame" body2="camera_rgb_optical_frame" /><exclude body1="d435_link" body2="d435_depth_frame" /><exclude body1="d435_depth_frame" body2="d435_depth_optical_frame" /><exclude body1="d435_link" body2="d435_color_frame" /><exclude body1="d435_color_frame" body2="d435_color_optical_frame" /><exclude body1="base_link" body2="gps_link" /><exclude body1="base_link" body2="lift_base_link" /><exclude body1="lift_base_link" body2="lift_carriage_link" /><exclude body1="lift_carriage_link" body2="chest_link" /><exclude body1="lift_carriage_link" body2="left_link0_base" /><exclude body1="left_link0_base" body2="openarmx_left_link0" /><exclude body1="openarmx_left_link0" body2="openarmx_left_link1" /><exclude body1="openarmx_left_link1" body2="openarmx_left_link2" /><exclude body1="openarmx_left_link2" body2="openarmx_left_link3" /><exclude body1="openarmx_left_link3" body2="openarmx_left_link4" /><exclude body1="openarmx_left_link4" body2="openarmx_left_link4_ext" /><exclude body1="openarmx_left_link4" body2="openarmx_left_link5" /><exclude body1="openarmx_left_link5" body2="openarmx_left_link6" /><exclude body1="openarmx_left_link6" body2="openarmx_left_link7" /><exclude body1="openarmx_left_link7" body2="ldjy_left_palm" /><exclude body1="ldjy_left_palm" body2="ldjy_left_finger1_link1" /><exclude body1="ldjy_left_finger1_link1" body2="ldjy_left_finger1_link2" /><exclude body1="ldjy_left_finger1_link2" body2="ldjy_left_finger1_link3" /><exclude body1="ldjy_left_finger1_link3" body2="ldjy_left_finger1_link4" /><exclude body1="ldjy_left_palm" body2="ldjy_left_finger2_link1" /><exclude body1="ldjy_left_finger2_link1" body2="ldjy_left_finger2_link2" /><exclude body1="ldjy_left_finger2_link2" body2="ldjy_left_finger2_link3" /><exclude body1="ldjy_left_finger2_link3" body2="ldjy_left_finger2_link4" /><exclude body1="ldjy_left_palm" body2="ldjy_left_finger3_link1" /><exclude body1="ldjy_left_finger3_link1" body2="ldjy_left_finger3_link2" /><exclude body1="ldjy_left_finger3_link2" body2="ldjy_left_finger3_link3" /><exclude body1="ldjy_left_finger3_link3" body2="ldjy_left_finger3_link4" /><exclude body1="ldjy_left_palm" body2="ldjy_left_thumb_link1" /><exclude body1="ldjy_left_thumb_link1" body2="ldjy_left_thumb_link2" /><exclude body1="ldjy_left_thumb_link2" body2="ldjy_left_thumb_link3" /><exclude body1="ldjy_left_thumb_link3" body2="ldjy_left_thumb_link4" /><exclude body1="ldjy_left_palm" body2="ldjy_left_finger4_link1" /><exclude body1="ldjy_left_finger4_link1" body2="ldjy_left_finger4_link2" /><exclude body1="ldjy_left_finger4_link2" body2="ldjy_left_finger4_link3" /><exclude body1="ldjy_left_finger4_link3" body2="ldjy_left_finger4_link4" /><exclude body1="lift_carriage_link" body2="right_link0_base" /><exclude body1="right_link0_base" body2="openarmx_right_link0" /><exclude body1="openarmx_right_link0" body2="openarmx_right_link1" /><exclude body1="openarmx_right_link1" body2="openarmx_right_link2" /><exclude body1="openarmx_right_link2" body2="openarmx_right_link3" /><exclude body1="openarmx_right_link3" body2="openarmx_right_link4" /><exclude body1="openarmx_right_link4" body2="openarmx_right_link4_ext" /><exclude body1="openarmx_right_link4" body2="openarmx_right_link5" /><exclude body1="openarmx_right_link5" body2="openarmx_right_link6" /><exclude body1="openarmx_right_link6" body2="openarmx_right_link7" /><exclude body1="openarmx_right_link7" body2="ldjy_right_palm" /><exclude body1="ldjy_right_palm" body2="ldjy_right_finger1_link1" /><exclude body1="ldjy_right_finger1_link1" body2="ldjy_right_finger1_link2" /><exclude body1="ldjy_right_finger1_link2" body2="ldjy_right_finger1_link3" /><exclude body1="ldjy_right_finger1_link3" body2="ldjy_right_finger1_link4" /><exclude body1="ldjy_right_palm" body2="ldjy_right_finger2_link1" /><exclude body1="ldjy_right_finger2_link1" body2="ldjy_right_finger2_link2" /><exclude body1="ldjy_right_finger2_link2" body2="ldjy_right_finger2_link3" /><exclude body1="ldjy_right_finger2_link3" body2="ldjy_right_finger2_link4" /><exclude body1="ldjy_right_palm" body2="ldjy_right_finger3_link1" /><exclude body1="ldjy_right_finger3_link1" body2="ldjy_right_finger3_link2" /><exclude body1="ldjy_right_finger3_link2" body2="ldjy_right_finger3_link3" /><exclude body1="ldjy_right_finger3_link3" body2="ldjy_right_finger3_link4" /><exclude body1="ldjy_right_palm" body2="ldjy_right_thumb_link1" /><exclude body1="ldjy_right_thumb_link1" body2="ldjy_right_thumb_link2" /><exclude body1="ldjy_right_thumb_link2" body2="ldjy_right_thumb_link3" /><exclude body1="ldjy_right_thumb_link3" body2="ldjy_right_thumb_link4" /><exclude body1="ldjy_right_palm" body2="ldjy_right_finger4_link1" /><exclude body1="ldjy_right_finger4_link1" body2="ldjy_right_finger4_link2" /><exclude body1="ldjy_right_finger4_link2" body2="ldjy_right_finger4_link3" /><exclude body1="ldjy_right_finger4_link3" body2="ldjy_right_finger4_link4" /><exclude body1="lift_carriage_link" body2="head_base_link" /><exclude body1="head_base_link" body2="head_pitch_link" /><exclude body1="head_pitch_link" body2="head_yaw_link" /><exclude body1="openflex_robot_yaw_root" body2="base_link" /><exclude body1="openflex_robot_yaw_root" body2="base_footprint" /><exclude body1="openflex_robot_yaw_root" body2="fl_steering_link" /><exclude body1="openflex_robot_yaw_root" body2="fl_wheel_link" /><exclude body1="openflex_robot_yaw_root" body2="fr_steering_link" /><exclude body1="openflex_robot_yaw_root" body2="fr_wheel_link" /><exclude body1="openflex_robot_yaw_root" body2="bl_steering_link" /><exclude body1="openflex_robot_yaw_root" body2="bl_wheel_link" /><exclude body1="openflex_robot_yaw_root" body2="br_steering_link" /><exclude body1="openflex_robot_yaw_root" body2="br_wheel_link" /><exclude body1="openflex_robot_yaw_root" body2="mid360_link" /><exclude body1="openflex_robot_yaw_root" body2="livox_frame" /><exclude body1="openflex_robot_yaw_root" body2="imu_link" /><exclude body1="openflex_robot_yaw_root" body2="d435_link" /><exclude body1="openflex_robot_yaw_root" body2="camera_link" /><exclude body1="openflex_robot_yaw_root" body2="camera_depth_frame" /><exclude body1="openflex_robot_yaw_root" body2="camera_depth_optical_frame" /><exclude body1="openflex_robot_yaw_root" body2="camera_rgb_frame" /><exclude body1="openflex_robot_yaw_root" body2="camera_rgb_optical_frame" /><exclude body1="openflex_robot_yaw_root" body2="d435_depth_frame" /><exclude body1="openflex_robot_yaw_root" body2="d435_depth_optical_frame" /><exclude body1="openflex_robot_yaw_root" body2="d435_color_frame" /><exclude body1="openflex_robot_yaw_root" body2="d435_color_optical_frame" /><exclude body1="openflex_robot_yaw_root" body2="gps_link" /><exclude body1="openflex_robot_yaw_root" body2="lift_base_link" /><exclude body1="openflex_robot_yaw_root" body2="lift_carriage_link" /><exclude body1="openflex_robot_yaw_root" body2="chest_link" /><exclude body1="openflex_robot_yaw_root" body2="left_link0_base" /><exclude body1="openflex_robot_yaw_root" body2="right_link0_base" /><exclude body1="openflex_robot_yaw_root" body2="head_base_link" /><exclude body1="openflex_robot_yaw_root" body2="head_pitch_link" /><exclude body1="openflex_robot_yaw_root" body2="head_yaw_link" /><exclude body1="base_link" body2="base_footprint" /><exclude body1="base_link" body2="fl_steering_link" /><exclude body1="base_link" body2="fl_wheel_link" /><exclude body1="base_link" body2="fr_steering_link" /><exclude body1="base_link" body2="fr_wheel_link" /><exclude body1="base_link" body2="bl_steering_link" /><exclude body1="base_link" body2="bl_wheel_link" /><exclude body1="base_link" body2="br_steering_link" /><exclude body1="base_link" body2="br_wheel_link" /><exclude body1="base_link" body2="mid360_link" /><exclude body1="base_link" body2="livox_frame" /><exclude body1="base_link" body2="imu_link" /><exclude body1="base_link" body2="d435_link" /><exclude body1="base_link" body2="camera_link" /><exclude body1="base_link" body2="camera_depth_frame" /><exclude body1="base_link" body2="camera_depth_optical_frame" /><exclude body1="base_link" body2="camera_rgb_frame" /><exclude body1="base_link" body2="camera_rgb_optical_frame" /><exclude body1="base_link" body2="d435_depth_frame" /><exclude body1="base_link" body2="d435_depth_optical_frame" /><exclude body1="base_link" body2="d435_color_frame" /><exclude body1="base_link" body2="d435_color_optical_frame" /><exclude body1="base_link" body2="gps_link" /><exclude body1="base_link" body2="lift_base_link" /><exclude body1="base_link" body2="lift_carriage_link" /><exclude body1="base_link" body2="chest_link" /><exclude body1="base_link" body2="left_link0_base" /><exclude body1="base_link" body2="right_link0_base" /><exclude body1="base_link" body2="head_base_link" /><exclude body1="base_link" body2="head_pitch_link" /><exclude body1="base_link" body2="head_yaw_link" /><exclude body1="base_footprint" body2="fl_steering_link" /><exclude body1="base_footprint" body2="fl_wheel_link" /><exclude body1="base_footprint" body2="fr_steering_link" /><exclude body1="base_footprint" body2="fr_wheel_link" /><exclude body1="base_footprint" body2="bl_steering_link" /><exclude body1="base_footprint" body2="bl_wheel_link" /><exclude body1="base_footprint" body2="br_steering_link" /><exclude body1="base_footprint" body2="br_wheel_link" /><exclude body1="base_footprint" body2="mid360_link" /><exclude body1="base_footprint" body2="livox_frame" /><exclude body1="base_footprint" body2="imu_link" /><exclude body1="base_footprint" body2="d435_link" /><exclude body1="base_footprint" body2="camera_link" /><exclude body1="base_footprint" body2="camera_depth_frame" /><exclude body1="base_footprint" body2="camera_depth_optical_frame" /><exclude body1="base_footprint" body2="camera_rgb_frame" /><exclude body1="base_footprint" body2="camera_rgb_optical_frame" /><exclude body1="base_footprint" body2="d435_depth_frame" /><exclude body1="base_footprint" body2="d435_depth_optical_frame" /><exclude body1="base_footprint" body2="d435_color_frame" /><exclude body1="base_footprint" body2="d435_color_optical_frame" /><exclude body1="base_footprint" body2="gps_link" /><exclude body1="base_footprint" body2="lift_base_link" /><exclude body1="base_footprint" body2="lift_carriage_link" /><exclude body1="base_footprint" body2="chest_link" /><exclude body1="base_footprint" body2="left_link0_base" /><exclude body1="base_footprint" body2="right_link0_base" /><exclude body1="base_footprint" body2="head_base_link" /><exclude body1="base_footprint" body2="head_pitch_link" /><exclude body1="base_footprint" body2="head_yaw_link" /><exclude body1="fl_steering_link" body2="fl_wheel_link" /><exclude body1="fl_steering_link" body2="fr_steering_link" /><exclude body1="fl_steering_link" body2="fr_wheel_link" /><exclude body1="fl_steering_link" body2="bl_steering_link" /><exclude body1="fl_steering_link" body2="bl_wheel_link" /><exclude body1="fl_steering_link" body2="br_steering_link" /><exclude body1="fl_steering_link" body2="br_wheel_link" /><exclude body1="fl_steering_link" body2="mid360_link" /><exclude body1="fl_steering_link" body2="livox_frame" /><exclude body1="fl_steering_link" body2="imu_link" /><exclude body1="fl_steering_link" body2="d435_link" /><exclude body1="fl_steering_link" body2="camera_link" /><exclude body1="fl_steering_link" body2="camera_depth_frame" /><exclude body1="fl_steering_link" body2="camera_depth_optical_frame" /><exclude body1="fl_steering_link" body2="camera_rgb_frame" /><exclude body1="fl_steering_link" body2="camera_rgb_optical_frame" /><exclude body1="fl_steering_link" body2="d435_depth_frame" /><exclude body1="fl_steering_link" body2="d435_depth_optical_frame" /><exclude body1="fl_steering_link" body2="d435_color_frame" /><exclude body1="fl_steering_link" body2="d435_color_optical_frame" /><exclude body1="fl_steering_link" body2="gps_link" /><exclude body1="fl_steering_link" body2="lift_base_link" /><exclude body1="fl_steering_link" body2="lift_carriage_link" /><exclude body1="fl_steering_link" body2="chest_link" /><exclude body1="fl_steering_link" body2="left_link0_base" /><exclude body1="fl_steering_link" body2="right_link0_base" /><exclude body1="fl_steering_link" body2="head_base_link" /><exclude body1="fl_steering_link" body2="head_pitch_link" /><exclude body1="fl_steering_link" body2="head_yaw_link" /><exclude body1="fl_wheel_link" body2="fr_steering_link" /><exclude body1="fl_wheel_link" body2="fr_wheel_link" /><exclude body1="fl_wheel_link" body2="bl_steering_link" /><exclude body1="fl_wheel_link" body2="bl_wheel_link" /><exclude body1="fl_wheel_link" body2="br_steering_link" /><exclude body1="fl_wheel_link" body2="br_wheel_link" /><exclude body1="fl_wheel_link" body2="mid360_link" /><exclude body1="fl_wheel_link" body2="livox_frame" /><exclude body1="fl_wheel_link" body2="imu_link" /><exclude body1="fl_wheel_link" body2="d435_link" /><exclude body1="fl_wheel_link" body2="camera_link" /><exclude body1="fl_wheel_link" body2="camera_depth_frame" /><exclude body1="fl_wheel_link" body2="camera_depth_optical_frame" /><exclude body1="fl_wheel_link" body2="camera_rgb_frame" /><exclude body1="fl_wheel_link" body2="camera_rgb_optical_frame" /><exclude body1="fl_wheel_link" body2="d435_depth_frame" /><exclude body1="fl_wheel_link" body2="d435_depth_optical_frame" /><exclude body1="fl_wheel_link" body2="d435_color_frame" /><exclude body1="fl_wheel_link" body2="d435_color_optical_frame" /><exclude body1="fl_wheel_link" body2="gps_link" /><exclude body1="fl_wheel_link" body2="lift_base_link" /><exclude body1="fl_wheel_link" body2="lift_carriage_link" /><exclude body1="fl_wheel_link" body2="chest_link" /><exclude body1="fl_wheel_link" body2="left_link0_base" /><exclude body1="fl_wheel_link" body2="right_link0_base" /><exclude body1="fl_wheel_link" body2="head_base_link" /><exclude body1="fl_wheel_link" body2="head_pitch_link" /><exclude body1="fl_wheel_link" body2="head_yaw_link" /><exclude body1="fr_steering_link" body2="fr_wheel_link" /><exclude body1="fr_steering_link" body2="bl_steering_link" /><exclude body1="fr_steering_link" body2="bl_wheel_link" /><exclude body1="fr_steering_link" body2="br_steering_link" /><exclude body1="fr_steering_link" body2="br_wheel_link" /><exclude body1="fr_steering_link" body2="mid360_link" /><exclude body1="fr_steering_link" body2="livox_frame" /><exclude body1="fr_steering_link" body2="imu_link" /><exclude body1="fr_steering_link" body2="d435_link" /><exclude body1="fr_steering_link" body2="camera_link" /><exclude body1="fr_steering_link" body2="camera_depth_frame" /><exclude body1="fr_steering_link" body2="camera_depth_optical_frame" /><exclude body1="fr_steering_link" body2="camera_rgb_frame" /><exclude body1="fr_steering_link" body2="camera_rgb_optical_frame" /><exclude body1="fr_steering_link" body2="d435_depth_frame" /><exclude body1="fr_steering_link" body2="d435_depth_optical_frame" /><exclude body1="fr_steering_link" body2="d435_color_frame" /><exclude body1="fr_steering_link" body2="d435_color_optical_frame" /><exclude body1="fr_steering_link" body2="gps_link" /><exclude body1="fr_steering_link" body2="lift_base_link" /><exclude body1="fr_steering_link" body2="lift_carriage_link" /><exclude body1="fr_steering_link" body2="chest_link" /><exclude body1="fr_steering_link" body2="left_link0_base" /><exclude body1="fr_steering_link" body2="right_link0_base" /><exclude body1="fr_steering_link" body2="head_base_link" /><exclude body1="fr_steering_link" body2="head_pitch_link" /><exclude body1="fr_steering_link" body2="head_yaw_link" /><exclude body1="fr_wheel_link" body2="bl_steering_link" /><exclude body1="fr_wheel_link" body2="bl_wheel_link" /><exclude body1="fr_wheel_link" body2="br_steering_link" /><exclude body1="fr_wheel_link" body2="br_wheel_link" /><exclude body1="fr_wheel_link" body2="mid360_link" /><exclude body1="fr_wheel_link" body2="livox_frame" /><exclude body1="fr_wheel_link" body2="imu_link" /><exclude body1="fr_wheel_link" body2="d435_link" /><exclude body1="fr_wheel_link" body2="camera_link" /><exclude body1="fr_wheel_link" body2="camera_depth_frame" /><exclude body1="fr_wheel_link" body2="camera_depth_optical_frame" /><exclude body1="fr_wheel_link" body2="camera_rgb_frame" /><exclude body1="fr_wheel_link" body2="camera_rgb_optical_frame" /><exclude body1="fr_wheel_link" body2="d435_depth_frame" /><exclude body1="fr_wheel_link" body2="d435_depth_optical_frame" /><exclude body1="fr_wheel_link" body2="d435_color_frame" /><exclude body1="fr_wheel_link" body2="d435_color_optical_frame" /><exclude body1="fr_wheel_link" body2="gps_link" /><exclude body1="fr_wheel_link" body2="lift_base_link" /><exclude body1="fr_wheel_link" body2="lift_carriage_link" /><exclude body1="fr_wheel_link" body2="chest_link" /><exclude body1="fr_wheel_link" body2="left_link0_base" /><exclude body1="fr_wheel_link" body2="right_link0_base" /><exclude body1="fr_wheel_link" body2="head_base_link" /><exclude body1="fr_wheel_link" body2="head_pitch_link" /><exclude body1="fr_wheel_link" body2="head_yaw_link" /><exclude body1="bl_steering_link" body2="bl_wheel_link" /><exclude body1="bl_steering_link" body2="br_steering_link" /><exclude body1="bl_steering_link" body2="br_wheel_link" /><exclude body1="bl_steering_link" body2="mid360_link" /><exclude body1="bl_steering_link" body2="livox_frame" /><exclude body1="bl_steering_link" body2="imu_link" /><exclude body1="bl_steering_link" body2="d435_link" /><exclude body1="bl_steering_link" body2="camera_link" /><exclude body1="bl_steering_link" body2="camera_depth_frame" /><exclude body1="bl_steering_link" body2="camera_depth_optical_frame" /><exclude body1="bl_steering_link" body2="camera_rgb_frame" /><exclude body1="bl_steering_link" body2="camera_rgb_optical_frame" /><exclude body1="bl_steering_link" body2="d435_depth_frame" /><exclude body1="bl_steering_link" body2="d435_depth_optical_frame" /><exclude body1="bl_steering_link" body2="d435_color_frame" /><exclude body1="bl_steering_link" body2="d435_color_optical_frame" /><exclude body1="bl_steering_link" body2="gps_link" /><exclude body1="bl_steering_link" body2="lift_base_link" /><exclude body1="bl_steering_link" body2="lift_carriage_link" /><exclude body1="bl_steering_link" body2="chest_link" /><exclude body1="bl_steering_link" body2="left_link0_base" /><exclude body1="bl_steering_link" body2="right_link0_base" /><exclude body1="bl_steering_link" body2="head_base_link" /><exclude body1="bl_steering_link" body2="head_pitch_link" /><exclude body1="bl_steering_link" body2="head_yaw_link" /><exclude body1="bl_wheel_link" body2="br_steering_link" /><exclude body1="bl_wheel_link" body2="br_wheel_link" /><exclude body1="bl_wheel_link" body2="mid360_link" /><exclude body1="bl_wheel_link" body2="livox_frame" /><exclude body1="bl_wheel_link" body2="imu_link" /><exclude body1="bl_wheel_link" body2="d435_link" /><exclude body1="bl_wheel_link" body2="camera_link" /><exclude body1="bl_wheel_link" body2="camera_depth_frame" /><exclude body1="bl_wheel_link" body2="camera_depth_optical_frame" /><exclude body1="bl_wheel_link" body2="camera_rgb_frame" /><exclude body1="bl_wheel_link" body2="camera_rgb_optical_frame" /><exclude body1="bl_wheel_link" body2="d435_depth_frame" /><exclude body1="bl_wheel_link" body2="d435_depth_optical_frame" /><exclude body1="bl_wheel_link" body2="d435_color_frame" /><exclude body1="bl_wheel_link" body2="d435_color_optical_frame" /><exclude body1="bl_wheel_link" body2="gps_link" /><exclude body1="bl_wheel_link" body2="lift_base_link" /><exclude body1="bl_wheel_link" body2="lift_carriage_link" /><exclude body1="bl_wheel_link" body2="chest_link" /><exclude body1="bl_wheel_link" body2="left_link0_base" /><exclude body1="bl_wheel_link" body2="right_link0_base" /><exclude body1="bl_wheel_link" body2="head_base_link" /><exclude body1="bl_wheel_link" body2="head_pitch_link" /><exclude body1="bl_wheel_link" body2="head_yaw_link" /><exclude body1="br_steering_link" body2="br_wheel_link" /><exclude body1="br_steering_link" body2="mid360_link" /><exclude body1="br_steering_link" body2="livox_frame" /><exclude body1="br_steering_link" body2="imu_link" /><exclude body1="br_steering_link" body2="d435_link" /><exclude body1="br_steering_link" body2="camera_link" /><exclude body1="br_steering_link" body2="camera_depth_frame" /><exclude body1="br_steering_link" body2="camera_depth_optical_frame" /><exclude body1="br_steering_link" body2="camera_rgb_frame" /><exclude body1="br_steering_link" body2="camera_rgb_optical_frame" /><exclude body1="br_steering_link" body2="d435_depth_frame" /><exclude body1="br_steering_link" body2="d435_depth_optical_frame" /><exclude body1="br_steering_link" body2="d435_color_frame" /><exclude body1="br_steering_link" body2="d435_color_optical_frame" /><exclude body1="br_steering_link" body2="gps_link" /><exclude body1="br_steering_link" body2="lift_base_link" /><exclude body1="br_steering_link" body2="lift_carriage_link" /><exclude body1="br_steering_link" body2="chest_link" /><exclude body1="br_steering_link" body2="left_link0_base" /><exclude body1="br_steering_link" body2="right_link0_base" /><exclude body1="br_steering_link" body2="head_base_link" /><exclude body1="br_steering_link" body2="head_pitch_link" /><exclude body1="br_steering_link" body2="head_yaw_link" /><exclude body1="br_wheel_link" body2="mid360_link" /><exclude body1="br_wheel_link" body2="livox_frame" /><exclude body1="br_wheel_link" body2="imu_link" /><exclude body1="br_wheel_link" body2="d435_link" /><exclude body1="br_wheel_link" body2="camera_link" /><exclude body1="br_wheel_link" body2="camera_depth_frame" /><exclude body1="br_wheel_link" body2="camera_depth_optical_frame" /><exclude body1="br_wheel_link" body2="camera_rgb_frame" /><exclude body1="br_wheel_link" body2="camera_rgb_optical_frame" /><exclude body1="br_wheel_link" body2="d435_depth_frame" /><exclude body1="br_wheel_link" body2="d435_depth_optical_frame" /><exclude body1="br_wheel_link" body2="d435_color_frame" /><exclude body1="br_wheel_link" body2="d435_color_optical_frame" /><exclude body1="br_wheel_link" body2="gps_link" /><exclude body1="br_wheel_link" body2="lift_base_link" /><exclude body1="br_wheel_link" body2="lift_carriage_link" /><exclude body1="br_wheel_link" body2="chest_link" /><exclude body1="br_wheel_link" body2="left_link0_base" /><exclude body1="br_wheel_link" body2="right_link0_base" /><exclude body1="br_wheel_link" body2="head_base_link" /><exclude body1="br_wheel_link" body2="head_pitch_link" /><exclude body1="br_wheel_link" body2="head_yaw_link" /><exclude body1="mid360_link" body2="livox_frame" /><exclude body1="mid360_link" body2="imu_link" /><exclude body1="mid360_link" body2="d435_link" /><exclude body1="mid360_link" body2="camera_link" /><exclude body1="mid360_link" body2="camera_depth_frame" /><exclude body1="mid360_link" body2="camera_depth_optical_frame" /><exclude body1="mid360_link" body2="camera_rgb_frame" /><exclude body1="mid360_link" body2="camera_rgb_optical_frame" /><exclude body1="mid360_link" body2="d435_depth_frame" /><exclude body1="mid360_link" body2="d435_depth_optical_frame" /><exclude body1="mid360_link" body2="d435_color_frame" /><exclude body1="mid360_link" body2="d435_color_optical_frame" /><exclude body1="mid360_link" body2="gps_link" /><exclude body1="mid360_link" body2="lift_base_link" /><exclude body1="mid360_link" body2="lift_carriage_link" /><exclude body1="mid360_link" body2="chest_link" /><exclude body1="mid360_link" body2="left_link0_base" /><exclude body1="mid360_link" body2="right_link0_base" /><exclude body1="mid360_link" body2="head_base_link" /><exclude body1="mid360_link" body2="head_pitch_link" /><exclude body1="mid360_link" body2="head_yaw_link" /><exclude body1="livox_frame" body2="imu_link" /><exclude body1="livox_frame" body2="d435_link" /><exclude body1="livox_frame" body2="camera_link" /><exclude body1="livox_frame" body2="camera_depth_frame" /><exclude body1="livox_frame" body2="camera_depth_optical_frame" /><exclude body1="livox_frame" body2="camera_rgb_frame" /><exclude body1="livox_frame" body2="camera_rgb_optical_frame" /><exclude body1="livox_frame" body2="d435_depth_frame" /><exclude body1="livox_frame" body2="d435_depth_optical_frame" /><exclude body1="livox_frame" body2="d435_color_frame" /><exclude body1="livox_frame" body2="d435_color_optical_frame" /><exclude body1="livox_frame" body2="gps_link" /><exclude body1="livox_frame" body2="lift_base_link" /><exclude body1="livox_frame" body2="lift_carriage_link" /><exclude body1="livox_frame" body2="chest_link" /><exclude body1="livox_frame" body2="left_link0_base" /><exclude body1="livox_frame" body2="right_link0_base" /><exclude body1="livox_frame" body2="head_base_link" /><exclude body1="livox_frame" body2="head_pitch_link" /><exclude body1="livox_frame" body2="head_yaw_link" /><exclude body1="imu_link" body2="d435_link" /><exclude body1="imu_link" body2="camera_link" /><exclude body1="imu_link" body2="camera_depth_frame" /><exclude body1="imu_link" body2="camera_depth_optical_frame" /><exclude body1="imu_link" body2="camera_rgb_frame" /><exclude body1="imu_link" body2="camera_rgb_optical_frame" /><exclude body1="imu_link" body2="d435_depth_frame" /><exclude body1="imu_link" body2="d435_depth_optical_frame" /><exclude body1="imu_link" body2="d435_color_frame" /><exclude body1="imu_link" body2="d435_color_optical_frame" /><exclude body1="imu_link" body2="gps_link" /><exclude body1="imu_link" body2="lift_base_link" /><exclude body1="imu_link" body2="lift_carriage_link" /><exclude body1="imu_link" body2="chest_link" /><exclude body1="imu_link" body2="left_link0_base" /><exclude body1="imu_link" body2="right_link0_base" /><exclude body1="imu_link" body2="head_base_link" /><exclude body1="imu_link" body2="head_pitch_link" /><exclude body1="imu_link" body2="head_yaw_link" /><exclude body1="d435_link" body2="camera_link" /><exclude body1="d435_link" body2="camera_depth_frame" /><exclude body1="d435_link" body2="camera_depth_optical_frame" /><exclude body1="d435_link" body2="camera_rgb_frame" /><exclude body1="d435_link" body2="camera_rgb_optical_frame" /><exclude body1="d435_link" body2="d435_depth_frame" /><exclude body1="d435_link" body2="d435_depth_optical_frame" /><exclude body1="d435_link" body2="d435_color_frame" /><exclude body1="d435_link" body2="d435_color_optical_frame" /><exclude body1="d435_link" body2="gps_link" /><exclude body1="d435_link" body2="lift_base_link" /><exclude body1="d435_link" body2="lift_carriage_link" /><exclude body1="d435_link" body2="chest_link" /><exclude body1="d435_link" body2="left_link0_base" /><exclude body1="d435_link" body2="right_link0_base" /><exclude body1="d435_link" body2="head_base_link" /><exclude body1="d435_link" body2="head_pitch_link" /><exclude body1="d435_link" body2="head_yaw_link" /><exclude body1="camera_link" body2="camera_depth_frame" /><exclude body1="camera_link" body2="camera_depth_optical_frame" /><exclude body1="camera_link" body2="camera_rgb_frame" /><exclude body1="camera_link" body2="camera_rgb_optical_frame" /><exclude body1="camera_link" body2="d435_depth_frame" /><exclude body1="camera_link" body2="d435_depth_optical_frame" /><exclude body1="camera_link" body2="d435_color_frame" /><exclude body1="camera_link" body2="d435_color_optical_frame" /><exclude body1="camera_link" body2="gps_link" /><exclude body1="camera_link" body2="lift_base_link" /><exclude body1="camera_link" body2="lift_carriage_link" /><exclude body1="camera_link" body2="chest_link" /><exclude body1="camera_link" body2="left_link0_base" /><exclude body1="camera_link" body2="right_link0_base" /><exclude body1="camera_link" body2="head_base_link" /><exclude body1="camera_link" body2="head_pitch_link" /><exclude body1="camera_link" body2="head_yaw_link" /><exclude body1="camera_depth_frame" body2="camera_depth_optical_frame" /><exclude body1="camera_depth_frame" body2="camera_rgb_frame" /><exclude body1="camera_depth_frame" body2="camera_rgb_optical_frame" /><exclude body1="camera_depth_frame" body2="d435_depth_frame" /><exclude body1="camera_depth_frame" body2="d435_depth_optical_frame" /><exclude body1="camera_depth_frame" body2="d435_color_frame" /><exclude body1="camera_depth_frame" body2="d435_color_optical_frame" /><exclude body1="camera_depth_frame" body2="gps_link" /><exclude body1="camera_depth_frame" body2="lift_base_link" /><exclude body1="camera_depth_frame" body2="lift_carriage_link" /><exclude body1="camera_depth_frame" body2="chest_link" /><exclude body1="camera_depth_frame" body2="left_link0_base" /><exclude body1="camera_depth_frame" body2="right_link0_base" /><exclude body1="camera_depth_frame" body2="head_base_link" /><exclude body1="camera_depth_frame" body2="head_pitch_link" /><exclude body1="camera_depth_frame" body2="head_yaw_link" /><exclude body1="camera_depth_optical_frame" body2="camera_rgb_frame" /><exclude body1="camera_depth_optical_frame" body2="camera_rgb_optical_frame" /><exclude body1="camera_depth_optical_frame" body2="d435_depth_frame" /><exclude body1="camera_depth_optical_frame" body2="d435_depth_optical_frame" /><exclude body1="camera_depth_optical_frame" body2="d435_color_frame" /><exclude body1="camera_depth_optical_frame" body2="d435_color_optical_frame" /><exclude body1="camera_depth_optical_frame" body2="gps_link" /><exclude body1="camera_depth_optical_frame" body2="lift_base_link" /><exclude body1="camera_depth_optical_frame" body2="lift_carriage_link" /><exclude body1="camera_depth_optical_frame" body2="chest_link" /><exclude body1="camera_depth_optical_frame" body2="left_link0_base" /><exclude body1="camera_depth_optical_frame" body2="right_link0_base" /><exclude body1="camera_depth_optical_frame" body2="head_base_link" /><exclude body1="camera_depth_optical_frame" body2="head_pitch_link" /><exclude body1="camera_depth_optical_frame" body2="head_yaw_link" /><exclude body1="camera_rgb_frame" body2="camera_rgb_optical_frame" /><exclude body1="camera_rgb_frame" body2="d435_depth_frame" /><exclude body1="camera_rgb_frame" body2="d435_depth_optical_frame" /><exclude body1="camera_rgb_frame" body2="d435_color_frame" /><exclude body1="camera_rgb_frame" body2="d435_color_optical_frame" /><exclude body1="camera_rgb_frame" body2="gps_link" /><exclude body1="camera_rgb_frame" body2="lift_base_link" /><exclude body1="camera_rgb_frame" body2="lift_carriage_link" /><exclude body1="camera_rgb_frame" body2="chest_link" /><exclude body1="camera_rgb_frame" body2="left_link0_base" /><exclude body1="camera_rgb_frame" body2="right_link0_base" /><exclude body1="camera_rgb_frame" body2="head_base_link" /><exclude body1="camera_rgb_frame" body2="head_pitch_link" /><exclude body1="camera_rgb_frame" body2="head_yaw_link" /><exclude body1="camera_rgb_optical_frame" body2="d435_depth_frame" /><exclude body1="camera_rgb_optical_frame" body2="d435_depth_optical_frame" /><exclude body1="camera_rgb_optical_frame" body2="d435_color_frame" /><exclude body1="camera_rgb_optical_frame" body2="d435_color_optical_frame" /><exclude body1="camera_rgb_optical_frame" body2="gps_link" /><exclude body1="camera_rgb_optical_frame" body2="lift_base_link" /><exclude body1="camera_rgb_optical_frame" body2="lift_carriage_link" /><exclude body1="camera_rgb_optical_frame" body2="chest_link" /><exclude body1="camera_rgb_optical_frame" body2="left_link0_base" /><exclude body1="camera_rgb_optical_frame" body2="right_link0_base" /><exclude body1="camera_rgb_optical_frame" body2="head_base_link" /><exclude body1="camera_rgb_optical_frame" body2="head_pitch_link" /><exclude body1="camera_rgb_optical_frame" body2="head_yaw_link" /><exclude body1="d435_depth_frame" body2="d435_depth_optical_frame" /><exclude body1="d435_depth_frame" body2="d435_color_frame" /><exclude body1="d435_depth_frame" body2="d435_color_optical_frame" /><exclude body1="d435_depth_frame" body2="gps_link" /><exclude body1="d435_depth_frame" body2="lift_base_link" /><exclude body1="d435_depth_frame" body2="lift_carriage_link" /><exclude body1="d435_depth_frame" body2="chest_link" /><exclude body1="d435_depth_frame" body2="left_link0_base" /><exclude body1="d435_depth_frame" body2="right_link0_base" /><exclude body1="d435_depth_frame" body2="head_base_link" /><exclude body1="d435_depth_frame" body2="head_pitch_link" /><exclude body1="d435_depth_frame" body2="head_yaw_link" /><exclude body1="d435_depth_optical_frame" body2="d435_color_frame" /><exclude body1="d435_depth_optical_frame" body2="d435_color_optical_frame" /><exclude body1="d435_depth_optical_frame" body2="gps_link" /><exclude body1="d435_depth_optical_frame" body2="lift_base_link" /><exclude body1="d435_depth_optical_frame" body2="lift_carriage_link" /><exclude body1="d435_depth_optical_frame" body2="chest_link" /><exclude body1="d435_depth_optical_frame" body2="left_link0_base" /><exclude body1="d435_depth_optical_frame" body2="right_link0_base" /><exclude body1="d435_depth_optical_frame" body2="head_base_link" /><exclude body1="d435_depth_optical_frame" body2="head_pitch_link" /><exclude body1="d435_depth_optical_frame" body2="head_yaw_link" /><exclude body1="d435_color_frame" body2="d435_color_optical_frame" /><exclude body1="d435_color_frame" body2="gps_link" /><exclude body1="d435_color_frame" body2="lift_base_link" /><exclude body1="d435_color_frame" body2="lift_carriage_link" /><exclude body1="d435_color_frame" body2="chest_link" /><exclude body1="d435_color_frame" body2="left_link0_base" /><exclude body1="d435_color_frame" body2="right_link0_base" /><exclude body1="d435_color_frame" body2="head_base_link" /><exclude body1="d435_color_frame" body2="head_pitch_link" /><exclude body1="d435_color_frame" body2="head_yaw_link" /><exclude body1="d435_color_optical_frame" body2="gps_link" /><exclude body1="d435_color_optical_frame" body2="lift_base_link" /><exclude body1="d435_color_optical_frame" body2="lift_carriage_link" /><exclude body1="d435_color_optical_frame" body2="chest_link" /><exclude body1="d435_color_optical_frame" body2="left_link0_base" /><exclude body1="d435_color_optical_frame" body2="right_link0_base" /><exclude body1="d435_color_optical_frame" body2="head_base_link" /><exclude body1="d435_color_optical_frame" body2="head_pitch_link" /><exclude body1="d435_color_optical_frame" body2="head_yaw_link" /><exclude body1="gps_link" body2="lift_base_link" /><exclude body1="gps_link" body2="lift_carriage_link" /><exclude body1="gps_link" body2="chest_link" /><exclude body1="gps_link" body2="left_link0_base" /><exclude body1="gps_link" body2="right_link0_base" /><exclude body1="gps_link" body2="head_base_link" /><exclude body1="gps_link" body2="head_pitch_link" /><exclude body1="gps_link" body2="head_yaw_link" /><exclude body1="lift_base_link" body2="lift_carriage_link" /><exclude body1="lift_base_link" body2="chest_link" /><exclude body1="lift_base_link" body2="left_link0_base" /><exclude body1="lift_base_link" body2="right_link0_base" /><exclude body1="lift_base_link" body2="head_base_link" /><exclude body1="lift_base_link" body2="head_pitch_link" /><exclude body1="lift_base_link" body2="head_yaw_link" /><exclude body1="lift_carriage_link" body2="chest_link" /><exclude body1="lift_carriage_link" body2="left_link0_base" /><exclude body1="lift_carriage_link" body2="right_link0_base" /><exclude body1="lift_carriage_link" body2="head_base_link" /><exclude body1="lift_carriage_link" body2="head_pitch_link" /><exclude body1="lift_carriage_link" body2="head_yaw_link" /><exclude body1="chest_link" body2="left_link0_base" /><exclude body1="chest_link" body2="right_link0_base" /><exclude body1="chest_link" body2="head_base_link" /><exclude body1="chest_link" body2="head_pitch_link" /><exclude body1="chest_link" body2="head_yaw_link" /><exclude body1="left_link0_base" body2="right_link0_base" /><exclude body1="left_link0_base" body2="head_base_link" /><exclude body1="left_link0_base" body2="head_pitch_link" /><exclude body1="left_link0_base" body2="head_yaw_link" /><exclude body1="right_link0_base" body2="head_base_link" /><exclude body1="right_link0_base" body2="head_pitch_link" /><exclude body1="right_link0_base" body2="head_yaw_link" /><exclude body1="head_base_link" body2="head_pitch_link" /><exclude body1="head_base_link" body2="head_yaw_link" /><exclude body1="head_pitch_link" body2="head_yaw_link" /></contact><equality /><actuator><position name="fl_steering_joint_pos" joint="fl_steering_joint" kp="20" kv="4" ctrllimited="true" ctrlrange="-1.5708 1.5708" /><position name="fr_steering_joint_pos" joint="fr_steering_joint" kp="20" kv="4" ctrllimited="true" ctrlrange="-1.5708 1.5708" /><position name="bl_steering_joint_pos" joint="bl_steering_joint" kp="20" kv="4" ctrllimited="true" ctrlrange="-1.5708 1.5708" /><position name="br_steering_joint_pos" joint="br_steering_joint" kp="20" kv="4" ctrllimited="true" ctrlrange="-1.5708 1.5708" /><position name="lift_joint_pos" joint="lift_joint" kp="10000" kv="2000" ctrllimited="true" ctrlrange="-0.65 0.3" /><position name="openarmx_left_joint1_pos" joint="openarmx_left_joint1" kp="180" kv="20" ctrllimited="true" ctrlrange="-3.344396 0.9056039999999999" /><position name="openarmx_left_joint2_pos" joint="openarmx_left_joint2" kp="180" kv="20" ctrllimited="true" ctrlrange="-3.2707963267948967 0.1292036732051034" /><position name="openarmx_left_joint3_pos" joint="openarmx_left_joint3" kp="180" kv="20" ctrllimited="true" ctrlrange="-1.57 1.57" /><position name="openarmx_left_joint4_pos" joint="openarmx_left_joint4" kp="180" kv="20" ctrllimited="true" ctrlrange="0.0 1.8" /><position name="openarmx_left_joint5_pos" joint="openarmx_left_joint5" kp="180" kv="20" ctrllimited="true" ctrlrange="-1.5 1.5" /><position name="openarmx_left_joint6_pos" joint="openarmx_left_joint6" kp="180" kv="20" ctrllimited="true" ctrlrange="-0.75 0.75" /><position name="openarmx_left_joint7_pos" joint="openarmx_left_joint7" kp="180" kv="20" ctrllimited="true" ctrlrange="-1.4 1.4" /><position name="openarmx_right_joint1_pos" joint="openarmx_right_joint1" kp="180" kv="20" ctrllimited="true" ctrlrange="-1.25 3.0" /><position name="openarmx_right_joint2_pos" joint="openarmx_right_joint2" kp="180" kv="20" ctrllimited="true" ctrlrange="-0.1292036732051034 3.2707963267948967" /><position name="openarmx_right_joint3_pos" joint="openarmx_right_joint3" kp="180" kv="20" ctrllimited="true" ctrlrange="-1.57 1.57" /><position name="openarmx_right_joint4_pos" joint="openarmx_right_joint4" kp="180" kv="20" ctrllimited="true" ctrlrange="0.0 1.8" /><position name="openarmx_right_joint5_pos" joint="openarmx_right_joint5" kp="180" kv="20" ctrllimited="true" ctrlrange="-1.5 1.5" /><position name="openarmx_right_joint6_pos" joint="openarmx_right_joint6" kp="180" kv="20" ctrllimited="true" ctrlrange="-0.75 0.75" /><position name="openarmx_right_joint7_pos" joint="openarmx_right_joint7" kp="180" kv="20" ctrllimited="true" ctrlrange="-1.4 1.4" /><position name="openarmx_head_pitch_joint_pos" joint="openarmx_head_pitch_joint" kp="40" kv="4" ctrllimited="true" ctrlrange="-1.5708 1.5708" /><position name="openarmx_head_yaw_joint_pos" joint="openarmx_head_yaw_joint" kp="40" kv="4" ctrllimited="true" ctrlrange="-1.5708 1.5708" /><position name="ldjy_left_finger1_joint1_actuator" joint="ldjy_left_finger1_joint1" kp="0.35" kv="0.02" ctrlrange="-0.37 0.37" forcerange="-0.1822 0.1822" /><position name="ldjy_left_finger1_joint2_actuator" joint="ldjy_left_finger1_joint2" kp="0.35" kv="0.02" ctrlrange="-1.5604 0.0" forcerange="-0.6188 0.6188" /><position name="ldjy_left_finger1_joint3_actuator" joint="ldjy_left_finger1_joint3" kp="0.22" kv="0.01" ctrlrange="-1.5485 0.4777" forcerange="-0.2251 0.2251" /><position name="ldjy_left_finger1_joint4_actuator" joint="ldjy_left_finger1_joint4" kp="0.22" kv="0.01" ctrlrange="-1.5753 0.4683" forcerange="-0.217 0.217" /><position name="ldjy_left_finger2_joint1_actuator" joint="ldjy_left_finger2_joint1" kp="0.35" kv="0.02" ctrlrange="-0.37 0.37" forcerange="-0.1827 0.1827" /><position name="ldjy_left_finger2_joint2_actuator" joint="ldjy_left_finger2_joint2" kp="0.35" kv="0.02" ctrlrange="-1.5516 0.0" forcerange="-0.6494 0.6494" /><position name="ldjy_left_finger2_joint3_actuator" joint="ldjy_left_finger2_joint3" kp="0.22" kv="0.01" ctrlrange="-1.5512 0.4739" forcerange="-0.2078 0.2078" /><position name="ldjy_left_finger2_joint4_actuator" joint="ldjy_left_finger2_joint4" kp="0.22" kv="0.01" ctrlrange="-1.5745 0.4684" forcerange="-0.2018 0.2018" /><position name="ldjy_left_finger3_joint1_actuator" joint="ldjy_left_finger3_joint1" kp="0.35" kv="0.02" ctrlrange="-0.37 0.37" forcerange="-0.1832 0.1832" /><position name="ldjy_left_finger3_joint2_actuator" joint="ldjy_left_finger3_joint2" kp="0.35" kv="0.02" ctrlrange="-1.5585 0.0" forcerange="-0.6389 0.6389" /><position name="ldjy_left_finger3_joint3_actuator" joint="ldjy_left_finger3_joint3" kp="0.22" kv="0.01" ctrlrange="-1.5487 0.4765" forcerange="-0.2249 0.2249" /><position name="ldjy_left_finger3_joint4_actuator" joint="ldjy_left_finger3_joint4" kp="0.22" kv="0.01" ctrlrange="-1.5634 0.4777" forcerange="-0.2044 0.2044" /><position name="ldjy_left_thumb_joint1_actuator" joint="ldjy_left_thumb_joint1" kp="0.35" kv="0.02" ctrlrange="-0.9250245036 1.5707963268" forcerange="-0.4259 0.4259" /><position name="ldjy_left_thumb_joint2_actuator" joint="ldjy_left_thumb_joint2" kp="0.35" kv="0.02" ctrlrange="-1.6033 0.0" forcerange="-0.4452 0.4452" /><position name="ldjy_left_thumb_joint3_actuator" joint="ldjy_left_thumb_joint3" kp="0.22" kv="0.01" ctrlrange="0.0 1.5707963268" forcerange="-0.1888 0.1888" /><position name="ldjy_left_thumb_joint4_actuator" joint="ldjy_left_thumb_joint4" kp="0.22" kv="0.01" ctrlrange="0.0 1.5707963268" forcerange="-0.1468 0.1468" /><position name="ldjy_left_finger4_joint1_actuator" joint="ldjy_left_finger4_joint1" kp="0.35" kv="0.02" ctrlrange="-1.0471975511965976 0.0" forcerange="-0.1798 0.1798" /><position name="ldjy_left_finger4_joint2_actuator" joint="ldjy_left_finger4_joint2" kp="0.35" kv="0.02" ctrlrange="-0.3665191429 0.3665191429" forcerange="-0.6441 0.6441" /><position name="ldjy_left_finger4_joint3_actuator" joint="ldjy_left_finger4_joint3" kp="0.22" kv="0.01" ctrlrange="-1.549 0.4768" forcerange="-0.2384 0.2384" /><position name="ldjy_left_finger4_joint4_actuator" joint="ldjy_left_finger4_joint4" kp="0.22" kv="0.01" ctrlrange="-1.5735 0.4683" forcerange="-0.1866 0.1866" /><position name="ldjy_right_finger1_joint1_actuator" joint="ldjy_right_finger1_joint1" kp="0.35" kv="0.02" ctrlrange="-0.37 0.37" forcerange="-0.1822 0.1822" /><position name="ldjy_right_finger1_joint2_actuator" joint="ldjy_right_finger1_joint2" kp="0.35" kv="0.02" ctrlrange="0.0 1.5604" forcerange="-0.6188 0.6188" /><position name="ldjy_right_finger1_joint3_actuator" joint="ldjy_right_finger1_joint3" kp="0.22" kv="0.01" ctrlrange="-0.4777 1.5485" forcerange="-0.2251 0.2251" /><position name="ldjy_right_finger1_joint4_actuator" joint="ldjy_right_finger1_joint4" kp="0.22" kv="0.01" ctrlrange="-0.4683 1.5753" forcerange="-0.217 0.217" /><position name="ldjy_right_finger2_joint1_actuator" joint="ldjy_right_finger2_joint1" kp="0.35" kv="0.02" ctrlrange="-0.37 0.37" forcerange="-0.1827 0.1827" /><position name="ldjy_right_finger2_joint2_actuator" joint="ldjy_right_finger2_joint2" kp="0.35" kv="0.02" ctrlrange="0.0 1.5516" forcerange="-0.6494 0.6494" /><position name="ldjy_right_finger2_joint3_actuator" joint="ldjy_right_finger2_joint3" kp="0.22" kv="0.01" ctrlrange="-0.4739 1.5512" forcerange="-0.2078 0.2078" /><position name="ldjy_right_finger2_joint4_actuator" joint="ldjy_right_finger2_joint4" kp="0.22" kv="0.01" ctrlrange="-0.4684 1.5745" forcerange="-0.2018 0.2018" /><position name="ldjy_right_finger3_joint1_actuator" joint="ldjy_right_finger3_joint1" kp="0.35" kv="0.02" ctrlrange="-0.37 0.37" forcerange="-0.1832 0.1832" /><position name="ldjy_right_finger3_joint2_actuator" joint="ldjy_right_finger3_joint2" kp="0.35" kv="0.02" ctrlrange="0.0 1.5585" forcerange="-0.6389 0.6389" /><position name="ldjy_right_finger3_joint3_actuator" joint="ldjy_right_finger3_joint3" kp="0.22" kv="0.01" ctrlrange="-0.4765 1.5487" forcerange="-0.2249 0.2249" /><position name="ldjy_right_finger3_joint4_actuator" joint="ldjy_right_finger3_joint4" kp="0.22" kv="0.01" ctrlrange="-0.4777 1.5634" forcerange="-0.2044 0.2044" /><position name="ldjy_right_thumb_joint1_actuator" joint="ldjy_right_thumb_joint1" kp="0.35" kv="0.02" ctrlrange="-1.5707963268 0.9250245036" forcerange="-0.4259 0.4259" /><position name="ldjy_right_thumb_joint2_actuator" joint="ldjy_right_thumb_joint2" kp="0.35" kv="0.02" ctrlrange="0.0 1.6033" forcerange="-0.4452 0.4452" /><position name="ldjy_right_thumb_joint3_actuator" joint="ldjy_right_thumb_joint3" kp="0.22" kv="0.01" ctrlrange="-1.5707963268 0.0" forcerange="-0.1888 0.1888" /><position name="ldjy_right_thumb_joint4_actuator" joint="ldjy_right_thumb_joint4" kp="0.22" kv="0.01" ctrlrange="-1.5707963268 0.0" forcerange="-0.1468 0.1468" /><position name="ldjy_right_finger4_joint1_actuator" joint="ldjy_right_finger4_joint1" kp="0.35" kv="0.02" ctrlrange="0.0 1.0471975511965976" forcerange="-0.1798 0.1798" /><position name="ldjy_right_finger4_joint2_actuator" joint="ldjy_right_finger4_joint2" kp="0.35" kv="0.02" ctrlrange="-0.3665191429 0.3665191429" forcerange="-0.6441 0.6441" /><position name="ldjy_right_finger4_joint3_actuator" joint="ldjy_right_finger4_joint3" kp="0.22" kv="0.01" ctrlrange="-0.4768 1.549" forcerange="-0.2384 0.2384" /><position name="ldjy_right_finger4_joint4_actuator" joint="ldjy_right_finger4_joint4" kp="0.22" kv="0.01" ctrlrange="-0.4683 1.5735" forcerange="-0.1866 0.1866" /></actuator></mujoco>