<mujoco model="ldjy-left-hand"><compiler angle="radian" /><option timestep="0.01" integrator="Euler" iterations="5" ls_iterations="8" /><default /><asset><mesh name="left_palm_visual_0" content_type="model/stl" file="../meshes/palm.stl" scale="-1 1 1" /><mesh name="left_palm_collision" content_type="model/stl" file="../meshes/collision/palm_collision.stl" scale="-1 1 1" /><mesh name="left_finger1_link1_visual_0" content_type="model/stl" file="../meshes/finger1_link1.stl" scale="-1 1 1" /><mesh name="left_finger1_link2_visual_0" content_type="model/stl" file="../meshes/finger1_link2.stl" scale="-1 1 1" /><mesh name="left_finger1_link3_visual_0" content_type="model/stl" file="../meshes/finger1_link3.stl" scale="-1 1 1" /><mesh name="left_finger1_link4_visual_0" content_type="model/stl" file="../meshes/finger1_link4.stl" scale="-1 1 1" /><mesh name="left_finger1_link4_collision" content_type="model/stl" file="../meshes/collision/finger1_link4_collision.stl" scale="-1 1 1" /><mesh name="left_finger2_link1_visual_0" content_type="model/stl" file="../meshes/finger2_link1.stl" scale="-1 1 1" /><mesh name="left_finger2_link2_visual_0" content_type="model/stl" file="../meshes/finger2_link2.stl" scale="-1 1 1" /><mesh name="left_finger2_link3_visual_0" content_type="model/stl" file="../meshes/finger2_link3.stl" scale="-1 1 1" /><mesh name="left_finger2_link4_visual_0" content_type="model/stl" file="../meshes/finger2_link4.stl" scale="-1 1 1" /><mesh name="left_finger2_link4_collision" content_type="model/stl" file="../meshes/collision/finger2_link4_collision.stl" scale="-1 1 1" /><mesh name="left_finger3_link1_visual_0" content_type="model/stl" file="../meshes/finger3_link1.stl" scale="-1 1 1" /><mesh name="left_finger3_link2_visual_0" content_type="model/stl" file="../meshes/finger3_link2.stl" scale="-1 1 1" /><mesh name="left_finger3_link3_visual_0" content_type="model/stl" file="../meshes/finger3_link3.stl" scale="-1 1 1" /><mesh name="left_finger3_link4_visual_0" content_type="model/stl" file="../meshes/finger3_link4.stl" scale="-1 1 1" /><mesh name="left_finger3_link4_collision" content_type="model/stl" file="../meshes/collision/finger3_link4_collision.stl" scale="-1 1 1" /><mesh name="left_thumb_link1_visual_0" content_type="model/stl" file="../meshes/thumb_link1.stl" scale="-1 1 1" /><mesh name="left_thumb_link2_visual_0" content_type="model/stl" file="../meshes/thumb_link2.stl" scale="-1 1 1" /><mesh name="left_thumb_link3_visual_0" content_type="model/stl" file="../meshes/thumb_link3.stl" scale="-1 1 1" /><mesh name="left_thumb_link4_visual_0" content_type="model/stl" file="../meshes/thumb_link4.stl" scale="-1 1 1" /><mesh name="left_thumb_link4_collision" content_type="model/stl" file="../meshes/collision/thumb_link4_collision.stl" scale="-1 1 1" /><mesh name="left_finger4_link1_visual_0" content_type="model/stl" file="../meshes/finger4_link1.stl" scale="-1 1 1" /><mesh name="left_finger4_link2_visual_0" content_type="model/stl" file="../meshes/finger4_link2.stl" scale="-1 1 1" /><mesh name="left_finger4_link3_visual_0" content_type="model/stl" file="../meshes/finger4_link3.stl" scale="-1 1 1" /><mesh name="left_finger4_link4_visual_0" content_type="model/stl" file="../meshes/finger4_link4.stl" scale="-1 1 1" /><mesh name="left_finger4_link4_collision" content_type="model/stl" file="../meshes/collision/finger4_link4_collision.stl" scale="-1 1 1" /></asset><worldbody><body name="left_palm"><inertial pos="0.002100989686 -0.001688548819 0.01727660861" mass="0.200010115" fullinertia="0.0001400575215 0.0001960126545 9.28994431e-05 -3.300850571e-06 -1.303765852e-05 -1.969913402e-06" /><geom name="left_palm_visual_0_geom" type="mesh" mesh="left_palm_visual_0" pos="0.0 0.0 0.0" euler="0.0 0.0 0.0" contype="0" conaffinity="0" group="1" density="0" rgba="0.72 0.76 0.78 1" /><geom name="left_palm_collision" rgba="0.55 0.7 0.9 0.35" friction="0.7 0.005 0.0001" solref="0.02 1.5" solimp="0.9 0.95 0.001 0.5 2.0" priority="1" condim="3" type="mesh" mesh="left_palm_collision" pos="0.0 0.0 0.0" euler="0.0 0.0 0.0" /><body name="left_finger1_link1" pos="-0.0233 -0.00295 0.0495" euler="0.0 0.0 0.0"><inertial pos="-0.002552140053 -0.0002949597412 0.01500495062" mass="0.0150541391" fullinertia="2.363453405e-06 1.594218588e-06 1.446291259e-06 4.524555776e-08 -1.6055183e-07 2.654450928e-07" /><joint name="left_finger1_joint1" axis="0.0 1.0 0.0" range="-0.37 0.37" actuatorfrcrange="-0.1822 0.1822" armature="0.0005" /><geom name="left_finger1_link1_visual_0_geom" type="mesh" mesh="left_finger1_link1_visual_0" pos="0.0233 0.00295 -0.0495" euler="0.0 0.0 0.0" contype="0" conaffinity="0" group="1" density="0" rgba="0.72 0.76 0.78 1" /><body name="left_finger1_link2" pos="0.0009621741619 -0.0117 0.02207380139" euler="0.0 0.0 0.0"><inertial pos="-0.007529199598 -0.000357884412 0.01653624902" mass="0.01150473762" fullinertia="1.861515854e-06 1.970814569e-06 5.399282613e-07 5.501808106e-09 -2.315560267e-07 3.19692724e-08" /><joint name="left_finger1_joint2" axis="-0.9858405936 0.0 -0.1676851933" range="-1.5604 0.0" actuatorfrcrange="-0.6188 0.6188" armature="0.0005" /><geom name="left_finger1_link2_visual_0_geom" type="mesh" mesh="left_finger1_link2_visual_0" pos="0.02233782584 0.01465 -0.07157380139" euler="0.0 0.0 0.0" contype="0" conaffinity="0" group="1" density="0" rgba="0.72 0.76 0.78 1" /><geom name="left_finger1_link2_capsule_body" rgba="0.55 0.7 0.9 0.35" friction="0.7 0.005 0.0001" solref="0.02 1.5" solimp="0.9 0.95 0.001 0.5 2.0" priority="1" condim="3" type="capsule" fromto="-0.005864106671017739 -3.315357052071993e-05 0.0021571807155113445 -0.008643711232982262 0.0015634059923207199 0.029713695544488654" size="0.007647541322" /><body name="left_finger1_link3" pos="-0.005447258779 -0.0009862714603 0.03202506269" euler="0.0 0.0 0.0"><inertial pos="-0.007529199598 -0.000357884412 0.01653624902" mass="0.01150473762" fullinertia="1.861515854e-06 1.970814569e-06 5.399282613e-07 5.501808106e-09 -2.315560267e-07 3.19692724e-08" /><joint name="left_finger1_joint3" axis="-0.9858405936 0.0 -0.1676851933" range="-1.5485 0.4777" actuatorfrcrange="-0.2251 0.2251" armature="0.0005" /><geom name="left_finger1_link3_visual_0_geom" type="mesh" mesh="left_finger1_link3_visual_0" pos="0.02778508462 0.01563627146 -0.1035988641" euler="0.0 0.0 0.0" contype="0" conaffinity="0" group="1" density="0" rgba="0.72 0.76 0.78 1" /><geom name="left_finger1_link3_capsule_body" rgba="0.55 0.7 0.9 0.35" friction="0.7 0.005 0.0001" solref="0.02 1.5" solimp="0.9 0.95 0.001 0.5 2.0" priority="1" condim="3" type="capsule" fromto="-0.005864106671017739 -3.315357052071993e-05 0.0021571807155113445 -0.008643711232982262 0.0015634059923207199 0.029713695544488654" size="0.007647541322" /><body name="left_finger1_link4" pos="-0.005447258779 -0.0009862714603 0.03202506269" euler="0.0 0.0 0.0"><inertial pos="-0.006403231499 -0.0003803927588 0.009915921237" mass="0.007585938385" fullinertia="6.792669082e-07 7.730027699e-07 3.194495902e-07 2.470647307e-09 -6.30049988e-08 1.451842468e-08" /><joint name="left_finger1_joint4" axis="-0.9858405936 0.0 -0.1676851933" range="-1.5753 0.4683" actuatorfrcrange="-0.217 0.217" armature="0.0005" /><geom name="left_finger1_link4_visual_0_geom" type="mesh" mesh="left_finger1_link4_visual_0" pos="0.0332323434 0.01662254292 -0.1356239268" euler="0.0 0.0 0.0" contype="0" conaffinity="0" group="1" density="0" rgba="0.72 0.76 0.78 1" /><geom name="left_finger1_link4_collision" rgba="0.55 0.7 0.9 0.35" friction="0.7 0.005 0.0001" solref="0.02 1.5" solimp="0.9 0.95 0.001 0.5 2.0" priority="1" condim="3" type="mesh" mesh="left_finger1_link4_collision" pos="0.0332323434 0.01662254292 -0.1356239268" euler="0.0 0.0 0.0" /><site name="left_finger1_link4_tip" pos="0 0 0.025" group="4" size="0.003" /></body></body></body></body><body name="left_finger2_link1" pos="0.0 -0.00295 0.0545" euler="0.0 0.0 0.0"><inertial pos="0.0004261161081 -0.0002949597412 0.01521447952" mass="0.0150541391" fullinertia="2.389979737e-06 1.594218588e-06 1.419764927e-06 -7.443150302e-09 2.7281791e-08 2.691706844e-07" /><joint name="left_finger2_joint1" axis="0.0 1.0 0.0" range="-0.37 0.37" actuatorfrcrange="-0.1827 0.1827" armature="0.0005" /><geom name="left_finger2_link1_visual_0_geom" type="mesh" mesh="left_finger2_link1_visual_0" pos="0.0 0.00295 -0.0545" euler="0.0 0.0 0.0" contype="0" conaffinity="0" group="1" density="0" rgba="0.72 0.76 0.78 1" /><body name="left_finger2_link2" pos="0.005252746989 -0.0117 0.0214612939" euler="0.0 0.0 0.0"><inertial pos="-0.00415623752 -0.0003144280118 0.01768873326" mass="0.01150473762" fullinertia="1.899818734e-06 1.970966079e-06 5.014738708e-07 -7.431753573e-10 3.91233677e-08 2.879175918e-08" /><joint name="left_finger2_joint2" axis="-0.9996082196 0.0 0.02798941517" range="-1.5516 0.0" actuatorfrcrange="-0.6494 0.6494" armature="0.0005" /><geom name="left_finger2_link2_visual_0_geom" type="mesh" mesh="left_finger2_link2_visual_0" pos="-0.005252746989 0.01465 -0.0759612939" euler="0.0 0.0 0.0" contype="0" conaffinity="0" group="1" density="0" rgba="0.72 0.76 0.78 1" /><geom name="left_finger2_link2_capsule_body" rgba="0.55 0.7 0.9 0.35" friction="0.7 0.005 0.0001" solref="0.02 1.5" solimp="0.9 0.95 0.001 0.5 2.0" priority="1" condim="3" type="capsule" fromto="-0.005330175945664866 -2.5459360278297892e-05 0.0032604985870525113 -0.0026770375963351334 0.0016394585514782978 0.03082543317294749" size="0.007647541322" /><body name="left_finger2_link3" pos="0.0009093025454 -0.0009058997649 0.03247464418" euler="0.0 0.0 0.0"><inertial pos="-0.00415623752 -0.0003144280118 0.01768873326" mass="0.01150473762" fullinertia="1.899818734e-06 1.970966079e-06 5.014738708e-07 -7.431753573e-10 3.91233677e-08 2.879175918e-08" /><joint name="left_finger2_joint3" axis="-0.9996082196 0.0 0.02798941517" range="-1.5512 0.4739" actuatorfrcrange="-0.2078 0.2078" armature="0.0005" /><geom name="left_finger2_link3_visual_0_geom" type="mesh" mesh="left_finger2_link3_visual_0" pos="-0.006162049534 0.01555589976 -0.1084359381" euler="0.0 0.0 0.0" contype="0" conaffinity="0" group="1" density="0" rgba="0.72 0.76 0.78 1" /><geom name="left_finger2_link3_capsule_body" rgba="0.55 0.7 0.9 0.35" friction="0.7 0.005 0.0001" solref="0.02 1.5" solimp="0.9 0.95 0.001 0.5 2.0" priority="1" condim="3" type="capsule" fromto="-0.005330175945664866 -2.5459360278297892e-05 0.0032604985870525113 -0.0026770375963351334 0.0016394585514782978 0.03082543317294749" size="0.007647541322" /><body name="left_finger2_link4" pos="0.0009093025454 -0.0009058997649 0.03247464418" euler="0.0 0.0 0.0"><inertial pos="-0.004344301239 -0.0003535503261 0.01097604734" mass="0.007585938385" fullinertia="6.896804327e-07 7.730727985e-07 3.08966037e-07 -3.788620486e-10 1.068844763e-08 1.357307458e-08" /><joint name="left_finger2_joint4" axis="-0.9996082196 0.0 0.02798941517" range="-1.5745 0.4684" actuatorfrcrange="-0.2018 0.2018" armature="0.0005" /><geom name="left_finger2_link4_visual_0_geom" type="mesh" mesh="left_finger2_link4_visual_0" pos="-0.00707135208 0.01646179953 -0.1409105823" euler="0.0 0.0 0.0" contype="0" conaffinity="0" group="1" density="0" rgba="0.72 0.76 0.78 1" /><geom name="left_finger2_link4_collision" rgba="0.55 0.7 0.9 0.35" friction="0.7 0.005 0.0001" solref="0.02 1.5" solimp="0.9 0.95 0.001 0.5 2.0" priority="1" condim="3" type="mesh" mesh="left_finger2_link4_collision" pos="-0.00707135208 0.01646179953 -0.1409105823" euler="0.0 0.0 0.0" /><site name="left_finger2_link4_tip" pos="0 0 0.025" group="4" size="0.003" /></body></body></body></body><body name="left_finger3_link1" pos="0.0233 -0.00295 0.0445" euler="0.0 0.0 0.0"><inertial pos="0.002586982248 -0.0002951945879 0.01499906285" mass="0.01505382492" fullinertia="2.362593935e-06 1.5942064e-06 1.447056064e-06 -4.568916311e-08 1.628553627e-07 2.653544912e-07" /><joint name="left_finger3_joint1" axis="0.0 1.0 0.0" range="-0.37 0.37" actuatorfrcrange="-0.1832 0.1832" armature="0.0005" /><geom name="left_finger3_link1_visual_0_geom" type="mesh" mesh="left_finger3_link1_visual_0" pos="-0.0233 0.00295 -0.0445" euler="0.0 0.0 0.0" contype="0" conaffinity="0" group="1" density="0" rgba="0.72 0.76 0.78 1" /><body name="left_finger3_link2" pos="0.008253592832 -0.0117 0.02049528464" euler="0.0 0.0 0.0"><inertial pos="-0.001596931475 0.0004290719444 0.01809779453" mass="0.01150473762" fullinertia="1.860480436e-06 1.970768424e-06 5.410098243e-07 5.747964394e-09 2.344859304e-07 -3.297133497e-08" /><joint name="left_finger3_joint2" axis="-0.98544992 0.0 0.1699660413" range="-1.5585 0.0" actuatorfrcrange="-0.6389 0.6389" armature="0.0005" /><geom name="left_finger3_link2_visual_0_geom" type="mesh" mesh="left_finger3_link2_visual_0" pos="-0.03155359283 0.01465 -0.06499528464" euler="0.0 0.0 0.0" contype="0" conaffinity="0" group="1" density="0" rgba="0.72 0.76 0.78 1" /><geom name="left_finger3_link2_capsule_body" rgba="0.55 0.7 0.9 0.35" friction="0.7 0.005 0.0001" solref="0.02 1.5" solimp="0.9 0.95 0.001 0.5 2.0" priority="1" condim="3" type="capsule" fromto="-0.004812185541144998 0.00010615303547150366 0.003984203394555937 0.001720734881144998 0.0029385739125284962 0.030797167725444066" size="0.007647541322" /><body name="left_finger3_link3" pos="0.005523319931 0.0004694951803 0.0320237804" euler="0.0 0.0 0.0"><inertial pos="-0.001596931475 0.0004290719444 0.01809779453" mass="0.01150473762" fullinertia="1.860480436e-06 1.970768424e-06 5.410098243e-07 5.747964394e-09 2.344859304e-07 -3.297133497e-08" /><joint name="left_finger3_joint3" axis="-0.98544992 0.0 0.1699660413" range="-1.5487 0.4765" actuatorfrcrange="-0.2249 0.2249" armature="0.0005" /><geom name="left_finger3_link3_visual_0_geom" type="mesh" mesh="left_finger3_link3_visual_0" pos="-0.03707691276 0.01418050482 -0.09701906504" euler="0.0 0.0 0.0" contype="0" conaffinity="0" group="1" density="0" rgba="0.72 0.76 0.78 1" /><geom name="left_finger3_link3_capsule_body" rgba="0.55 0.7 0.9 0.35" friction="0.7 0.005 0.0001" solref="0.02 1.5" solimp="0.9 0.95 0.001 0.5 2.0" priority="1" condim="3" type="capsule" fromto="-0.004812185541144998 0.00010615303547150366 0.003984203394555937 0.001720734881144998 0.0029385739125284962 0.030797167725444066" size="0.007647541322" /><body name="left_finger3_link4" pos="0.005523319931 0.0004694951803 0.0320237804" euler="0.0 0.0 0.0"><inertial pos="-0.002737108666 0.0001058506004 0.01148775862" mass="0.007585938385" fullinertia="6.789489057e-07 7.733894034e-07 3.193809591e-07 1.039186966e-09 6.393916346e-08 -6.013182828e-09" /><joint name="left_finger3_joint4" axis="-0.98544992 0.0 0.1699660413" range="-1.5634 0.4777" actuatorfrcrange="-0.2044 0.2044" armature="0.0005" /><geom name="left_finger3_link4_visual_0_geom" type="mesh" mesh="left_finger3_link4_visual_0" pos="-0.04260023269 0.01371100964 -0.1290428454" euler="0.0 0.0 0.0" contype="0" conaffinity="0" group="1" density="0" rgba="0.72 0.76 0.78 1" /><geom name="left_finger3_link4_collision" rgba="0.55 0.7 0.9 0.35" friction="0.7 0.005 0.0001" solref="0.02 1.5" solimp="0.9 0.95 0.001 0.5 2.0" priority="1" condim="3" type="mesh" mesh="left_finger3_link4_collision" pos="-0.04260023269 0.01371100964 -0.1290428454" euler="0.0 0.0 0.0" /><site name="left_finger3_link4_tip" pos="0 0 0.025" group="4" size="0.003" /></body></body></body></body><body name="left_thumb_link1" pos="-0.0233 -0.00295 -0.0084" euler="0.0 0.0 0.0"><inertial pos="0.0008689005969 -0.003804801439 -0.001284419564" mass="0.009231749795" fullinertia="1.060881976e-06 4.170231492e-07 1.055511507e-06 5.894022963e-08 -1.130080766e-08 7.482297275e-08" /><joint name="left_thumb_joint1" axis="0.0 1.0 0.0" range="-0.9250245036 1.5707963268" actuatorfrcrange="-0.4259 0.4259" armature="0.0005" /><geom name="left_thumb_link1_visual_0_geom" type="mesh" mesh="left_thumb_link1_visual_0" pos="0.0233 0.00295 0.0084" euler="0.0 0.0 0.0" contype="0" conaffinity="0" group="1" density="0" rgba="0.72 0.76 0.78 1" /><body name="left_thumb_link2" pos="-0.002608560701 -0.0166 -0.001938533227" euler="0.0 0.0 0.0"><inertial pos="-0.008159715317 -0.000678399895 0.01634525189" mass="0.01361136422" fullinertia="2.067853631e-06 2.82551883e-06 1.405796287e-06 3.320375324e-08 -1.072979093e-06 4.507555487e-08" /><joint name="left_thumb_joint2" axis="-0.8026340617 0.0 -0.5964717621" range="-1.6033 0.0" actuatorfrcrange="-0.4452 0.4452" armature="0.0005" /><geom name="left_thumb_link2_visual_0_geom" type="mesh" mesh="left_thumb_link2_visual_0" pos="0.0259085607 0.01955 0.01033853323" euler="0.0 0.0 0.0" contype="0" conaffinity="0" group="1" density="0" rgba="0.72 0.76 0.78 1" /><geom name="left_thumb_link2_capsule_body" rgba="0.55 0.7 0.9 0.35" friction="0.7 0.005 0.0001" solref="0.02 1.5" solimp="0.9 0.95 0.001 0.5 2.0" priority="1" condim="3" type="capsule" fromto="0.0012674068890160713 -0.003368696520349595 0.004496985802651246 -0.01835717003901607 0.0006926715583495948 0.030009979377348756" size="0.007912057707" /><body name="left_thumb_link3" pos="-0.02024684923 -0.006366194767 0.03269360274" euler="0.0 0.0 0.0"><inertial pos="-0.008158821575 0.004675488222 0.01269274767" mass="0.01150473762" fullinertia="1.569176561e-06 1.899515634e-06 9.035664892e-07 2.301654039e-08 -6.555138346e-07 3.775871711e-08" /><joint name="left_thumb_joint3" axis="-0.01888221858 0.9994988069 0.02540859896" range="0.0 1.5707963268" actuatorfrcrange="-0.1888 0.1888" armature="0.0005" /><geom name="left_thumb_link3_visual_0_geom" type="mesh" mesh="left_thumb_link3_visual_0" pos="0.04615540993 0.02591619477 -0.02235506952" euler="0.0 0.0 0.0" contype="0" conaffinity="0" group="1" density="0" rgba="0.72 0.76 0.78 1" /><geom name="left_thumb_link3_capsule_body" rgba="0.55 0.7 0.9 0.35" friction="0.7 0.005 0.0001" solref="0.02 1.5" solimp="0.9 0.95 0.001 0.5 2.0" priority="1" condim="3" type="capsule" fromto="-0.0031561761038444896 0.003973012588344725 0.0003210599958376435 -0.01573803159815551 0.0049888195556552755 0.025025346304162355" size="0.007647541322" /><body name="left_thumb_link4" pos="-0.01722211724 -0.001025525643 0.02754263922" euler="0.0 0.0 0.0"><inertial pos="-0.006524915211 0.00468820306 0.0134094626" mass="0.01143731998" fullinertia="1.670475431e-06 1.858111984e-06 7.407043888e-07 1.736442301e-08 -5.39596932e-07 3.864265835e-08" /><joint name="left_thumb_joint4" axis="-0.01888221858 0.9994988069 0.02540859896" range="0.0 1.5707963268" actuatorfrcrange="-0.1468 0.1468" armature="0.0005" /><geom name="left_thumb_link4_visual_0_geom" type="mesh" mesh="left_thumb_link4_visual_0" pos="0.06337752717 0.02694172041 -0.04989770873" euler="0.0 0.0 0.0" contype="0" conaffinity="0" group="1" density="0" rgba="0.72 0.76 0.78 1" /><geom name="left_thumb_link4_collision" rgba="0.55 0.7 0.9 0.35" friction="0.7 0.005 0.0001" solref="0.02 1.5" solimp="0.9 0.95 0.001 0.5 2.0" priority="1" condim="3" type="mesh" mesh="left_thumb_link4_collision" pos="0.06337752717 0.02694172041 -0.04989770873" euler="0.0 0.0 0.0" /><site name="left_thumb_link4_tip" pos="0 0 0.025" group="4" size="0.003" /></body></body></body></body><body name="left_finger4_link1" pos="0.0233 -0.0136 -0.00335" euler="0.0 0.0 0.0"><inertial pos="0.01635947532 0.0003022085593 0.01584337601" mass="0.02634208642" fullinertia="8.041665618e-06 9.603291865e-06 2.681265216e-06 2.877050045e-08 2.017341866e-06 -3.162593458e-08" /><joint name="left_finger4_joint1" axis="0.0 0.0 1.0" range="-1.0471975511965976 0.0" actuatorfrcrange="-0.1798 0.1798" armature="0.0005" /><geom name="left_finger4_link1_visual_0_geom" type="mesh" mesh="left_finger4_link1_visual_0" pos="-0.0233 0.0136 0.00335" euler="0.0 0.0 0.0" contype="0" conaffinity="0" group="1" density="0" rgba="0.72 0.76 0.78 1" /><geom name="left_finger4_link1_l_lower_body" rgba="0.55 0.7 0.9 0.35" friction="0.7 0.005 0.0001" solref="0.02 1.5" solimp="0.9 0.95 0.001 0.5 2.0" priority="1" condim="3" type="capsule" fromto="0.003267485672213381 8.358832052791327e-05 -0.009744681730066118 0.023885122387786617 0.0004408267940720868 0.007181010764066119" size="0.007121991075" /><geom name="left_finger4_link1_l_upper_body" rgba="0.55 0.7 0.9 0.35" friction="0.7 0.005 0.0001" solref="0.02 1.5" solimp="0.9 0.95 0.001 0.5 2.0" priority="1" condim="3" type="capsule" fromto="0.023614543657127906 3.906772957551863e-05 0.02177814756457811 0.026287592602872095 -0.00015601330679551864 0.04060698019542189" size="0.007839284308" /><body name="left_finger4_link2" pos="0.02339748876 -0.004742100776 0.0434" euler="0.0 0.0 0.0"><inertial pos="0.004459969685 0.005238464661 0.01000947843" mass="0.00822987786" fullinertia="7.197019922e-07 7.920318456e-07 4.435674176e-07 1.413809552e-09 1.587952065e-07 -3.11691908e-09" /><joint name="left_finger4_joint2" axis="-0.01960941425 0.999807717 0.0" range="-0.3665191429 0.3665191429" actuatorfrcrange="-0.6441 0.6441" armature="0.0005" /><geom name="left_finger4_link2_visual_0_geom" type="mesh" mesh="left_finger4_link2_visual_0" pos="-0.04669748876 0.01834210078 -0.04005" euler="0.0 0.0 0.0" contype="0" conaffinity="0" group="1" density="0" rgba="0.72 0.76 0.78 1" /><geom name="left_finger4_link2_capsule_body" rgba="0.55 0.7 0.9 0.35" friction="0.7 0.005 0.0001" solref="0.02 1.5" solimp="0.9 0.95 0.001 0.5 2.0" priority="1" condim="3" type="capsule" fromto="0.000379027462771523 0.006169885515716631 0.0030490395542072998 0.008689386565228477 0.004545450360283369 0.0169117013837927" size="0.007571680637" /><body name="left_finger4_link3" pos="0.004335573131 0.005236024848 0.02215472522" euler="0.0 0.0 0.0"><inertial pos="0.01088390563 -0.0004228266351 0.01144090115" mass="0.01150473762" fullinertia="1.659605194e-06 1.967140451e-06 7.455130385e-07 -3.218862917e-08 5.280480303e-07 7.332310364e-08" /><joint name="left_finger4_joint3" axis="-0.9097776159 -0.01784363717 0.4147123029" range="-1.549 0.4768" actuatorfrcrange="-0.2384 0.2384" armature="0.0005" /><geom name="left_finger4_link3_visual_0_geom" type="mesh" mesh="left_finger4_link3_visual_0" pos="-0.05103306189 0.01310607593 -0.06220472522" euler="0.0 0.0 0.0" contype="0" conaffinity="0" group="1" density="0" rgba="0.72 0.76 0.78 1" /><geom name="left_finger4_link3_capsule_body" rgba="0.55 0.7 0.9 0.35" friction="0.7 0.005 0.0001" solref="0.02 1.5" solimp="0.9 0.95 0.001 0.5 2.0" priority="1" condim="3" type="capsule" fromto="0.004436865187758943 0.0024805852068378463 0.00010139237783623675 0.01758502777224106 -0.0011909087612378463 0.024252638022163764" size="0.007647541322" /><body name="left_finger4_link4" pos="0.01349028053 -0.001501340608 0.02952978679" euler="0.0 0.0 0.0"><inertial pos="0.01079974174 0.000441005848 0.01129328197" mass="0.01143731415" fullinertia="1.624273381e-06 1.917800986e-06 7.272121268e-07 2.463588289e-09 5.160034856e-07 -3.052853862e-09" /><joint name="left_finger4_joint4" axis="-0.9097776159 -0.01784363717 0.4147123029" range="-1.5735 0.4683" actuatorfrcrange="-0.1866 0.1866" armature="0.0005" /><geom name="left_finger4_link4_visual_0_geom" type="mesh" mesh="left_finger4_link4_visual_0" pos="-0.06452334242 0.01460741654 -0.091734512" euler="0.0 0.0 0.0" contype="0" conaffinity="0" group="1" density="0" rgba="0.72 0.76 0.78 1" /><geom name="left_finger4_link4_collision" rgba="0.55 0.7 0.9 0.35" friction="0.7 0.005 0.0001" solref="0.02 1.5" solimp="0.9 0.95 0.001 0.5 2.0" priority="1" condim="3" type="mesh" mesh="left_finger4_link4_collision" pos="-0.06452334242 0.01460741654 -0.091734512" euler="0.0 0.0 0.0" /><site name="left_finger4_link4_tip" pos="0 0 0.025" group="4" size="0.003" /></body></body></body></body></body></worldbody><actuator><position name="left_finger1_joint1_actuator" joint="left_finger1_joint1" kp="0.35" kv="0.02" ctrlrange="-0.37 0.37" forcerange="-0.1822 0.1822" /><position name="left_finger1_joint2_actuator" joint="left_finger1_joint2" kp="0.35" kv="0.02" ctrlrange="-1.5604 0.0" forcerange="-0.6188 0.6188" /><position name="left_finger1_joint3_actuator" joint="left_finger1_joint3" kp="0.22" kv="0.01" ctrlrange="-1.5485 0.4777" forcerange="-0.2251 0.2251" /><position name="left_finger1_joint4_actuator" joint="left_finger1_joint4" kp="0.22" kv="0.01" ctrlrange="-1.5753 0.4683" forcerange="-0.217 0.217" /><position name="left_finger2_joint1_actuator" joint="left_finger2_joint1" kp="0.35" kv="0.02" ctrlrange="-0.37 0.37" forcerange="-0.1827 0.1827" /><position name="left_finger2_joint2_actuator" joint="left_finger2_joint2" kp="0.35" kv="0.02" ctrlrange="-1.5516 0.0" forcerange="-0.6494 0.6494" /><position name="left_finger2_joint3_actuator" joint="left_finger2_joint3" kp="0.22" kv="0.01" ctrlrange="-1.5512 0.4739" forcerange="-0.2078 0.2078" /><position name="left_finger2_joint4_actuator" joint="left_finger2_joint4" kp="0.22" kv="0.01" ctrlrange="-1.5745 0.4684" forcerange="-0.2018 0.2018" /><position name="left_finger3_joint1_actuator" joint="left_finger3_joint1" kp="0.35" kv="0.02" ctrlrange="-0.37 0.37" forcerange="-0.1832 0.1832" /><position name="left_finger3_joint2_actuator" joint="left_finger3_joint2" kp="0.35" kv="0.02" ctrlrange="-1.5585 0.0" forcerange="-0.6389 0.6389" /><position name="left_finger3_joint3_actuator" joint="left_finger3_joint3" kp="0.22" kv="0.01" ctrlrange="-1.5487 0.4765" forcerange="-0.2249 0.2249" /><position name="left_finger3_joint4_actuator" joint="left_finger3_joint4" kp="0.22" kv="0.01" ctrlrange="-1.5634 0.4777" forcerange="-0.2044 0.2044" /><position name="left_thumb_joint1_actuator" joint="left_thumb_joint1" kp="0.35" kv="0.02" ctrlrange="-0.9250245036 1.5707963268" forcerange="-0.4259 0.4259" /><position name="left_thumb_joint2_actuator" joint="left_thumb_joint2" kp="0.35" kv="0.02" ctrlrange="-1.6033 0.0" forcerange="-0.4452 0.4452" /><position name="left_thumb_joint3_actuator" joint="left_thumb_joint3" kp="0.22" kv="0.01" ctrlrange="0.0 1.5707963268" forcerange="-0.1888 0.1888" /><position name="left_thumb_joint4_actuator" joint="left_thumb_joint4" kp="0.22" kv="0.01" ctrlrange="0.0 1.5707963268" forcerange="-0.1468 0.1468" /><position name="left_finger4_joint1_actuator" joint="left_finger4_joint1" kp="0.35" kv="0.02" ctrlrange="-1.0471975511965976 0.0" forcerange="-0.1798 0.1798" /><position name="left_finger4_joint2_actuator" joint="left_finger4_joint2" kp="0.35" kv="0.02" ctrlrange="-0.3665191429 0.3665191429" forcerange="-0.6441 0.6441" /><position name="left_finger4_joint3_actuator" joint="left_finger4_joint3" kp="0.22" kv="0.01" ctrlrange="-1.549 0.4768" forcerange="-0.2384 0.2384" /><position name="left_finger4_joint4_actuator" joint="left_finger4_joint4" kp="0.22" kv="0.01" ctrlrange="-1.5735 0.4683" forcerange="-0.1866 0.1866" /></actuator><contact><exclude body1="left_palm" body2="left_finger4_link1" /></contact></mujoco>